{"voxels":[{"x":6,"y":0,"z":4,"color":"#141418"},{"x":6,"y":0,"z":5,"color":"#141418"},{"x":6,"y":0,"z":6,"color":"#141418"},{"x":6,"y":0,"z":7,"color":"#141418"},{"x":6,"y":0,"z":8,"color":"#141418"},{"x":6,"y":0,"z":9,"color":"#141418"},{"x":6,"y":1,"z":4,"color":"#141418"},{"x":6,"y":1,"z":5,"color":"#141418"},{"x":6,"y":1,"z":6,"color":"#141418"},{"x":6,"y":1,"z":7,"color":"#141418"},{"x":6,"y":1,"z":8,"color":"#141418"},{"x":6,"y":1,"z":9,"color":"#141418"},{"x":6,"y":2,"z":4,"color":"#141418"},{"x":6,"y":2,"z":5,"color":"#141418"},{"x":6,"y":2,"z":6,"color":"#141418"},{"x":6,"y":2,"z":7,"color":"#141418"},{"x":6,"y":2,"z":8,"color":"#141418"},{"x":6,"y":2,"z":9,"color":"#141418"},{"x":6,"y":3,"z":4,"color":"#141418"},{"x":6,"y":3,"z":5,"color":"#141418"},{"x":6,"y":3,"z":6,"color":"#141418"},{"x":6,"y":3,"z":7,"color":"#141418"},{"x":6,"y":3,"z":8,"color":"#141418"},{"x":6,"y":3,"z":9,"color":"#141418"},{"x":6,"y":4,"z":4,"color":"#141418"},{"x":6,"y":4,"z":5,"color":"#141418"},{"x":6,"y":4,"z":6,"color":"#141418"},{"x":6,"y":4,"z":7,"color":"#141418"},{"x":6,"y":4,"z":8,"color":"#141418"},{"x":6,"y":4,"z":9,"color":"#141418"},{"x":6,"y":5,"z":4,"color":"#141418"},{"x":6,"y":5,"z":5,"color":"#141418"},{"x":6,"y":5,"z":6,"color":"#141418"},{"x":6,"y":5,"z":7,"color":"#141418"},{"x":6,"y":5,"z":8,"color":"#141418"},{"x":6,"y":5,"z":9,"color":"#141418"},{"x":7,"y":0,"z":4,"color":"#141418"},{"x":7,"y":0,"z":5,"color":"#141418"},{"x":7,"y":0,"z":6,"color":"#141418"},{"x":7,"y":0,"z":7,"color":"#141418"},{"x":7,"y":0,"z":8,"color":"#141418"},{"x":7,"y":0,"z":9,"color":"#141418"},{"x":7,"y":1,"z":4,"color":"#141418"},{"x":7,"y":1,"z":5,"color":"#141418"},{"x":7,"y":1,"z":6,"color":"#141418"},{"x":7,"y":1,"z":7,"color":"#141418"},{"x":7,"y":1,"z":8,"color":"#141418"},{"x":7,"y":1,"z":9,"color":"#141418"},{"x":7,"y":2,"z":4,"color":"#141418"},{"x":7,"y":2,"z":5,"color":"#141418"},{"x":7,"y":2,"z":6,"color":"#141418"},{"x":7,"y":2,"z":7,"color":"#141418"},{"x":7,"y":2,"z":8,"color":"#141418"},{"x":7,"y":2,"z":9,"color":"#141418"},{"x":7,"y":3,"z":4,"color":"#141418"},{"x":7,"y":3,"z":5,"color":"#141418"},{"x":7,"y":3,"z":6,"color":"#141418"},{"x":7,"y":3,"z":7,"color":"#141418"},{"x":7,"y":3,"z":8,"color":"#141418"},{"x":7,"y":3,"z":9,"color":"#141418"},{"x":7,"y":4,"z":4,"color":"#141418"},{"x":7,"y":4,"z":5,"color":"#141418"},{"x":7,"y":4,"z":6,"color":"#141418"},{"x":7,"y":4,"z":7,"color":"#141418"},{"x":7,"y":4,"z":8,"color":"#141418"},{"x":7,"y":4,"z":9,"color":"#141418"},{"x":7,"y":5,"z":4,"color":"#141418"},{"x":7,"y":5,"z":5,"color":"#141418"},{"x":7,"y":5,"z":6,"color":"#141418"},{"x":7,"y":5,"z":7,"color":"#141418"},{"x":7,"y":5,"z":8,"color":"#141418"},{"x":7,"y":5,"z":9,"color":"#141418"},{"x":8,"y":0,"z":4,"color":"#141418"},{"x":8,"y":0,"z":5,"color":"#141418"},{"x":8,"y":0,"z":6,"color":"#141418"},{"x":8,"y":0,"z":7,"color":"#141418"},{"x":8,"y":0,"z":8,"color":"#141418"},{"x":8,"y":0,"z":9,"color":"#141418"},{"x":8,"y":1,"z":4,"color":"#141418"},{"x":8,"y":1,"z":5,"color":"#141418"},{"x":8,"y":1,"z":6,"color":"#141418"},{"x":8,"y":1,"z":7,"color":"#141418"},{"x":8,"y":1,"z":8,"color":"#141418"},{"x":8,"y":1,"z":9,"color":"#141418"},{"x":8,"y":2,"z":4,"color":"#141418"},{"x":8,"y":2,"z":5,"color":"#141418"},{"x":8,"y":2,"z":6,"color":"#141418"},{"x":8,"y":2,"z":7,"color":"#141418"},{"x":8,"y":2,"z":8,"color":"#141418"},{"x":8,"y":2,"z":9,"color":"#141418"},{"x":8,"y":3,"z":4,"color":"#141418"},{"x":8,"y":3,"z":5,"color":"#141418"},{"x":8,"y":3,"z":6,"color":"#141418"},{"x":8,"y":3,"z":7,"color":"#141418"},{"x":8,"y":3,"z":8,"color":"#141418"},{"x":8,"y":3,"z":9,"color":"#141418"},{"x":8,"y":4,"z":4,"color":"#141418"},{"x":8,"y":4,"z":5,"color":"#141418"},{"x":8,"y":4,"z":6,"color":"#141418"},{"x":8,"y":4,"z":7,"color":"#141418"},{"x":8,"y":4,"z":8,"color":"#141418"},{"x":8,"y":4,"z":9,"color":"#141418"},{"x":8,"y":5,"z":4,"color":"#141418"},{"x":8,"y":5,"z":5,"color":"#141418"},{"x":8,"y":5,"z":6,"color":"#141418"},{"x":8,"y":5,"z":7,"color":"#141418"},{"x":8,"y":5,"z":8,"color":"#141418"},{"x":8,"y":5,"z":9,"color":"#141418"},{"x":9,"y":0,"z":4,"color":"#141418"},{"x":9,"y":0,"z":5,"color":"#141418"},{"x":9,"y":0,"z":6,"color":"#141418"},{"x":9,"y":0,"z":7,"color":"#141418"},{"x":9,"y":0,"z":8,"color":"#141418"},{"x":9,"y":0,"z":9,"color":"#141418"},{"x":9,"y":1,"z":4,"color":"#141418"},{"x":9,"y":1,"z":5,"color":"#141418"},{"x":9,"y":1,"z":6,"color":"#141418"},{"x":9,"y":1,"z":7,"color":"#141418"},{"x":9,"y":1,"z":8,"color":"#141418"},{"x":9,"y":1,"z":9,"color":"#141418"},{"x":9,"y":2,"z":4,"color":"#141418"},{"x":9,"y":2,"z":5,"color":"#141418"},{"x":9,"y":2,"z":6,"color":"#141418"},{"x":9,"y":2,"z":7,"color":"#141418"},{"x":9,"y":2,"z":8,"color":"#141418"},{"x":9,"y":2,"z":9,"color":"#141418"},{"x":9,"y":3,"z":4,"color":"#141418"},{"x":9,"y":3,"z":5,"color":"#141418"},{"x":9,"y":3,"z":6,"color":"#141418"},{"x":9,"y":3,"z":7,"color":"#141418"},{"x":9,"y":3,"z":8,"color":"#141418"},{"x":9,"y":3,"z":9,"color":"#141418"},{"x":9,"y":4,"z":4,"color":"#141418"},{"x":9,"y":4,"z":5,"color":"#141418"},{"x":9,"y":4,"z":6,"color":"#141418"},{"x":9,"y":4,"z":7,"color":"#141418"},{"x":9,"y":4,"z":8,"color":"#141418"},{"x":9,"y":4,"z":9,"color":"#141418"},{"x":9,"y":5,"z":4,"color":"#141418"},{"x":9,"y":5,"z":5,"color":"#141418"},{"x":9,"y":5,"z":6,"color":"#141418"},{"x":9,"y":5,"z":7,"color":"#141418"},{"x":9,"y":5,"z":8,"color":"#141418"},{"x":9,"y":5,"z":9,"color":"#141418"},{"x":10,"y":0,"z":4,"color":"#141418"},{"x":10,"y":0,"z":5,"color":"#141418"},{"x":10,"y":0,"z":6,"color":"#141418"},{"x":10,"y":0,"z":7,"color":"#141418"},{"x":10,"y":0,"z":8,"color":"#141418"},{"x":10,"y":0,"z":9,"color":"#141418"},{"x":10,"y":1,"z":4,"color":"#141418"},{"x":10,"y":1,"z":5,"color":"#141418"},{"x":10,"y":1,"z":6,"color":"#141418"},{"x":10,"y":1,"z":7,"color":"#141418"},{"x":10,"y":1,"z":8,"color":"#141418"},{"x":10,"y":1,"z":9,"color":"#141418"},{"x":10,"y":2,"z":4,"color":"#141418"},{"x":10,"y":2,"z":5,"color":"#141418"},{"x":10,"y":2,"z":6,"color":"#141418"},{"x":10,"y":2,"z":7,"color":"#141418"},{"x":10,"y":2,"z":8,"color":"#141418"},{"x":10,"y":2,"z":9,"color":"#141418"},{"x":10,"y":3,"z":4,"color":"#141418"},{"x":10,"y":3,"z":5,"color":"#141418"},{"x":10,"y":3,"z":6,"color":"#141418"},{"x":10,"y":3,"z":7,"color":"#141418"},{"x":10,"y":3,"z":8,"color":"#141418"},{"x":10,"y":3,"z":9,"color":"#141418"},{"x":10,"y":4,"z":4,"color":"#141418"},{"x":10,"y":4,"z":5,"color":"#141418"},{"x":10,"y":4,"z":6,"color":"#141418"},{"x":10,"y":4,"z":7,"color":"#141418"},{"x":10,"y":4,"z":8,"color":"#141418"},{"x":10,"y":4,"z":9,"color":"#141418"},{"x":10,"y":5,"z":4,"color":"#141418"},{"x":10,"y":5,"z":5,"color":"#141418"},{"x":10,"y":5,"z":6,"color":"#141418"},{"x":10,"y":5,"z":7,"color":"#141418"},{"x":10,"y":5,"z":8,"color":"#141418"},{"x":10,"y":5,"z":9,"color":"#141418"},{"x":11,"y":0,"z":4,"color":"#141418"},{"x":11,"y":0,"z":5,"color":"#141418"},{"x":11,"y":0,"z":6,"color":"#141418"},{"x":11,"y":0,"z":7,"color":"#141418"},{"x":11,"y":0,"z":8,"color":"#141418"},{"x":11,"y":0,"z":9,"color":"#141418"},{"x":11,"y":1,"z":4,"color":"#141418"},{"x":11,"y":1,"z":5,"color":"#141418"},{"x":11,"y":1,"z":6,"color":"#141418"},{"x":11,"y":1,"z":7,"color":"#141418"},{"x":11,"y":1,"z":8,"color":"#141418"},{"x":11,"y":1,"z":9,"color":"#141418"},{"x":11,"y":2,"z":4,"color":"#141418"},{"x":11,"y":2,"z":5,"color":"#141418"},{"x":11,"y":2,"z":6,"color":"#141418"},{"x":11,"y":2,"z":7,"color":"#141418"},{"x":11,"y":2,"z":8,"color":"#141418"},{"x":11,"y":2,"z":9,"color":"#141418"},{"x":11,"y":3,"z":4,"color":"#141418"},{"x":11,"y":3,"z":5,"color":"#141418"},{"x":11,"y":3,"z":6,"color":"#141418"},{"x":11,"y":3,"z":7,"color":"#141418"},{"x":11,"y":3,"z":8,"color":"#141418"},{"x":11,"y":3,"z":9,"color":"#141418"},{"x":11,"y":4,"z":4,"color":"#141418"},{"x":11,"y":4,"z":5,"color":"#141418"},{"x":11,"y":4,"z":6,"color":"#141418"},{"x":11,"y":4,"z":7,"color":"#141418"},{"x":11,"y":4,"z":8,"color":"#141418"},{"x":11,"y":4,"z":9,"color":"#141418"},{"x":11,"y":5,"z":4,"color":"#141418"},{"x":11,"y":5,"z":5,"color":"#141418"},{"x":11,"y":5,"z":6,"color":"#141418"},{"x":11,"y":5,"z":7,"color":"#141418"},{"x":11,"y":5,"z":8,"color":"#141418"},{"x":11,"y":5,"z":9,"color":"#141418"},{"x":0,"y":0,"z":-6,"color":"#141418"},{"x":0,"y":0,"z":-5,"color":"#141418"},{"x":0,"y":0,"z":-4,"color":"#141418"},{"x":0,"y":0,"z":-3,"color":"#141418"},{"x":0,"y":0,"z":-2,"color":"#141418"},{"x":0,"y":0,"z":-1,"color":"#2b315e"},{"x":0,"y":1,"z":-6,"color":"#141418"},{"x":0,"y":1,"z":-5,"color":"#141418"},{"x":0,"y":1,"z":-4,"color":"#141418"},{"x":0,"y":1,"z":-3,"color":"#141418"},{"x":0,"y":1,"z":-2,"color":"#141418"},{"x":0,"y":1,"z":-1,"color":"#2b315e"},{"x":0,"y":2,"z":-6,"color":"#141418"},{"x":0,"y":2,"z":-5,"color":"#141418"},{"x":0,"y":2,"z":-4,"color":"#141418"},{"x":0,"y":2,"z":-3,"color":"#141418"},{"x":0,"y":2,"z":-2,"color":"#141418"},{"x":0,"y":2,"z":-1,"color":"#2b315e"},{"x":0,"y":3,"z":-6,"color":"#141418"},{"x":0,"y":3,"z":-5,"color":"#141418"},{"x":0,"y":3,"z":-4,"color":"#141418"},{"x":0,"y":3,"z":-3,"color":"#141418"},{"x":0,"y":3,"z":-2,"color":"#141418"},{"x":0,"y":3,"z":-1,"color":"#2b315e"},{"x":0,"y":4,"z":-6,"color":"#141418"},{"x":0,"y":4,"z":-5,"color":"#141418"},{"x":0,"y":4,"z":-4,"color":"#141418"},{"x":0,"y":4,"z":-3,"color":"#141418"},{"x":0,"y":4,"z":-2,"color":"#141418"},{"x":0,"y":4,"z":-1,"color":"#2b315e"},{"x":0,"y":5,"z":-6,"color":"#141418"},{"x":0,"y":5,"z":-5,"color":"#141418"},{"x":0,"y":5,"z":-4,"color":"#141418"},{"x":0,"y":5,"z":-3,"color":"#141418"},{"x":0,"y":5,"z":-2,"color":"#141418"},{"x":0,"y":5,"z":-1,"color":"#2b315e"},{"x":1,"y":0,"z":-6,"color":"#141418"},{"x":1,"y":0,"z":-5,"color":"#141418"},{"x":1,"y":0,"z":-4,"color":"#141418"},{"x":1,"y":0,"z":-3,"color":"#141418"},{"x":1,"y":0,"z":-2,"color":"#141418"},{"x":1,"y":0,"z":-1,"color":"#2b315e"},{"x":1,"y":1,"z":-6,"color":"#141418"},{"x":1,"y":1,"z":-5,"color":"#141418"},{"x":1,"y":1,"z":-4,"color":"#141418"},{"x":1,"y":1,"z":-3,"color":"#141418"},{"x":1,"y":1,"z":-2,"color":"#141418"},{"x":1,"y":1,"z":-1,"color":"#2b315e"},{"x":1,"y":2,"z":-6,"color":"#141418"},{"x":1,"y":2,"z":-5,"color":"#141418"},{"x":1,"y":2,"z":-4,"color":"#141418"},{"x":1,"y":2,"z":-3,"color":"#141418"},{"x":1,"y":2,"z":-2,"color":"#141418"},{"x":1,"y":2,"z":-1,"color":"#2b315e"},{"x":1,"y":3,"z":-6,"color":"#141418"},{"x":1,"y":3,"z":-5,"color":"#141418"},{"x":1,"y":3,"z":-4,"color":"#141418"},{"x":1,"y":3,"z":-3,"color":"#141418"},{"x":1,"y":3,"z":-2,"color":"#141418"},{"x":1,"y":3,"z":-1,"color":"#2b315e"},{"x":1,"y":4,"z":-6,"color":"#141418"},{"x":1,"y":4,"z":-5,"color":"#141418"},{"x":1,"y":4,"z":-4,"color":"#141418"},{"x":1,"y":4,"z":-3,"color":"#141418"},{"x":1,"y":4,"z":-2,"color":"#141418"},{"x":1,"y":4,"z":-1,"color":"#2b315e"},{"x":1,"y":5,"z":-6,"color":"#141418"},{"x":1,"y":5,"z":-5,"color":"#141418"},{"x":1,"y":5,"z":-4,"color":"#141418"},{"x":1,"y":5,"z":-3,"color":"#141418"},{"x":1,"y":5,"z":-2,"color":"#141418"},{"x":1,"y":5,"z":-1,"color":"#2b315e"},{"x":2,"y":0,"z":-6,"color":"#141418"},{"x":2,"y":0,"z":-5,"color":"#141418"},{"x":2,"y":0,"z":-4,"color":"#141418"},{"x":2,"y":0,"z":-3,"color":"#141418"},{"x":2,"y":0,"z":-2,"color":"#141418"},{"x":2,"y":0,"z":-1,"color":"#2b315e"},{"x":2,"y":1,"z":-6,"color":"#141418"},{"x":2,"y":1,"z":-5,"color":"#141418"},{"x":2,"y":1,"z":-4,"color":"#141418"},{"x":2,"y":1,"z":-3,"color":"#141418"},{"x":2,"y":1,"z":-2,"color":"#141418"},{"x":2,"y":1,"z":-1,"color":"#2b315e"},{"x":2,"y":2,"z":-6,"color":"#141418"},{"x":2,"y":2,"z":-5,"color":"#141418"},{"x":2,"y":2,"z":-4,"color":"#141418"},{"x":2,"y":2,"z":-3,"color":"#141418"},{"x":2,"y":2,"z":-2,"color":"#141418"},{"x":2,"y":2,"z":-1,"color":"#2b315e"},{"x":2,"y":3,"z":-6,"color":"#141418"},{"x":2,"y":3,"z":-5,"color":"#141418"},{"x":2,"y":3,"z":-4,"color":"#141418"},{"x":2,"y":3,"z":-3,"color":"#141418"},{"x":2,"y":3,"z":-2,"color":"#141418"},{"x":2,"y":3,"z":-1,"color":"#2b315e"},{"x":2,"y":4,"z":-6,"color":"#141418"},{"x":2,"y":4,"z":-5,"color":"#141418"},{"x":2,"y":4,"z":-4,"color":"#141418"},{"x":2,"y":4,"z":-3,"color":"#141418"},{"x":2,"y":4,"z":-2,"color":"#141418"},{"x":2,"y":4,"z":-1,"color":"#2b315e"},{"x":2,"y":5,"z":-6,"color":"#141418"},{"x":2,"y":5,"z":-5,"color":"#141418"},{"x":2,"y":5,"z":-4,"color":"#141418"},{"x":2,"y":5,"z":-3,"color":"#141418"},{"x":2,"y":5,"z":-2,"color":"#141418"},{"x":2,"y":5,"z":-1,"color":"#2b315e"},{"x":3,"y":0,"z":-6,"color":"#141418"},{"x":3,"y":0,"z":-5,"color":"#141418"},{"x":3,"y":0,"z":-4,"color":"#141418"},{"x":3,"y":0,"z":-3,"color":"#141418"},{"x":3,"y":0,"z":-2,"color":"#141418"},{"x":3,"y":0,"z":-1,"color":"#2b315e"},{"x":3,"y":1,"z":-6,"color":"#141418"},{"x":3,"y":1,"z":-5,"color":"#141418"},{"x":3,"y":1,"z":-4,"color":"#141418"},{"x":3,"y":1,"z":-3,"color":"#141418"},{"x":3,"y":1,"z":-2,"color":"#141418"},{"x":3,"y":1,"z":-1,"color":"#2b315e"},{"x":3,"y":2,"z":-6,"color":"#141418"},{"x":3,"y":2,"z":-5,"color":"#141418"},{"x":3,"y":2,"z":-4,"color":"#141418"},{"x":3,"y":2,"z":-3,"color":"#141418"},{"x":3,"y":2,"z":-2,"color":"#141418"},{"x":3,"y":2,"z":-1,"color":"#2b315e"},{"x":3,"y":3,"z":-6,"color":"#141418"},{"x":3,"y":3,"z":-5,"color":"#141418"},{"x":3,"y":3,"z":-4,"color":"#141418"},{"x":3,"y":3,"z":-3,"color":"#141418"},{"x":3,"y":3,"z":-2,"color":"#141418"},{"x":3,"y":3,"z":-1,"color":"#2b315e"},{"x":3,"y":4,"z":-6,"color":"#141418"},{"x":3,"y":4,"z":-5,"color":"#141418"},{"x":3,"y":4,"z":-4,"color":"#141418"},{"x":3,"y":4,"z":-3,"color":"#141418"},{"x":3,"y":4,"z":-2,"color":"#141418"},{"x":3,"y":4,"z":-1,"color":"#2b315e"},{"x":3,"y":5,"z":-6,"color":"#141418"},{"x":3,"y":5,"z":-5,"color":"#141418"},{"x":3,"y":5,"z":-4,"color":"#141418"},{"x":3,"y":5,"z":-3,"color":"#141418"},{"x":3,"y":5,"z":-2,"color":"#141418"},{"x":3,"y":5,"z":-1,"color":"#2b315e"},{"x":4,"y":0,"z":-6,"color":"#141418"},{"x":4,"y":0,"z":-5,"color":"#141418"},{"x":4,"y":0,"z":-4,"color":"#141418"},{"x":4,"y":0,"z":-3,"color":"#141418"},{"x":4,"y":0,"z":-2,"color":"#141418"},{"x":4,"y":0,"z":-1,"color":"#2b315e"},{"x":4,"y":1,"z":-6,"color":"#141418"},{"x":4,"y":1,"z":-5,"color":"#141418"},{"x":4,"y":1,"z":-4,"color":"#141418"},{"x":4,"y":1,"z":-3,"color":"#141418"},{"x":4,"y":1,"z":-2,"color":"#141418"},{"x":4,"y":1,"z":-1,"color":"#2b315e"},{"x":4,"y":2,"z":-6,"color":"#141418"},{"x":4,"y":2,"z":-5,"color":"#141418"},{"x":4,"y":2,"z":-4,"color":"#141418"},{"x":4,"y":2,"z":-3,"color":"#141418"},{"x":4,"y":2,"z":-2,"color":"#141418"},{"x":4,"y":2,"z":-1,"color":"#2b315e"},{"x":4,"y":3,"z":-6,"color":"#141418"},{"x":4,"y":3,"z":-5,"color":"#141418"},{"x":4,"y":3,"z":-4,"color":"#141418"},{"x":4,"y":3,"z":-3,"color":"#141418"},{"x":4,"y":3,"z":-2,"color":"#141418"},{"x":4,"y":3,"z":-1,"color":"#2b315e"},{"x":4,"y":4,"z":-6,"color":"#141418"},{"x":4,"y":4,"z":-5,"color":"#141418"},{"x":4,"y":4,"z":-4,"color":"#141418"},{"x":4,"y":4,"z":-3,"color":"#141418"},{"x":4,"y":4,"z":-2,"color":"#141418"},{"x":4,"y":4,"z":-1,"color":"#2b315e"},{"x":4,"y":5,"z":-6,"color":"#141418"},{"x":4,"y":5,"z":-5,"color":"#141418"},{"x":4,"y":5,"z":-4,"color":"#141418"},{"x":4,"y":5,"z":-3,"color":"#141418"},{"x":4,"y":5,"z":-2,"color":"#141418"},{"x":4,"y":5,"z":-1,"color":"#2b315e"},{"x":5,"y":0,"z":-6,"color":"#141418"},{"x":5,"y":0,"z":-5,"color":"#141418"},{"x":5,"y":0,"z":-4,"color":"#141418"},{"x":5,"y":0,"z":-3,"color":"#141418"},{"x":5,"y":0,"z":-2,"color":"#141418"},{"x":5,"y":0,"z":-1,"color":"#2b315e"},{"x":5,"y":1,"z":-6,"color":"#141418"},{"x":5,"y":1,"z":-5,"color":"#141418"},{"x":5,"y":1,"z":-4,"color":"#141418"},{"x":5,"y":1,"z":-3,"color":"#141418"},{"x":5,"y":1,"z":-2,"color":"#141418"},{"x":5,"y":1,"z":-1,"color":"#2b315e"},{"x":5,"y":2,"z":-6,"color":"#141418"},{"x":5,"y":2,"z":-5,"color":"#141418"},{"x":5,"y":2,"z":-4,"color":"#141418"},{"x":5,"y":2,"z":-3,"color":"#141418"},{"x":5,"y":2,"z":-2,"color":"#141418"},{"x":5,"y":2,"z":-1,"color":"#2b315e"},{"x":5,"y":3,"z":-6,"color":"#141418"},{"x":5,"y":3,"z":-5,"color":"#141418"},{"x":5,"y":3,"z":-4,"color":"#141418"},{"x":5,"y":3,"z":-3,"color":"#141418"},{"x":5,"y":3,"z":-2,"color":"#141418"},{"x":5,"y":3,"z":-1,"color":"#2b315e"},{"x":5,"y":4,"z":-6,"color":"#141418"},{"x":5,"y":4,"z":-5,"color":"#141418"},{"x":5,"y":4,"z":-4,"color":"#141418"},{"x":5,"y":4,"z":-3,"color":"#141418"},{"x":5,"y":4,"z":-2,"color":"#141418"},{"x":5,"y":4,"z":-1,"color":"#2b315e"},{"x":5,"y":5,"z":-6,"color":"#141418"},{"x":5,"y":5,"z":-5,"color":"#141418"},{"x":5,"y":5,"z":-4,"color":"#141418"},{"x":5,"y":5,"z":-3,"color":"#141418"},{"x":5,"y":5,"z":-2,"color":"#141418"},{"x":5,"y":5,"z":-1,"color":"#2b315e"},{"x":6,"y":6,"z":4,"color":"#2b315e"},{"x":6,"y":6,"z":5,"color":"#2b315e"},{"x":6,"y":6,"z":6,"color":"#2b315e"},{"x":6,"y":6,"z":7,"color":"#2b315e"},{"x":6,"y":7,"z":4,"color":"#2b315e"},{"x":6,"y":7,"z":5,"color":"#2b315e"},{"x":6,"y":7,"z":6,"color":"#2b315e"},{"x":6,"y":7,"z":7,"color":"#2b315e"},{"x":6,"y":8,"z":4,"color":"#2b315e"},{"x":6,"y":8,"z":5,"color":"#2b315e"},{"x":6,"y":8,"z":6,"color":"#2b315e"},{"x":6,"y":8,"z":7,"color":"#2b315e"},{"x":6,"y":9,"z":4,"color":"#2b315e"},{"x":6,"y":9,"z":5,"color":"#2b315e"},{"x":6,"y":9,"z":6,"color":"#2b315e"},{"x":6,"y":9,"z":7,"color":"#2b315e"},{"x":6,"y":10,"z":4,"color":"#2b315e"},{"x":6,"y":10,"z":5,"color":"#2b315e"},{"x":6,"y":10,"z":6,"color":"#2b315e"},{"x":6,"y":10,"z":7,"color":"#2b315e"},{"x":6,"y":11,"z":4,"color":"#2b315e"},{"x":6,"y":11,"z":5,"color":"#2b315e"},{"x":6,"y":11,"z":6,"color":"#2b315e"},{"x":6,"y":11,"z":7,"color":"#2b315e"},{"x":7,"y":6,"z":4,"color":"#2b315e"},{"x":7,"y":6,"z":5,"color":"#2b315e"},{"x":7,"y":6,"z":6,"color":"#2b315e"},{"x":7,"y":6,"z":7,"color":"#2b315e"},{"x":7,"y":7,"z":4,"color":"#2b315e"},{"x":7,"y":7,"z":5,"color":"#2b315e"},{"x":7,"y":7,"z":6,"color":"#2b315e"},{"x":7,"y":7,"z":7,"color":"#2b315e"},{"x":7,"y":8,"z":4,"color":"#2b315e"},{"x":7,"y":8,"z":5,"color":"#2b315e"},{"x":7,"y":8,"z":6,"color":"#2b315e"},{"x":7,"y":8,"z":7,"color":"#2b315e"},{"x":7,"y":9,"z":4,"color":"#2b315e"},{"x":7,"y":9,"z":5,"color":"#2b315e"},{"x":7,"y":9,"z":6,"color":"#2b315e"},{"x":7,"y":9,"z":7,"color":"#2b315e"},{"x":7,"y":10,"z":4,"color":"#2b315e"},{"x":7,"y":10,"z":5,"color":"#2b315e"},{"x":7,"y":10,"z":6,"color":"#2b315e"},{"x":7,"y":10,"z":7,"color":"#2b315e"},{"x":7,"y":11,"z":4,"color":"#2b315e"},{"x":7,"y":11,"z":5,"color":"#2b315e"},{"x":7,"y":11,"z":6,"color":"#2b315e"},{"x":7,"y":11,"z":7,"color":"#2b315e"},{"x":8,"y":6,"z":4,"color":"#2b315e"},{"x":8,"y":6,"z":5,"color":"#2b315e"},{"x":8,"y":6,"z":6,"color":"#2b315e"},{"x":8,"y":6,"z":7,"color":"#2b315e"},{"x":8,"y":7,"z":4,"color":"#2b315e"},{"x":8,"y":7,"z":5,"color":"#2b315e"},{"x":8,"y":7,"z":6,"color":"#2b315e"},{"x":8,"y":7,"z":7,"color":"#2b315e"},{"x":8,"y":8,"z":4,"color":"#2b315e"},{"x":8,"y":8,"z":5,"color":"#2b315e"},{"x":8,"y":8,"z":6,"color":"#2b315e"},{"x":8,"y":8,"z":7,"color":"#2b315e"},{"x":8,"y":9,"z":4,"color":"#2b315e"},{"x":8,"y":9,"z":5,"color":"#2b315e"},{"x":8,"y":9,"z":6,"color":"#2b315e"},{"x":8,"y":9,"z":7,"color":"#2b315e"},{"x":8,"y":10,"z":4,"color":"#2b315e"},{"x":8,"y":10,"z":5,"color":"#2b315e"},{"x":8,"y":10,"z":6,"color":"#2b315e"},{"x":8,"y":10,"z":7,"color":"#2b315e"},{"x":8,"y":11,"z":4,"color":"#2b315e"},{"x":8,"y":11,"z":5,"color":"#2b315e"},{"x":8,"y":11,"z":6,"color":"#2b315e"},{"x":8,"y":11,"z":7,"color":"#2b315e"},{"x":9,"y":6,"z":4,"color":"#2b315e"},{"x":9,"y":6,"z":5,"color":"#2b315e"},{"x":9,"y":6,"z":6,"color":"#2b315e"},{"x":9,"y":6,"z":7,"color":"#2b315e"},{"x":9,"y":7,"z":4,"color":"#2b315e"},{"x":9,"y":7,"z":5,"color":"#2b315e"},{"x":9,"y":7,"z":6,"color":"#2b315e"},{"x":9,"y":7,"z":7,"color":"#2b315e"},{"x":9,"y":8,"z":4,"color":"#2b315e"},{"x":9,"y":8,"z":5,"color":"#2b315e"},{"x":9,"y":8,"z":6,"color":"#2b315e"},{"x":9,"y":8,"z":7,"color":"#2b315e"},{"x":9,"y":9,"z":4,"color":"#2b315e"},{"x":9,"y":9,"z":5,"color":"#2b315e"},{"x":9,"y":9,"z":6,"color":"#2b315e"},{"x":9,"y":9,"z":7,"color":"#2b315e"},{"x":9,"y":10,"z":4,"color":"#2b315e"},{"x":9,"y":10,"z":5,"color":"#2b315e"},{"x":9,"y":10,"z":6,"color":"#2b315e"},{"x":9,"y":10,"z":7,"color":"#2b315e"},{"x":9,"y":11,"z":4,"color":"#2b315e"},{"x":9,"y":11,"z":5,"color":"#2b315e"},{"x":9,"y":11,"z":6,"color":"#2b315e"},{"x":9,"y":11,"z":7,"color":"#2b315e"},{"x":10,"y":6,"z":4,"color":"#2b315e"},{"x":10,"y":6,"z":5,"color":"#2b315e"},{"x":10,"y":6,"z":6,"color":"#2b315e"},{"x":10,"y":6,"z":7,"color":"#2b315e"},{"x":10,"y":7,"z":4,"color":"#2b315e"},{"x":10,"y":7,"z":5,"color":"#2b315e"},{"x":10,"y":7,"z":6,"color":"#2b315e"},{"x":10,"y":7,"z":7,"color":"#2b315e"},{"x":10,"y":8,"z":4,"color":"#2b315e"},{"x":10,"y":8,"z":5,"color":"#2b315e"},{"x":10,"y":8,"z":6,"color":"#2b315e"},{"x":10,"y":8,"z":7,"color":"#2b315e"},{"x":10,"y":9,"z":4,"color":"#2b315e"},{"x":10,"y":9,"z":5,"color":"#2b315e"},{"x":10,"y":9,"z":6,"color":"#2b315e"},{"x":10,"y":9,"z":7,"color":"#2b315e"},{"x":10,"y":10,"z":4,"color":"#2b315e"},{"x":10,"y":10,"z":5,"color":"#2b315e"},{"x":10,"y":10,"z":6,"color":"#2b315e"},{"x":10,"y":10,"z":7,"color":"#2b315e"},{"x":10,"y":11,"z":4,"color":"#2b315e"},{"x":10,"y":11,"z":5,"color":"#2b315e"},{"x":10,"y":11,"z":6,"color":"#2b315e"},{"x":10,"y":11,"z":7,"color":"#2b315e"},{"x":11,"y":6,"z":4,"color":"#2b315e"},{"x":11,"y":6,"z":5,"color":"#2b315e"},{"x":11,"y":6,"z":6,"color":"#2b315e"},{"x":11,"y":6,"z":7,"color":"#2b315e"},{"x":11,"y":7,"z":4,"color":"#2b315e"},{"x":11,"y":7,"z":5,"color":"#2b315e"},{"x":11,"y":7,"z":6,"color":"#2b315e"},{"x":11,"y":7,"z":7,"color":"#2b315e"},{"x":11,"y":8,"z":4,"color":"#2b315e"},{"x":11,"y":8,"z":5,"color":"#2b315e"},{"x":11,"y":8,"z":6,"color":"#2b315e"},{"x":11,"y":8,"z":7,"color":"#2b315e"},{"x":11,"y":9,"z":4,"color":"#2b315e"},{"x":11,"y":9,"z":5,"color":"#2b315e"},{"x":11,"y":9,"z":6,"color":"#2b315e"},{"x":11,"y":9,"z":7,"color":"#2b315e"},{"x":11,"y":10,"z":4,"color":"#2b315e"},{"x":11,"y":10,"z":5,"color":"#2b315e"},{"x":11,"y":10,"z":6,"color":"#2b315e"},{"x":11,"y":10,"z":7,"color":"#2b315e"},{"x":11,"y":11,"z":4,"color":"#2b315e"},{"x":11,"y":11,"z":5,"color":"#2b315e"},{"x":11,"y":11,"z":6,"color":"#2b315e"},{"x":11,"y":11,"z":7,"color":"#2b315e"},{"x":0,"y":6,"z":1,"color":"#2b315e"},{"x":0,"y":6,"z":2,"color":"#2b315e"},{"x":0,"y":6,"z":3,"color":"#2b315e"},{"x":0,"y":6,"z":4,"color":"#2b315e"},{"x":0,"y":7,"z":1,"color":"#2b315e"},{"x":0,"y":7,"z":2,"color":"#2b315e"},{"x":0,"y":7,"z":3,"color":"#2b315e"},{"x":0,"y":7,"z":4,"color":"#2b315e"},{"x":0,"y":8,"z":1,"color":"#2b315e"},{"x":0,"y":8,"z":2,"color":"#2b315e"},{"x":0,"y":8,"z":3,"color":"#2b315e"},{"x":0,"y":8,"z":4,"color":"#2b315e"},{"x":0,"y":9,"z":1,"color":"#2b315e"},{"x":0,"y":9,"z":2,"color":"#2b315e"},{"x":0,"y":9,"z":3,"color":"#2b315e"},{"x":0,"y":9,"z":4,"color":"#2b315e"},{"x":0,"y":10,"z":1,"color":"#2b315e"},{"x":0,"y":10,"z":2,"color":"#2b315e"},{"x":0,"y":10,"z":3,"color":"#2b315e"},{"x":0,"y":10,"z":4,"color":"#2b315e"},{"x":0,"y":11,"z":1,"color":"#2b315e"},{"x":0,"y":11,"z":2,"color":"#2b315e"},{"x":0,"y":11,"z":3,"color":"#2b315e"},{"x":0,"y":11,"z":4,"color":"#2b315e"},{"x":1,"y":6,"z":1,"color":"#2b315e"},{"x":1,"y":6,"z":2,"color":"#2b315e"},{"x":1,"y":6,"z":3,"color":"#2b315e"},{"x":1,"y":6,"z":4,"color":"#2b315e"},{"x":1,"y":7,"z":1,"color":"#2b315e"},{"x":1,"y":7,"z":2,"color":"#2b315e"},{"x":1,"y":7,"z":3,"color":"#2b315e"},{"x":1,"y":7,"z":4,"color":"#2b315e"},{"x":1,"y":8,"z":1,"color":"#2b315e"},{"x":1,"y":8,"z":2,"color":"#2b315e"},{"x":1,"y":8,"z":3,"color":"#2b315e"},{"x":1,"y":8,"z":4,"color":"#2b315e"},{"x":1,"y":9,"z":1,"color":"#2b315e"},{"x":1,"y":9,"z":2,"color":"#2b315e"},{"x":1,"y":9,"z":3,"color":"#2b315e"},{"x":1,"y":9,"z":4,"color":"#2b315e"},{"x":1,"y":10,"z":1,"color":"#2b315e"},{"x":1,"y":10,"z":2,"color":"#2b315e"},{"x":1,"y":10,"z":3,"color":"#2b315e"},{"x":1,"y":10,"z":4,"color":"#2b315e"},{"x":1,"y":11,"z":1,"color":"#2b315e"},{"x":1,"y":11,"z":2,"color":"#2b315e"},{"x":1,"y":11,"z":3,"color":"#2b315e"},{"x":1,"y":11,"z":4,"color":"#2b315e"},{"x":2,"y":6,"z":1,"color":"#2b315e"},{"x":2,"y":6,"z":2,"color":"#2b315e"},{"x":2,"y":6,"z":3,"color":"#2b315e"},{"x":2,"y":6,"z":4,"color":"#2b315e"},{"x":2,"y":7,"z":1,"color":"#2b315e"},{"x":2,"y":7,"z":2,"color":"#2b315e"},{"x":2,"y":7,"z":3,"color":"#2b315e"},{"x":2,"y":7,"z":4,"color":"#2b315e"},{"x":2,"y":8,"z":1,"color":"#2b315e"},{"x":2,"y":8,"z":2,"color":"#2b315e"},{"x":2,"y":8,"z":3,"color":"#2b315e"},{"x":2,"y":8,"z":4,"color":"#2b315e"},{"x":2,"y":9,"z":1,"color":"#2b315e"},{"x":2,"y":9,"z":2,"color":"#2b315e"},{"x":2,"y":9,"z":3,"color":"#2b315e"},{"x":2,"y":9,"z":4,"color":"#2b315e"},{"x":2,"y":10,"z":1,"color":"#2b315e"},{"x":2,"y":10,"z":2,"color":"#2b315e"},{"x":2,"y":10,"z":3,"color":"#2b315e"},{"x":2,"y":10,"z":4,"color":"#2b315e"},{"x":2,"y":11,"z":1,"color":"#2b315e"},{"x":2,"y":11,"z":2,"color":"#2b315e"},{"x":2,"y":11,"z":3,"color":"#2b315e"},{"x":2,"y":11,"z":4,"color":"#2b315e"},{"x":3,"y":6,"z":1,"color":"#2b315e"},{"x":3,"y":6,"z":2,"color":"#2b315e"},{"x":3,"y":6,"z":3,"color":"#2b315e"},{"x":3,"y":6,"z":4,"color":"#2b315e"},{"x":3,"y":7,"z":1,"color":"#2b315e"},{"x":3,"y":7,"z":2,"color":"#2b315e"},{"x":3,"y":7,"z":3,"color":"#2b315e"},{"x":3,"y":7,"z":4,"color":"#2b315e"},{"x":3,"y":8,"z":1,"color":"#2b315e"},{"x":3,"y":8,"z":2,"color":"#2b315e"},{"x":3,"y":8,"z":3,"color":"#2b315e"},{"x":3,"y":8,"z":4,"color":"#2b315e"},{"x":3,"y":9,"z":1,"color":"#2b315e"},{"x":3,"y":9,"z":2,"color":"#2b315e"},{"x":3,"y":9,"z":3,"color":"#2b315e"},{"x":3,"y":9,"z":4,"color":"#2b315e"},{"x":3,"y":10,"z":1,"color":"#2b315e"},{"x":3,"y":10,"z":2,"color":"#2b315e"},{"x":3,"y":10,"z":3,"color":"#2b315e"},{"x":3,"y":10,"z":4,"color":"#2b315e"},{"x":3,"y":11,"z":1,"color":"#2b315e"},{"x":3,"y":11,"z":2,"color":"#2b315e"},{"x":3,"y":11,"z":3,"color":"#2b315e"},{"x":3,"y":11,"z":4,"color":"#2b315e"},{"x":4,"y":6,"z":1,"color":"#2b315e"},{"x":4,"y":6,"z":2,"color":"#2b315e"},{"x":4,"y":6,"z":3,"color":"#2b315e"},{"x":4,"y":6,"z":4,"color":"#2b315e"},{"x":4,"y":7,"z":1,"color":"#2b315e"},{"x":4,"y":7,"z":2,"color":"#2b315e"},{"x":4,"y":7,"z":3,"color":"#2b315e"},{"x":4,"y":7,"z":4,"color":"#2b315e"},{"x":4,"y":8,"z":1,"color":"#2b315e"},{"x":4,"y":8,"z":2,"color":"#2b315e"},{"x":4,"y":8,"z":3,"color":"#2b315e"},{"x":4,"y":8,"z":4,"color":"#2b315e"},{"x":4,"y":9,"z":1,"color":"#2b315e"},{"x":4,"y":9,"z":2,"color":"#2b315e"},{"x":4,"y":9,"z":3,"color":"#2b315e"},{"x":4,"y":9,"z":4,"color":"#2b315e"},{"x":4,"y":10,"z":1,"color":"#2b315e"},{"x":4,"y":10,"z":2,"color":"#2b315e"},{"x":4,"y":10,"z":3,"color":"#2b315e"},{"x":4,"y":10,"z":4,"color":"#2b315e"},{"x":4,"y":11,"z":1,"color":"#2b315e"},{"x":4,"y":11,"z":2,"color":"#2b315e"},{"x":4,"y":11,"z":3,"color":"#2b315e"},{"x":4,"y":11,"z":4,"color":"#2b315e"},{"x":5,"y":6,"z":1,"color":"#2b315e"},{"x":5,"y":6,"z":2,"color":"#2b315e"},{"x":5,"y":6,"z":3,"color":"#2b315e"},{"x":5,"y":6,"z":4,"color":"#2b315e"},{"x":5,"y":7,"z":1,"color":"#2b315e"},{"x":5,"y":7,"z":2,"color":"#2b315e"},{"x":5,"y":7,"z":3,"color":"#2b315e"},{"x":5,"y":7,"z":4,"color":"#2b315e"},{"x":5,"y":8,"z":1,"color":"#2b315e"},{"x":5,"y":8,"z":2,"color":"#2b315e"},{"x":5,"y":8,"z":3,"color":"#2b315e"},{"x":5,"y":8,"z":4,"color":"#2b315e"},{"x":5,"y":9,"z":1,"color":"#2b315e"},{"x":5,"y":9,"z":2,"color":"#2b315e"},{"x":5,"y":9,"z":3,"color":"#2b315e"},{"x":5,"y":9,"z":4,"color":"#2b315e"},{"x":5,"y":10,"z":1,"color":"#2b315e"},{"x":5,"y":10,"z":2,"color":"#2b315e"},{"x":5,"y":10,"z":3,"color":"#2b315e"},{"x":5,"y":10,"z":4,"color":"#2b315e"},{"x":5,"y":11,"z":1,"color":"#2b315e"},{"x":5,"y":11,"z":2,"color":"#2b315e"},{"x":5,"y":11,"z":3,"color":"#2b315e"},{"x":5,"y":11,"z":4,"color":"#2b315e"},{"x":0,"y":0,"z":0,"color":"#2b315e"},{"x":0,"y":0,"z":1,"color":"#2b315e"},{"x":0,"y":1,"z":0,"color":"#2b315e"},{"x":0,"y":1,"z":1,"color":"#2b315e"},{"x":0,"y":2,"z":0,"color":"#2b315e"},{"x":0,"y":2,"z":1,"color":"#2b315e"},{"x":0,"y":3,"z":0,"color":"#2b315e"},{"x":0,"y":3,"z":1,"color":"#2b315e"},{"x":0,"y":4,"z":0,"color":"#2b315e"},{"x":0,"y":4,"z":1,"color":"#2b315e"},{"x":0,"y":5,"z":0,"color":"#2b315e"},{"x":0,"y":5,"z":1,"color":"#2b315e"},{"x":1,"y":0,"z":0,"color":"#2b315e"},{"x":1,"y":0,"z":1,"color":"#2b315e"},{"x":1,"y":1,"z":0,"color":"#2b315e"},{"x":1,"y":1,"z":1,"color":"#2b315e"},{"x":1,"y":2,"z":0,"color":"#2b315e"},{"x":1,"y":2,"z":1,"color":"#2b315e"},{"x":1,"y":3,"z":0,"color":"#2b315e"},{"x":1,"y":3,"z":1,"color":"#2b315e"},{"x":1,"y":4,"z":0,"color":"#2b315e"},{"x":1,"y":4,"z":1,"color":"#2b315e"},{"x":1,"y":5,"z":0,"color":"#2b315e"},{"x":1,"y":5,"z":1,"color":"#2b315e"},{"x":2,"y":0,"z":0,"color":"#2b315e"},{"x":2,"y":0,"z":1,"color":"#2b315e"},{"x":2,"y":1,"z":0,"color":"#2b315e"},{"x":2,"y":1,"z":1,"color":"#2b315e"},{"x":2,"y":2,"z":0,"color":"#2b315e"},{"x":2,"y":2,"z":1,"color":"#2b315e"},{"x":2,"y":3,"z":0,"color":"#2b315e"},{"x":2,"y":3,"z":1,"color":"#2b315e"},{"x":2,"y":4,"z":0,"color":"#2b315e"},{"x":2,"y":4,"z":1,"color":"#2b315e"},{"x":2,"y":5,"z":0,"color":"#2b315e"},{"x":2,"y":5,"z":1,"color":"#2b315e"},{"x":3,"y":0,"z":0,"color":"#2b315e"},{"x":3,"y":0,"z":1,"color":"#2b315e"},{"x":3,"y":1,"z":0,"color":"#2b315e"},{"x":3,"y":1,"z":1,"color":"#2b315e"},{"x":3,"y":2,"z":0,"color":"#2b315e"},{"x":3,"y":2,"z":1,"color":"#2b315e"},{"x":3,"y":3,"z":0,"color":"#2b315e"},{"x":3,"y":3,"z":1,"color":"#2b315e"},{"x":3,"y":4,"z":0,"color":"#2b315e"},{"x":3,"y":4,"z":1,"color":"#2b315e"},{"x":3,"y":5,"z":0,"color":"#2b315e"},{"x":3,"y":5,"z":1,"color":"#2b315e"},{"x":4,"y":0,"z":0,"color":"#2b315e"},{"x":4,"y":0,"z":1,"color":"#2b315e"},{"x":4,"y":1,"z":0,"color":"#2b315e"},{"x":4,"y":1,"z":1,"color":"#2b315e"},{"x":4,"y":2,"z":0,"color":"#2b315e"},{"x":4,"y":2,"z":1,"color":"#2b315e"},{"x":4,"y":3,"z":0,"color":"#2b315e"},{"x":4,"y":3,"z":1,"color":"#2b315e"},{"x":4,"y":4,"z":0,"color":"#2b315e"},{"x":4,"y":4,"z":1,"color":"#2b315e"},{"x":4,"y":5,"z":0,"color":"#2b315e"},{"x":4,"y":5,"z":1,"color":"#2b315e"},{"x":5,"y":0,"z":0,"color":"#2b315e"},{"x":5,"y":0,"z":1,"color":"#2b315e"},{"x":5,"y":1,"z":0,"color":"#2b315e"},{"x":5,"y":1,"z":1,"color":"#2b315e"},{"x":5,"y":2,"z":0,"color":"#2b315e"},{"x":5,"y":2,"z":1,"color":"#2b315e"},{"x":5,"y":3,"z":0,"color":"#2b315e"},{"x":5,"y":3,"z":1,"color":"#2b315e"},{"x":5,"y":4,"z":0,"color":"#2b315e"},{"x":5,"y":4,"z":1,"color":"#2b315e"},{"x":5,"y":5,"z":0,"color":"#2b315e"},{"x":5,"y":5,"z":1,"color":"#2b315e"},{"x":0,"y":11,"z":0,"color":"#2b315e"},{"x":0,"y":11,"z":5,"color":"#2b315e"},{"x":0,"y":11,"z":6,"color":"#2b315e"},{"x":0,"y":12,"z":0,"color":"#4f8a3f"},{"x":0,"y":12,"z":1,"color":"#37642a"},{"x":0,"y":12,"z":2,"color":"#4f8a3f"},{"x":0,"y":12,"z":3,"color":"#4f8a3f"},{"x":0,"y":12,"z":4,"color":"#4f8a3f"},{"x":0,"y":12,"z":5,"color":"#37642a"},{"x":0,"y":12,"z":6,"color":"#4f8a3f"},{"x":1,"y":11,"z":0,"color":"#2b315e"},{"x":1,"y":11,"z":5,"color":"#2b315e"},{"x":1,"y":11,"z":6,"color":"#2b315e"},{"x":1,"y":12,"z":0,"color":"#37642a"},{"x":1,"y":12,"z":1,"color":"#d9c64a"},{"x":1,"y":12,"z":2,"color":"#37642a"},{"x":1,"y":12,"z":3,"color":"#37642a"},{"x":1,"y":12,"z":4,"color":"#37642a"},{"x":1,"y":12,"z":5,"color":"#d9c64a"},{"x":1,"y":12,"z":6,"color":"#37642a"},{"x":2,"y":11,"z":0,"color":"#2b315e"},{"x":2,"y":11,"z":5,"color":"#2b315e"},{"x":2,"y":11,"z":6,"color":"#2b315e"},{"x":2,"y":12,"z":0,"color":"#4f8a3f"},{"x":2,"y":12,"z":1,"color":"#37642a"},{"x":2,"y":12,"z":2,"color":"#4f8a3f"},{"x":2,"y":12,"z":3,"color":"#4f8a3f"},{"x":2,"y":12,"z":4,"color":"#4f8a3f"},{"x":2,"y":12,"z":5,"color":"#37642a"},{"x":2,"y":12,"z":6,"color":"#4f8a3f"},{"x":3,"y":11,"z":0,"color":"#2b315e"},{"x":3,"y":11,"z":5,"color":"#2b315e"},{"x":3,"y":11,"z":6,"color":"#2b315e"},{"x":3,"y":12,"z":0,"color":"#4f8a3f"},{"x":3,"y":12,"z":1,"color":"#37642a"},{"x":3,"y":12,"z":2,"color":"#4f8a3f"},{"x":3,"y":12,"z":3,"color":"#4f8a3f"},{"x":3,"y":12,"z":4,"color":"#4f8a3f"},{"x":3,"y":12,"z":5,"color":"#37642a"},{"x":3,"y":12,"z":6,"color":"#4f8a3f"},{"x":4,"y":11,"z":0,"color":"#2b315e"},{"x":4,"y":11,"z":5,"color":"#2b315e"},{"x":4,"y":11,"z":6,"color":"#2b315e"},{"x":4,"y":12,"z":0,"color":"#4f8a3f"},{"x":4,"y":12,"z":1,"color":"#37642a"},{"x":4,"y":12,"z":2,"color":"#4f8a3f"},{"x":4,"y":12,"z":3,"color":"#4f8a3f"},{"x":4,"y":12,"z":4,"color":"#4f8a3f"},{"x":4,"y":12,"z":5,"color":"#37642a"},{"x":4,"y":12,"z":6,"color":"#4f8a3f"},{"x":5,"y":11,"z":0,"color":"#2b315e"},{"x":5,"y":11,"z":5,"color":"#2b315e"},{"x":5,"y":11,"z":6,"color":"#2b315e"},{"x":5,"y":12,"z":0,"color":"#37642a"},{"x":5,"y":12,"z":1,"color":"#d9c64a"},{"x":5,"y":12,"z":2,"color":"#37642a"},{"x":5,"y":12,"z":3,"color":"#37642a"},{"x":5,"y":12,"z":4,"color":"#37642a"},{"x":5,"y":12,"z":5,"color":"#d9c64a"},{"x":5,"y":12,"z":6,"color":"#37642a"},{"x":6,"y":11,"z":0,"color":"#2b315e"},{"x":6,"y":11,"z":1,"color":"#2b315e"},{"x":6,"y":11,"z":2,"color":"#2b315e"},{"x":6,"y":11,"z":3,"color":"#2b315e"},{"x":6,"y":12,"z":0,"color":"#4f8a3f"},{"x":6,"y":12,"z":1,"color":"#37642a"},{"x":6,"y":12,"z":2,"color":"#4f8a3f"},{"x":6,"y":12,"z":3,"color":"#4f8a3f"},{"x":6,"y":12,"z":4,"color":"#4f8a3f"},{"x":6,"y":12,"z":5,"color":"#37642a"},{"x":6,"y":12,"z":6,"color":"#4f8a3f"},{"x":7,"y":11,"z":0,"color":"#2b315e"},{"x":7,"y":11,"z":1,"color":"#2b315e"},{"x":7,"y":11,"z":2,"color":"#2b315e"},{"x":7,"y":11,"z":3,"color":"#2b315e"},{"x":7,"y":12,"z":0,"color":"#4f8a3f"},{"x":7,"y":12,"z":1,"color":"#37642a"},{"x":7,"y":12,"z":2,"color":"#4f8a3f"},{"x":7,"y":12,"z":3,"color":"#4f8a3f"},{"x":7,"y":12,"z":4,"color":"#4f8a3f"},{"x":7,"y":12,"z":5,"color":"#37642a"},{"x":7,"y":12,"z":6,"color":"#4f8a3f"},{"x":8,"y":11,"z":0,"color":"#2b315e"},{"x":8,"y":11,"z":1,"color":"#2b315e"},{"x":8,"y":11,"z":2,"color":"#2b315e"},{"x":8,"y":11,"z":3,"color":"#2b315e"},{"x":8,"y":12,"z":0,"color":"#4f8a3f"},{"x":8,"y":12,"z":1,"color":"#37642a"},{"x":8,"y":12,"z":2,"color":"#4f8a3f"},{"x":8,"y":12,"z":3,"color":"#4f8a3f"},{"x":8,"y":12,"z":4,"color":"#4f8a3f"},{"x":8,"y":12,"z":5,"color":"#37642a"},{"x":8,"y":12,"z":6,"color":"#4f8a3f"},{"x":9,"y":11,"z":0,"color":"#2b315e"},{"x":9,"y":11,"z":1,"color":"#2b315e"},{"x":9,"y":11,"z":2,"color":"#2b315e"},{"x":9,"y":11,"z":3,"color":"#2b315e"},{"x":9,"y":12,"z":0,"color":"#37642a"},{"x":9,"y":12,"z":1,"color":"#d9c64a"},{"x":9,"y":12,"z":2,"color":"#37642a"},{"x":9,"y":12,"z":3,"color":"#37642a"},{"x":9,"y":12,"z":4,"color":"#37642a"},{"x":9,"y":12,"z":5,"color":"#d9c64a"},{"x":9,"y":12,"z":6,"color":"#37642a"},{"x":10,"y":11,"z":0,"color":"#2b315e"},{"x":10,"y":11,"z":1,"color":"#2b315e"},{"x":10,"y":11,"z":2,"color":"#2b315e"},{"x":10,"y":11,"z":3,"color":"#2b315e"},{"x":10,"y":12,"z":0,"color":"#4f8a3f"},{"x":10,"y":12,"z":1,"color":"#37642a"},{"x":10,"y":12,"z":2,"color":"#4f8a3f"},{"x":10,"y":12,"z":3,"color":"#4f8a3f"},{"x":10,"y":12,"z":4,"color":"#4f8a3f"},{"x":10,"y":12,"z":5,"color":"#37642a"},{"x":10,"y":12,"z":6,"color":"#4f8a3f"},{"x":11,"y":11,"z":0,"color":"#2b315e"},{"x":11,"y":11,"z":1,"color":"#2b315e"},{"x":11,"y":11,"z":2,"color":"#2b315e"},{"x":11,"y":11,"z":3,"color":"#2b315e"},{"x":11,"y":12,"z":0,"color":"#4f8a3f"},{"x":11,"y":12,"z":1,"color":"#37642a"},{"x":11,"y":12,"z":2,"color":"#4f8a3f"},{"x":11,"y":12,"z":3,"color":"#4f8a3f"},{"x":11,"y":12,"z":4,"color":"#4f8a3f"},{"x":11,"y":12,"z":5,"color":"#37642a"},{"x":11,"y":12,"z":6,"color":"#4f8a3f"},{"x":0,"y":13,"z":0,"color":"#37642a"},{"x":0,"y":13,"z":1,"color":"#d9c64a"},{"x":0,"y":13,"z":2,"color":"#37642a"},{"x":0,"y":13,"z":3,"color":"#37642a"},{"x":0,"y":13,"z":4,"color":"#37642a"},{"x":0,"y":13,"z":5,"color":"#d9c64a"},{"x":0,"y":13,"z":6,"color":"#37642a"},{"x":0,"y":14,"z":0,"color":"#4f8a3f"},{"x":0,"y":14,"z":1,"color":"#37642a"},{"x":0,"y":14,"z":2,"color":"#4f8a3f"},{"x":0,"y":14,"z":3,"color":"#4f8a3f"},{"x":0,"y":14,"z":4,"color":"#4f8a3f"},{"x":0,"y":14,"z":5,"color":"#37642a"},{"x":0,"y":14,"z":6,"color":"#4f8a3f"},{"x":0,"y":15,"z":0,"color":"#4f8a3f"},{"x":0,"y":15,"z":1,"color":"#37642a"},{"x":0,"y":15,"z":2,"color":"#4f8a3f"},{"x":0,"y":15,"z":3,"color":"#4f8a3f"},{"x":0,"y":15,"z":4,"color":"#4f8a3f"},{"x":0,"y":15,"z":5,"color":"#37642a"},{"x":0,"y":15,"z":6,"color":"#4f8a3f"},{"x":0,"y":16,"z":0,"color":"#4f8a3f"},{"x":0,"y":16,"z":1,"color":"#37642a"},{"x":0,"y":16,"z":2,"color":"#4f8a3f"},{"x":0,"y":16,"z":3,"color":"#4f8a3f"},{"x":0,"y":16,"z":4,"color":"#4f8a3f"},{"x":0,"y":16,"z":5,"color":"#37642a"},{"x":0,"y":16,"z":6,"color":"#4f8a3f"},{"x":0,"y":17,"z":0,"color":"#37642a"},{"x":0,"y":17,"z":1,"color":"#d9c64a"},{"x":0,"y":17,"z":2,"color":"#37642a"},{"x":0,"y":17,"z":3,"color":"#37642a"},{"x":0,"y":17,"z":4,"color":"#37642a"},{"x":0,"y":17,"z":5,"color":"#d9c64a"},{"x":0,"y":17,"z":6,"color":"#37642a"},{"x":0,"y":18,"z":0,"color":"#4f8a3f"},{"x":0,"y":18,"z":1,"color":"#37642a"},{"x":0,"y":18,"z":2,"color":"#4f8a3f"},{"x":0,"y":18,"z":3,"color":"#4f8a3f"},{"x":0,"y":18,"z":4,"color":"#4f8a3f"},{"x":0,"y":18,"z":5,"color":"#37642a"},{"x":0,"y":18,"z":6,"color":"#4f8a3f"},{"x":0,"y":19,"z":0,"color":"#4f8a3f"},{"x":0,"y":19,"z":1,"color":"#37642a"},{"x":0,"y":19,"z":2,"color":"#4f8a3f"},{"x":0,"y":19,"z":3,"color":"#4f8a3f"},{"x":0,"y":19,"z":4,"color":"#4f8a3f"},{"x":0,"y":19,"z":5,"color":"#37642a"},{"x":0,"y":19,"z":6,"color":"#4f8a3f"},{"x":0,"y":20,"z":0,"color":"#4f8a3f"},{"x":0,"y":20,"z":1,"color":"#37642a"},{"x":0,"y":20,"z":2,"color":"#4f8a3f"},{"x":0,"y":20,"z":3,"color":"#4f8a3f"},{"x":0,"y":20,"z":4,"color":"#4f8a3f"},{"x":0,"y":20,"z":5,"color":"#37642a"},{"x":0,"y":20,"z":6,"color":"#4f8a3f"},{"x":0,"y":21,"z":0,"color":"#37642a"},{"x":0,"y":21,"z":1,"color":"#d9c64a"},{"x":0,"y":21,"z":2,"color":"#37642a"},{"x":0,"y":21,"z":3,"color":"#37642a"},{"x":0,"y":21,"z":4,"color":"#37642a"},{"x":0,"y":21,"z":5,"color":"#d9c64a"},{"x":0,"y":21,"z":6,"color":"#37642a"},{"x":0,"y":22,"z":0,"color":"#4f8a3f"},{"x":0,"y":22,"z":1,"color":"#37642a"},{"x":0,"y":22,"z":2,"color":"#4f8a3f"},{"x":0,"y":22,"z":3,"color":"#4f8a3f"},{"x":0,"y":22,"z":4,"color":"#4f8a3f"},{"x":0,"y":22,"z":5,"color":"#37642a"},{"x":0,"y":22,"z":6,"color":"#4f8a3f"},{"x":0,"y":23,"z":0,"color":"#4f8a3f"},{"x":0,"y":23,"z":1,"color":"#37642a"},{"x":0,"y":23,"z":2,"color":"#4f8a3f"},{"x":0,"y":23,"z":3,"color":"#4f8a3f"},{"x":0,"y":23,"z":4,"color":"#4f8a3f"},{"x":0,"y":23,"z":5,"color":"#37642a"},{"x":0,"y":23,"z":6,"color":"#4f8a3f"},{"x":1,"y":13,"z":0,"color":"#d9c64a"},{"x":1,"y":13,"z":1,"color":"#d9c64a"},{"x":1,"y":13,"z":2,"color":"#d9c64a"},{"x":1,"y":13,"z":3,"color":"#d9c64a"},{"x":1,"y":13,"z":4,"color":"#d9c64a"},{"x":1,"y":13,"z":5,"color":"#d9c64a"},{"x":1,"y":13,"z":6,"color":"#d9c64a"},{"x":1,"y":14,"z":0,"color":"#37642a"},{"x":1,"y":14,"z":1,"color":"#d9c64a"},{"x":1,"y":14,"z":2,"color":"#37642a"},{"x":1,"y":14,"z":3,"color":"#37642a"},{"x":1,"y":14,"z":4,"color":"#37642a"},{"x":1,"y":14,"z":5,"color":"#d9c64a"},{"x":1,"y":14,"z":6,"color":"#37642a"},{"x":1,"y":15,"z":0,"color":"#37642a"},{"x":1,"y":15,"z":1,"color":"#d9c64a"},{"x":1,"y":15,"z":2,"color":"#37642a"},{"x":1,"y":15,"z":3,"color":"#37642a"},{"x":1,"y":15,"z":4,"color":"#37642a"},{"x":1,"y":15,"z":5,"color":"#d9c64a"},{"x":1,"y":15,"z":6,"color":"#37642a"},{"x":1,"y":16,"z":0,"color":"#37642a"},{"x":1,"y":16,"z":1,"color":"#d9c64a"},{"x":1,"y":16,"z":2,"color":"#37642a"},{"x":1,"y":16,"z":3,"color":"#37642a"},{"x":1,"y":16,"z":4,"color":"#37642a"},{"x":1,"y":16,"z":5,"color":"#d9c64a"},{"x":1,"y":16,"z":6,"color":"#37642a"},{"x":1,"y":17,"z":0,"color":"#d9c64a"},{"x":1,"y":17,"z":1,"color":"#d9c64a"},{"x":1,"y":17,"z":2,"color":"#d9c64a"},{"x":1,"y":17,"z":3,"color":"#d9c64a"},{"x":1,"y":17,"z":4,"color":"#d9c64a"},{"x":1,"y":17,"z":5,"color":"#d9c64a"},{"x":1,"y":17,"z":6,"color":"#d9c64a"},{"x":1,"y":18,"z":0,"color":"#37642a"},{"x":1,"y":18,"z":1,"color":"#d9c64a"},{"x":1,"y":18,"z":2,"color":"#37642a"},{"x":1,"y":18,"z":3,"color":"#37642a"},{"x":1,"y":18,"z":4,"color":"#37642a"},{"x":1,"y":18,"z":5,"color":"#d9c64a"},{"x":1,"y":18,"z":6,"color":"#37642a"},{"x":1,"y":19,"z":0,"color":"#37642a"},{"x":1,"y":19,"z":1,"color":"#d9c64a"},{"x":1,"y":19,"z":2,"color":"#37642a"},{"x":1,"y":19,"z":3,"color":"#37642a"},{"x":1,"y":19,"z":4,"color":"#37642a"},{"x":1,"y":19,"z":5,"color":"#d9c64a"},{"x":1,"y":19,"z":6,"color":"#37642a"},{"x":1,"y":20,"z":0,"color":"#37642a"},{"x":1,"y":20,"z":1,"color":"#d9c64a"},{"x":1,"y":20,"z":2,"color":"#37642a"},{"x":1,"y":20,"z":3,"color":"#37642a"},{"x":1,"y":20,"z":4,"color":"#37642a"},{"x":1,"y":20,"z":5,"color":"#d9c64a"},{"x":1,"y":20,"z":6,"color":"#37642a"},{"x":1,"y":21,"z":0,"color":"#d9c64a"},{"x":1,"y":21,"z":1,"color":"#d9c64a"},{"x":1,"y":21,"z":2,"color":"#d9c64a"},{"x":1,"y":21,"z":3,"color":"#d9c64a"},{"x":1,"y":21,"z":4,"color":"#d9c64a"},{"x":1,"y":21,"z":5,"color":"#d9c64a"},{"x":1,"y":21,"z":6,"color":"#d9c64a"},{"x":1,"y":22,"z":0,"color":"#37642a"},{"x":1,"y":22,"z":1,"color":"#d9c64a"},{"x":1,"y":22,"z":2,"color":"#37642a"},{"x":1,"y":22,"z":3,"color":"#37642a"},{"x":1,"y":22,"z":4,"color":"#37642a"},{"x":1,"y":22,"z":5,"color":"#d9c64a"},{"x":1,"y":22,"z":6,"color":"#37642a"},{"x":1,"y":23,"z":0,"color":"#37642a"},{"x":1,"y":23,"z":1,"color":"#d9c64a"},{"x":1,"y":23,"z":2,"color":"#37642a"},{"x":1,"y":23,"z":3,"color":"#37642a"},{"x":1,"y":23,"z":4,"color":"#37642a"},{"x":1,"y":23,"z":5,"color":"#d9c64a"},{"x":1,"y":23,"z":6,"color":"#37642a"},{"x":2,"y":13,"z":0,"color":"#37642a"},{"x":2,"y":13,"z":1,"color":"#d9c64a"},{"x":2,"y":13,"z":2,"color":"#37642a"},{"x":2,"y":13,"z":3,"color":"#37642a"},{"x":2,"y":13,"z":4,"color":"#37642a"},{"x":2,"y":13,"z":5,"color":"#d9c64a"},{"x":2,"y":13,"z":6,"color":"#37642a"},{"x":2,"y":14,"z":0,"color":"#4f8a3f"},{"x":2,"y":14,"z":1,"color":"#37642a"},{"x":2,"y":14,"z":2,"color":"#4f8a3f"},{"x":2,"y":14,"z":3,"color":"#4f8a3f"},{"x":2,"y":14,"z":4,"color":"#4f8a3f"},{"x":2,"y":14,"z":5,"color":"#37642a"},{"x":2,"y":14,"z":6,"color":"#4f8a3f"},{"x":2,"y":15,"z":0,"color":"#4f8a3f"},{"x":2,"y":15,"z":1,"color":"#37642a"},{"x":2,"y":15,"z":2,"color":"#4f8a3f"},{"x":2,"y":15,"z":3,"color":"#4f8a3f"},{"x":2,"y":15,"z":4,"color":"#4f8a3f"},{"x":2,"y":15,"z":5,"color":"#37642a"},{"x":2,"y":15,"z":6,"color":"#4f8a3f"},{"x":2,"y":16,"z":0,"color":"#4f8a3f"},{"x":2,"y":16,"z":1,"color":"#37642a"},{"x":2,"y":16,"z":2,"color":"#4f8a3f"},{"x":2,"y":16,"z":3,"color":"#4f8a3f"},{"x":2,"y":16,"z":4,"color":"#4f8a3f"},{"x":2,"y":16,"z":5,"color":"#37642a"},{"x":2,"y":16,"z":6,"color":"#4f8a3f"},{"x":2,"y":17,"z":0,"color":"#37642a"},{"x":2,"y":17,"z":1,"color":"#d9c64a"},{"x":2,"y":17,"z":2,"color":"#37642a"},{"x":2,"y":17,"z":3,"color":"#37642a"},{"x":2,"y":17,"z":4,"color":"#37642a"},{"x":2,"y":17,"z":5,"color":"#d9c64a"},{"x":2,"y":17,"z":6,"color":"#37642a"},{"x":2,"y":18,"z":0,"color":"#4f8a3f"},{"x":2,"y":18,"z":1,"color":"#37642a"},{"x":2,"y":18,"z":2,"color":"#4f8a3f"},{"x":2,"y":18,"z":3,"color":"#4f8a3f"},{"x":2,"y":18,"z":4,"color":"#4f8a3f"},{"x":2,"y":18,"z":5,"color":"#37642a"},{"x":2,"y":18,"z":6,"color":"#4f8a3f"},{"x":2,"y":19,"z":0,"color":"#4f8a3f"},{"x":2,"y":19,"z":1,"color":"#37642a"},{"x":2,"y":19,"z":2,"color":"#4f8a3f"},{"x":2,"y":19,"z":3,"color":"#4f8a3f"},{"x":2,"y":19,"z":4,"color":"#4f8a3f"},{"x":2,"y":19,"z":5,"color":"#37642a"},{"x":2,"y":19,"z":6,"color":"#4f8a3f"},{"x":2,"y":20,"z":0,"color":"#4f8a3f"},{"x":2,"y":20,"z":1,"color":"#37642a"},{"x":2,"y":20,"z":2,"color":"#4f8a3f"},{"x":2,"y":20,"z":3,"color":"#4f8a3f"},{"x":2,"y":20,"z":4,"color":"#4f8a3f"},{"x":2,"y":20,"z":5,"color":"#37642a"},{"x":2,"y":20,"z":6,"color":"#4f8a3f"},{"x":2,"y":21,"z":0,"color":"#37642a"},{"x":2,"y":21,"z":1,"color":"#d9c64a"},{"x":2,"y":21,"z":2,"color":"#37642a"},{"x":2,"y":21,"z":3,"color":"#37642a"},{"x":2,"y":21,"z":4,"color":"#37642a"},{"x":2,"y":21,"z":5,"color":"#d9c64a"},{"x":2,"y":21,"z":6,"color":"#37642a"},{"x":2,"y":22,"z":0,"color":"#4f8a3f"},{"x":2,"y":22,"z":1,"color":"#37642a"},{"x":2,"y":22,"z":2,"color":"#4f8a3f"},{"x":2,"y":22,"z":3,"color":"#4f8a3f"},{"x":2,"y":22,"z":4,"color":"#4f8a3f"},{"x":2,"y":22,"z":5,"color":"#37642a"},{"x":2,"y":22,"z":6,"color":"#4f8a3f"},{"x":2,"y":23,"z":0,"color":"#4f8a3f"},{"x":2,"y":23,"z":1,"color":"#37642a"},{"x":2,"y":23,"z":2,"color":"#4f8a3f"},{"x":2,"y":23,"z":3,"color":"#4f8a3f"},{"x":2,"y":23,"z":4,"color":"#4f8a3f"},{"x":2,"y":23,"z":5,"color":"#37642a"},{"x":2,"y":23,"z":6,"color":"#4f8a3f"},{"x":3,"y":13,"z":0,"color":"#37642a"},{"x":3,"y":13,"z":1,"color":"#d9c64a"},{"x":3,"y":13,"z":2,"color":"#37642a"},{"x":3,"y":13,"z":3,"color":"#37642a"},{"x":3,"y":13,"z":4,"color":"#37642a"},{"x":3,"y":13,"z":5,"color":"#d9c64a"},{"x":3,"y":13,"z":6,"color":"#37642a"},{"x":3,"y":14,"z":0,"color":"#4f8a3f"},{"x":3,"y":14,"z":1,"color":"#37642a"},{"x":3,"y":14,"z":2,"color":"#4f8a3f"},{"x":3,"y":14,"z":3,"color":"#4f8a3f"},{"x":3,"y":14,"z":4,"color":"#4f8a3f"},{"x":3,"y":14,"z":5,"color":"#37642a"},{"x":3,"y":14,"z":6,"color":"#4f8a3f"},{"x":3,"y":15,"z":0,"color":"#4f8a3f"},{"x":3,"y":15,"z":1,"color":"#37642a"},{"x":3,"y":15,"z":2,"color":"#4f8a3f"},{"x":3,"y":15,"z":3,"color":"#4f8a3f"},{"x":3,"y":15,"z":4,"color":"#4f8a3f"},{"x":3,"y":15,"z":5,"color":"#37642a"},{"x":3,"y":15,"z":6,"color":"#4f8a3f"},{"x":3,"y":16,"z":0,"color":"#4f8a3f"},{"x":3,"y":16,"z":1,"color":"#37642a"},{"x":3,"y":16,"z":2,"color":"#4f8a3f"},{"x":3,"y":16,"z":3,"color":"#4f8a3f"},{"x":3,"y":16,"z":4,"color":"#4f8a3f"},{"x":3,"y":16,"z":5,"color":"#37642a"},{"x":3,"y":16,"z":6,"color":"#4f8a3f"},{"x":3,"y":17,"z":0,"color":"#37642a"},{"x":3,"y":17,"z":1,"color":"#d9c64a"},{"x":3,"y":17,"z":2,"color":"#37642a"},{"x":3,"y":17,"z":3,"color":"#37642a"},{"x":3,"y":17,"z":4,"color":"#37642a"},{"x":3,"y":17,"z":5,"color":"#d9c64a"},{"x":3,"y":17,"z":6,"color":"#37642a"},{"x":3,"y":18,"z":0,"color":"#4f8a3f"},{"x":3,"y":18,"z":1,"color":"#37642a"},{"x":3,"y":18,"z":2,"color":"#4f8a3f"},{"x":3,"y":18,"z":3,"color":"#4f8a3f"},{"x":3,"y":18,"z":4,"color":"#4f8a3f"},{"x":3,"y":18,"z":5,"color":"#37642a"},{"x":3,"y":18,"z":6,"color":"#4f8a3f"},{"x":3,"y":19,"z":0,"color":"#4f8a3f"},{"x":3,"y":19,"z":1,"color":"#37642a"},{"x":3,"y":19,"z":2,"color":"#4f8a3f"},{"x":3,"y":19,"z":3,"color":"#4f8a3f"},{"x":3,"y":19,"z":4,"color":"#4f8a3f"},{"x":3,"y":19,"z":5,"color":"#37642a"},{"x":3,"y":19,"z":6,"color":"#4f8a3f"},{"x":3,"y":20,"z":0,"color":"#4f8a3f"},{"x":3,"y":20,"z":1,"color":"#37642a"},{"x":3,"y":20,"z":2,"color":"#4f8a3f"},{"x":3,"y":20,"z":3,"color":"#4f8a3f"},{"x":3,"y":20,"z":4,"color":"#4f8a3f"},{"x":3,"y":20,"z":5,"color":"#37642a"},{"x":3,"y":20,"z":6,"color":"#4f8a3f"},{"x":3,"y":21,"z":0,"color":"#37642a"},{"x":3,"y":21,"z":1,"color":"#d9c64a"},{"x":3,"y":21,"z":2,"color":"#37642a"},{"x":3,"y":21,"z":3,"color":"#37642a"},{"x":3,"y":21,"z":4,"color":"#37642a"},{"x":3,"y":21,"z":5,"color":"#d9c64a"},{"x":3,"y":21,"z":6,"color":"#37642a"},{"x":3,"y":22,"z":0,"color":"#4f8a3f"},{"x":3,"y":22,"z":1,"color":"#37642a"},{"x":3,"y":22,"z":2,"color":"#4f8a3f"},{"x":3,"y":22,"z":3,"color":"#4f8a3f"},{"x":3,"y":22,"z":4,"color":"#4f8a3f"},{"x":3,"y":22,"z":5,"color":"#37642a"},{"x":3,"y":22,"z":6,"color":"#4f8a3f"},{"x":3,"y":23,"z":0,"color":"#4f8a3f"},{"x":3,"y":23,"z":1,"color":"#37642a"},{"x":3,"y":23,"z":2,"color":"#4f8a3f"},{"x":3,"y":23,"z":3,"color":"#4f8a3f"},{"x":3,"y":23,"z":4,"color":"#4f8a3f"},{"x":3,"y":23,"z":5,"color":"#37642a"},{"x":3,"y":23,"z":6,"color":"#4f8a3f"},{"x":4,"y":13,"z":0,"color":"#37642a"},{"x":4,"y":13,"z":1,"color":"#d9c64a"},{"x":4,"y":13,"z":2,"color":"#37642a"},{"x":4,"y":13,"z":3,"color":"#37642a"},{"x":4,"y":13,"z":4,"color":"#37642a"},{"x":4,"y":13,"z":5,"color":"#d9c64a"},{"x":4,"y":13,"z":6,"color":"#37642a"},{"x":4,"y":14,"z":0,"color":"#4f8a3f"},{"x":4,"y":14,"z":1,"color":"#37642a"},{"x":4,"y":14,"z":2,"color":"#4f8a3f"},{"x":4,"y":14,"z":3,"color":"#4f8a3f"},{"x":4,"y":14,"z":4,"color":"#4f8a3f"},{"x":4,"y":14,"z":5,"color":"#37642a"},{"x":4,"y":14,"z":6,"color":"#4f8a3f"},{"x":4,"y":15,"z":0,"color":"#4f8a3f"},{"x":4,"y":15,"z":1,"color":"#37642a"},{"x":4,"y":15,"z":2,"color":"#4f8a3f"},{"x":4,"y":15,"z":3,"color":"#4f8a3f"},{"x":4,"y":15,"z":4,"color":"#4f8a3f"},{"x":4,"y":15,"z":5,"color":"#37642a"},{"x":4,"y":15,"z":6,"color":"#4f8a3f"},{"x":4,"y":16,"z":0,"color":"#4f8a3f"},{"x":4,"y":16,"z":1,"color":"#37642a"},{"x":4,"y":16,"z":2,"color":"#4f8a3f"},{"x":4,"y":16,"z":3,"color":"#4f8a3f"},{"x":4,"y":16,"z":4,"color":"#4f8a3f"},{"x":4,"y":16,"z":5,"color":"#37642a"},{"x":4,"y":16,"z":6,"color":"#4f8a3f"},{"x":4,"y":17,"z":0,"color":"#37642a"},{"x":4,"y":17,"z":1,"color":"#d9c64a"},{"x":4,"y":17,"z":2,"color":"#37642a"},{"x":4,"y":17,"z":3,"color":"#37642a"},{"x":4,"y":17,"z":4,"color":"#37642a"},{"x":4,"y":17,"z":5,"color":"#d9c64a"},{"x":4,"y":17,"z":6,"color":"#37642a"},{"x":4,"y":18,"z":0,"color":"#4f8a3f"},{"x":4,"y":18,"z":1,"color":"#37642a"},{"x":4,"y":18,"z":2,"color":"#4f8a3f"},{"x":4,"y":18,"z":3,"color":"#4f8a3f"},{"x":4,"y":18,"z":4,"color":"#4f8a3f"},{"x":4,"y":18,"z":5,"color":"#37642a"},{"x":4,"y":18,"z":6,"color":"#4f8a3f"},{"x":4,"y":19,"z":0,"color":"#4f8a3f"},{"x":4,"y":19,"z":1,"color":"#37642a"},{"x":4,"y":19,"z":2,"color":"#4f8a3f"},{"x":4,"y":19,"z":3,"color":"#4f8a3f"},{"x":4,"y":19,"z":4,"color":"#4f8a3f"},{"x":4,"y":19,"z":5,"color":"#37642a"},{"x":4,"y":19,"z":6,"color":"#4f8a3f"},{"x":4,"y":20,"z":0,"color":"#4f8a3f"},{"x":4,"y":20,"z":1,"color":"#37642a"},{"x":4,"y":20,"z":2,"color":"#4f8a3f"},{"x":4,"y":20,"z":3,"color":"#4f8a3f"},{"x":4,"y":20,"z":4,"color":"#4f8a3f"},{"x":4,"y":20,"z":5,"color":"#37642a"},{"x":4,"y":20,"z":6,"color":"#4f8a3f"},{"x":4,"y":21,"z":0,"color":"#37642a"},{"x":4,"y":21,"z":1,"color":"#d9c64a"},{"x":4,"y":21,"z":2,"color":"#37642a"},{"x":4,"y":21,"z":3,"color":"#37642a"},{"x":4,"y":21,"z":4,"color":"#37642a"},{"x":4,"y":21,"z":5,"color":"#d9c64a"},{"x":4,"y":21,"z":6,"color":"#37642a"},{"x":4,"y":22,"z":0,"color":"#4f8a3f"},{"x":4,"y":22,"z":1,"color":"#37642a"},{"x":4,"y":22,"z":2,"color":"#4f8a3f"},{"x":4,"y":22,"z":3,"color":"#4f8a3f"},{"x":4,"y":22,"z":4,"color":"#4f8a3f"},{"x":4,"y":22,"z":5,"color":"#37642a"},{"x":4,"y":22,"z":6,"color":"#4f8a3f"},{"x":4,"y":23,"z":0,"color":"#4f8a3f"},{"x":4,"y":23,"z":1,"color":"#37642a"},{"x":4,"y":23,"z":2,"color":"#4f8a3f"},{"x":4,"y":23,"z":3,"color":"#4f8a3f"},{"x":4,"y":23,"z":4,"color":"#4f8a3f"},{"x":4,"y":23,"z":5,"color":"#37642a"},{"x":4,"y":23,"z":6,"color":"#4f8a3f"},{"x":5,"y":13,"z":0,"color":"#d9c64a"},{"x":5,"y":13,"z":1,"color":"#d9c64a"},{"x":5,"y":13,"z":2,"color":"#d9c64a"},{"x":5,"y":13,"z":3,"color":"#d9c64a"},{"x":5,"y":13,"z":4,"color":"#d9c64a"},{"x":5,"y":13,"z":5,"color":"#d9c64a"},{"x":5,"y":13,"z":6,"color":"#d9c64a"},{"x":5,"y":14,"z":0,"color":"#37642a"},{"x":5,"y":14,"z":1,"color":"#d9c64a"},{"x":5,"y":14,"z":2,"color":"#37642a"},{"x":5,"y":14,"z":3,"color":"#37642a"},{"x":5,"y":14,"z":4,"color":"#37642a"},{"x":5,"y":14,"z":5,"color":"#d9c64a"},{"x":5,"y":14,"z":6,"color":"#37642a"},{"x":5,"y":15,"z":0,"color":"#37642a"},{"x":5,"y":15,"z":1,"color":"#d9c64a"},{"x":5,"y":15,"z":2,"color":"#37642a"},{"x":5,"y":15,"z":3,"color":"#37642a"},{"x":5,"y":15,"z":4,"color":"#37642a"},{"x":5,"y":15,"z":5,"color":"#d9c64a"},{"x":5,"y":15,"z":6,"color":"#37642a"},{"x":5,"y":16,"z":0,"color":"#37642a"},{"x":5,"y":16,"z":1,"color":"#d9c64a"},{"x":5,"y":16,"z":2,"color":"#37642a"},{"x":5,"y":16,"z":3,"color":"#37642a"},{"x":5,"y":16,"z":4,"color":"#37642a"},{"x":5,"y":16,"z":5,"color":"#d9c64a"},{"x":5,"y":16,"z":6,"color":"#37642a"},{"x":5,"y":17,"z":0,"color":"#d9c64a"},{"x":5,"y":17,"z":1,"color":"#d9c64a"},{"x":5,"y":17,"z":2,"color":"#d9c64a"},{"x":5,"y":17,"z":3,"color":"#d9c64a"},{"x":5,"y":17,"z":4,"color":"#d9c64a"},{"x":5,"y":17,"z":5,"color":"#d9c64a"},{"x":5,"y":17,"z":6,"color":"#d9c64a"},{"x":5,"y":18,"z":0,"color":"#37642a"},{"x":5,"y":18,"z":1,"color":"#d9c64a"},{"x":5,"y":18,"z":2,"color":"#37642a"},{"x":5,"y":18,"z":3,"color":"#37642a"},{"x":5,"y":18,"z":4,"color":"#37642a"},{"x":5,"y":18,"z":5,"color":"#d9c64a"},{"x":5,"y":18,"z":6,"color":"#37642a"},{"x":5,"y":19,"z":0,"color":"#37642a"},{"x":5,"y":19,"z":1,"color":"#d9c64a"},{"x":5,"y":19,"z":2,"color":"#37642a"},{"x":5,"y":19,"z":3,"color":"#37642a"},{"x":5,"y":19,"z":4,"color":"#37642a"},{"x":5,"y":19,"z":5,"color":"#d9c64a"},{"x":5,"y":19,"z":6,"color":"#37642a"},{"x":5,"y":20,"z":0,"color":"#37642a"},{"x":5,"y":20,"z":1,"color":"#d9c64a"},{"x":5,"y":20,"z":2,"color":"#37642a"},{"x":5,"y":20,"z":3,"color":"#37642a"},{"x":5,"y":20,"z":4,"color":"#37642a"},{"x":5,"y":20,"z":5,"color":"#d9c64a"},{"x":5,"y":20,"z":6,"color":"#37642a"},{"x":5,"y":21,"z":0,"color":"#d9c64a"},{"x":5,"y":21,"z":1,"color":"#d9c64a"},{"x":5,"y":21,"z":2,"color":"#d9c64a"},{"x":5,"y":21,"z":3,"color":"#d9c64a"},{"x":5,"y":21,"z":4,"color":"#d9c64a"},{"x":5,"y":21,"z":5,"color":"#d9c64a"},{"x":5,"y":21,"z":6,"color":"#d9c64a"},{"x":5,"y":22,"z":0,"color":"#37642a"},{"x":5,"y":22,"z":1,"color":"#d9c64a"},{"x":5,"y":22,"z":2,"color":"#37642a"},{"x":5,"y":22,"z":3,"color":"#37642a"},{"x":5,"y":22,"z":4,"color":"#37642a"},{"x":5,"y":22,"z":5,"color":"#d9c64a"},{"x":5,"y":22,"z":6,"color":"#37642a"},{"x":5,"y":23,"z":0,"color":"#37642a"},{"x":5,"y":23,"z":1,"color":"#d9c64a"},{"x":5,"y":23,"z":2,"color":"#37642a"},{"x":5,"y":23,"z":3,"color":"#37642a"},{"x":5,"y":23,"z":4,"color":"#37642a"},{"x":5,"y":23,"z":5,"color":"#d9c64a"},{"x":5,"y":23,"z":6,"color":"#37642a"},{"x":6,"y":13,"z":0,"color":"#37642a"},{"x":6,"y":13,"z":1,"color":"#d9c64a"},{"x":6,"y":13,"z":2,"color":"#37642a"},{"x":6,"y":13,"z":3,"color":"#37642a"},{"x":6,"y":13,"z":4,"color":"#37642a"},{"x":6,"y":13,"z":5,"color":"#d9c64a"},{"x":6,"y":13,"z":6,"color":"#37642a"},{"x":6,"y":14,"z":0,"color":"#4f8a3f"},{"x":6,"y":14,"z":1,"color":"#37642a"},{"x":6,"y":14,"z":2,"color":"#4f8a3f"},{"x":6,"y":14,"z":3,"color":"#4f8a3f"},{"x":6,"y":14,"z":4,"color":"#4f8a3f"},{"x":6,"y":14,"z":5,"color":"#37642a"},{"x":6,"y":14,"z":6,"color":"#4f8a3f"},{"x":6,"y":15,"z":0,"color":"#4f8a3f"},{"x":6,"y":15,"z":1,"color":"#37642a"},{"x":6,"y":15,"z":2,"color":"#4f8a3f"},{"x":6,"y":15,"z":3,"color":"#4f8a3f"},{"x":6,"y":15,"z":4,"color":"#4f8a3f"},{"x":6,"y":15,"z":5,"color":"#37642a"},{"x":6,"y":15,"z":6,"color":"#4f8a3f"},{"x":6,"y":16,"z":0,"color":"#4f8a3f"},{"x":6,"y":16,"z":1,"color":"#37642a"},{"x":6,"y":16,"z":2,"color":"#4f8a3f"},{"x":6,"y":16,"z":3,"color":"#4f8a3f"},{"x":6,"y":16,"z":4,"color":"#4f8a3f"},{"x":6,"y":16,"z":5,"color":"#37642a"},{"x":6,"y":16,"z":6,"color":"#4f8a3f"},{"x":6,"y":17,"z":0,"color":"#37642a"},{"x":6,"y":17,"z":1,"color":"#d9c64a"},{"x":6,"y":17,"z":2,"color":"#37642a"},{"x":6,"y":17,"z":3,"color":"#37642a"},{"x":6,"y":17,"z":4,"color":"#37642a"},{"x":6,"y":17,"z":5,"color":"#d9c64a"},{"x":6,"y":17,"z":6,"color":"#37642a"},{"x":6,"y":18,"z":0,"color":"#4f8a3f"},{"x":6,"y":18,"z":1,"color":"#37642a"},{"x":6,"y":18,"z":2,"color":"#4f8a3f"},{"x":6,"y":18,"z":3,"color":"#4f8a3f"},{"x":6,"y":18,"z":4,"color":"#4f8a3f"},{"x":6,"y":18,"z":5,"color":"#37642a"},{"x":6,"y":18,"z":6,"color":"#4f8a3f"},{"x":6,"y":19,"z":0,"color":"#4f8a3f"},{"x":6,"y":19,"z":1,"color":"#37642a"},{"x":6,"y":19,"z":2,"color":"#4f8a3f"},{"x":6,"y":19,"z":3,"color":"#4f8a3f"},{"x":6,"y":19,"z":4,"color":"#4f8a3f"},{"x":6,"y":19,"z":5,"color":"#37642a"},{"x":6,"y":19,"z":6,"color":"#4f8a3f"},{"x":6,"y":20,"z":0,"color":"#4f8a3f"},{"x":6,"y":20,"z":1,"color":"#37642a"},{"x":6,"y":20,"z":2,"color":"#4f8a3f"},{"x":6,"y":20,"z":3,"color":"#4f8a3f"},{"x":6,"y":20,"z":4,"color":"#4f8a3f"},{"x":6,"y":20,"z":5,"color":"#37642a"},{"x":6,"y":20,"z":6,"color":"#4f8a3f"},{"x":6,"y":21,"z":0,"color":"#37642a"},{"x":6,"y":21,"z":1,"color":"#d9c64a"},{"x":6,"y":21,"z":2,"color":"#37642a"},{"x":6,"y":21,"z":3,"color":"#37642a"},{"x":6,"y":21,"z":4,"color":"#37642a"},{"x":6,"y":21,"z":5,"color":"#d9c64a"},{"x":6,"y":21,"z":6,"color":"#37642a"},{"x":6,"y":22,"z":0,"color":"#4f8a3f"},{"x":6,"y":22,"z":1,"color":"#37642a"},{"x":6,"y":22,"z":2,"color":"#4f8a3f"},{"x":6,"y":22,"z":3,"color":"#4f8a3f"},{"x":6,"y":22,"z":4,"color":"#4f8a3f"},{"x":6,"y":22,"z":5,"color":"#37642a"},{"x":6,"y":22,"z":6,"color":"#4f8a3f"},{"x":6,"y":23,"z":0,"color":"#4f8a3f"},{"x":6,"y":23,"z":1,"color":"#37642a"},{"x":6,"y":23,"z":2,"color":"#4f8a3f"},{"x":6,"y":23,"z":3,"color":"#4f8a3f"},{"x":6,"y":23,"z":4,"color":"#4f8a3f"},{"x":6,"y":23,"z":5,"color":"#37642a"},{"x":6,"y":23,"z":6,"color":"#4f8a3f"},{"x":7,"y":13,"z":0,"color":"#37642a"},{"x":7,"y":13,"z":1,"color":"#d9c64a"},{"x":7,"y":13,"z":2,"color":"#37642a"},{"x":7,"y":13,"z":3,"color":"#37642a"},{"x":7,"y":13,"z":4,"color":"#37642a"},{"x":7,"y":13,"z":5,"color":"#d9c64a"},{"x":7,"y":13,"z":6,"color":"#37642a"},{"x":7,"y":14,"z":0,"color":"#4f8a3f"},{"x":7,"y":14,"z":1,"color":"#37642a"},{"x":7,"y":14,"z":2,"color":"#4f8a3f"},{"x":7,"y":14,"z":3,"color":"#4f8a3f"},{"x":7,"y":14,"z":4,"color":"#4f8a3f"},{"x":7,"y":14,"z":5,"color":"#37642a"},{"x":7,"y":14,"z":6,"color":"#4f8a3f"},{"x":7,"y":15,"z":0,"color":"#4f8a3f"},{"x":7,"y":15,"z":1,"color":"#37642a"},{"x":7,"y":15,"z":2,"color":"#4f8a3f"},{"x":7,"y":15,"z":3,"color":"#4f8a3f"},{"x":7,"y":15,"z":4,"color":"#4f8a3f"},{"x":7,"y":15,"z":5,"color":"#37642a"},{"x":7,"y":15,"z":6,"color":"#4f8a3f"},{"x":7,"y":16,"z":0,"color":"#4f8a3f"},{"x":7,"y":16,"z":1,"color":"#37642a"},{"x":7,"y":16,"z":2,"color":"#4f8a3f"},{"x":7,"y":16,"z":3,"color":"#4f8a3f"},{"x":7,"y":16,"z":4,"color":"#4f8a3f"},{"x":7,"y":16,"z":5,"color":"#37642a"},{"x":7,"y":16,"z":6,"color":"#4f8a3f"},{"x":7,"y":17,"z":0,"color":"#37642a"},{"x":7,"y":17,"z":1,"color":"#d9c64a"},{"x":7,"y":17,"z":2,"color":"#37642a"},{"x":7,"y":17,"z":3,"color":"#37642a"},{"x":7,"y":17,"z":4,"color":"#37642a"},{"x":7,"y":17,"z":5,"color":"#d9c64a"},{"x":7,"y":17,"z":6,"color":"#37642a"},{"x":7,"y":18,"z":0,"color":"#4f8a3f"},{"x":7,"y":18,"z":1,"color":"#37642a"},{"x":7,"y":18,"z":2,"color":"#4f8a3f"},{"x":7,"y":18,"z":3,"color":"#4f8a3f"},{"x":7,"y":18,"z":4,"color":"#4f8a3f"},{"x":7,"y":18,"z":5,"color":"#37642a"},{"x":7,"y":18,"z":6,"color":"#4f8a3f"},{"x":7,"y":19,"z":0,"color":"#4f8a3f"},{"x":7,"y":19,"z":1,"color":"#37642a"},{"x":7,"y":19,"z":2,"color":"#4f8a3f"},{"x":7,"y":19,"z":3,"color":"#4f8a3f"},{"x":7,"y":19,"z":4,"color":"#4f8a3f"},{"x":7,"y":19,"z":5,"color":"#37642a"},{"x":7,"y":19,"z":6,"color":"#4f8a3f"},{"x":7,"y":20,"z":0,"color":"#4f8a3f"},{"x":7,"y":20,"z":1,"color":"#37642a"},{"x":7,"y":20,"z":2,"color":"#4f8a3f"},{"x":7,"y":20,"z":3,"color":"#4f8a3f"},{"x":7,"y":20,"z":4,"color":"#4f8a3f"},{"x":7,"y":20,"z":5,"color":"#37642a"},{"x":7,"y":20,"z":6,"color":"#4f8a3f"},{"x":7,"y":21,"z":0,"color":"#37642a"},{"x":7,"y":21,"z":1,"color":"#d9c64a"},{"x":7,"y":21,"z":2,"color":"#37642a"},{"x":7,"y":21,"z":3,"color":"#37642a"},{"x":7,"y":21,"z":4,"color":"#37642a"},{"x":7,"y":21,"z":5,"color":"#d9c64a"},{"x":7,"y":21,"z":6,"color":"#37642a"},{"x":7,"y":22,"z":0,"color":"#4f8a3f"},{"x":7,"y":22,"z":1,"color":"#37642a"},{"x":7,"y":22,"z":2,"color":"#4f8a3f"},{"x":7,"y":22,"z":3,"color":"#4f8a3f"},{"x":7,"y":22,"z":4,"color":"#4f8a3f"},{"x":7,"y":22,"z":5,"color":"#37642a"},{"x":7,"y":22,"z":6,"color":"#4f8a3f"},{"x":7,"y":23,"z":0,"color":"#4f8a3f"},{"x":7,"y":23,"z":1,"color":"#37642a"},{"x":7,"y":23,"z":2,"color":"#4f8a3f"},{"x":7,"y":23,"z":3,"color":"#4f8a3f"},{"x":7,"y":23,"z":4,"color":"#4f8a3f"},{"x":7,"y":23,"z":5,"color":"#37642a"},{"x":7,"y":23,"z":6,"color":"#4f8a3f"},{"x":8,"y":13,"z":0,"color":"#37642a"},{"x":8,"y":13,"z":1,"color":"#d9c64a"},{"x":8,"y":13,"z":2,"color":"#37642a"},{"x":8,"y":13,"z":3,"color":"#37642a"},{"x":8,"y":13,"z":4,"color":"#37642a"},{"x":8,"y":13,"z":5,"color":"#d9c64a"},{"x":8,"y":13,"z":6,"color":"#37642a"},{"x":8,"y":14,"z":0,"color":"#4f8a3f"},{"x":8,"y":14,"z":1,"color":"#37642a"},{"x":8,"y":14,"z":2,"color":"#4f8a3f"},{"x":8,"y":14,"z":3,"color":"#4f8a3f"},{"x":8,"y":14,"z":4,"color":"#4f8a3f"},{"x":8,"y":14,"z":5,"color":"#37642a"},{"x":8,"y":14,"z":6,"color":"#4f8a3f"},{"x":8,"y":15,"z":0,"color":"#4f8a3f"},{"x":8,"y":15,"z":1,"color":"#37642a"},{"x":8,"y":15,"z":2,"color":"#4f8a3f"},{"x":8,"y":15,"z":3,"color":"#4f8a3f"},{"x":8,"y":15,"z":4,"color":"#4f8a3f"},{"x":8,"y":15,"z":5,"color":"#37642a"},{"x":8,"y":15,"z":6,"color":"#4f8a3f"},{"x":8,"y":16,"z":0,"color":"#4f8a3f"},{"x":8,"y":16,"z":1,"color":"#37642a"},{"x":8,"y":16,"z":2,"color":"#4f8a3f"},{"x":8,"y":16,"z":3,"color":"#4f8a3f"},{"x":8,"y":16,"z":4,"color":"#4f8a3f"},{"x":8,"y":16,"z":5,"color":"#37642a"},{"x":8,"y":16,"z":6,"color":"#4f8a3f"},{"x":8,"y":17,"z":0,"color":"#37642a"},{"x":8,"y":17,"z":1,"color":"#d9c64a"},{"x":8,"y":17,"z":2,"color":"#37642a"},{"x":8,"y":17,"z":3,"color":"#37642a"},{"x":8,"y":17,"z":4,"color":"#37642a"},{"x":8,"y":17,"z":5,"color":"#d9c64a"},{"x":8,"y":17,"z":6,"color":"#37642a"},{"x":8,"y":18,"z":0,"color":"#4f8a3f"},{"x":8,"y":18,"z":1,"color":"#37642a"},{"x":8,"y":18,"z":2,"color":"#4f8a3f"},{"x":8,"y":18,"z":3,"color":"#4f8a3f"},{"x":8,"y":18,"z":4,"color":"#4f8a3f"},{"x":8,"y":18,"z":5,"color":"#37642a"},{"x":8,"y":18,"z":6,"color":"#4f8a3f"},{"x":8,"y":19,"z":0,"color":"#4f8a3f"},{"x":8,"y":19,"z":1,"color":"#37642a"},{"x":8,"y":19,"z":2,"color":"#4f8a3f"},{"x":8,"y":19,"z":3,"color":"#4f8a3f"},{"x":8,"y":19,"z":4,"color":"#4f8a3f"},{"x":8,"y":19,"z":5,"color":"#37642a"},{"x":8,"y":19,"z":6,"color":"#4f8a3f"},{"x":8,"y":20,"z":0,"color":"#4f8a3f"},{"x":8,"y":20,"z":1,"color":"#37642a"},{"x":8,"y":20,"z":2,"color":"#4f8a3f"},{"x":8,"y":20,"z":3,"color":"#4f8a3f"},{"x":8,"y":20,"z":4,"color":"#4f8a3f"},{"x":8,"y":20,"z":5,"color":"#37642a"},{"x":8,"y":20,"z":6,"color":"#4f8a3f"},{"x":8,"y":21,"z":0,"color":"#37642a"},{"x":8,"y":21,"z":1,"color":"#d9c64a"},{"x":8,"y":21,"z":2,"color":"#37642a"},{"x":8,"y":21,"z":3,"color":"#37642a"},{"x":8,"y":21,"z":4,"color":"#37642a"},{"x":8,"y":21,"z":5,"color":"#d9c64a"},{"x":8,"y":21,"z":6,"color":"#37642a"},{"x":8,"y":22,"z":0,"color":"#4f8a3f"},{"x":8,"y":22,"z":1,"color":"#37642a"},{"x":8,"y":22,"z":2,"color":"#4f8a3f"},{"x":8,"y":22,"z":3,"color":"#4f8a3f"},{"x":8,"y":22,"z":4,"color":"#4f8a3f"},{"x":8,"y":22,"z":5,"color":"#37642a"},{"x":8,"y":22,"z":6,"color":"#4f8a3f"},{"x":8,"y":23,"z":0,"color":"#4f8a3f"},{"x":8,"y":23,"z":1,"color":"#37642a"},{"x":8,"y":23,"z":2,"color":"#4f8a3f"},{"x":8,"y":23,"z":3,"color":"#4f8a3f"},{"x":8,"y":23,"z":4,"color":"#4f8a3f"},{"x":8,"y":23,"z":5,"color":"#37642a"},{"x":8,"y":23,"z":6,"color":"#4f8a3f"},{"x":9,"y":13,"z":0,"color":"#d9c64a"},{"x":9,"y":13,"z":1,"color":"#d9c64a"},{"x":9,"y":13,"z":2,"color":"#d9c64a"},{"x":9,"y":13,"z":3,"color":"#d9c64a"},{"x":9,"y":13,"z":4,"color":"#d9c64a"},{"x":9,"y":13,"z":5,"color":"#d9c64a"},{"x":9,"y":13,"z":6,"color":"#d9c64a"},{"x":9,"y":14,"z":0,"color":"#37642a"},{"x":9,"y":14,"z":1,"color":"#d9c64a"},{"x":9,"y":14,"z":2,"color":"#37642a"},{"x":9,"y":14,"z":3,"color":"#37642a"},{"x":9,"y":14,"z":4,"color":"#37642a"},{"x":9,"y":14,"z":5,"color":"#d9c64a"},{"x":9,"y":14,"z":6,"color":"#37642a"},{"x":9,"y":15,"z":0,"color":"#37642a"},{"x":9,"y":15,"z":1,"color":"#d9c64a"},{"x":9,"y":15,"z":2,"color":"#37642a"},{"x":9,"y":15,"z":3,"color":"#37642a"},{"x":9,"y":15,"z":4,"color":"#37642a"},{"x":9,"y":15,"z":5,"color":"#d9c64a"},{"x":9,"y":15,"z":6,"color":"#37642a"},{"x":9,"y":16,"z":0,"color":"#37642a"},{"x":9,"y":16,"z":1,"color":"#d9c64a"},{"x":9,"y":16,"z":2,"color":"#37642a"},{"x":9,"y":16,"z":3,"color":"#37642a"},{"x":9,"y":16,"z":4,"color":"#37642a"},{"x":9,"y":16,"z":5,"color":"#d9c64a"},{"x":9,"y":16,"z":6,"color":"#37642a"},{"x":9,"y":17,"z":0,"color":"#d9c64a"},{"x":9,"y":17,"z":1,"color":"#d9c64a"},{"x":9,"y":17,"z":2,"color":"#d9c64a"},{"x":9,"y":17,"z":3,"color":"#d9c64a"},{"x":9,"y":17,"z":4,"color":"#d9c64a"},{"x":9,"y":17,"z":5,"color":"#d9c64a"},{"x":9,"y":17,"z":6,"color":"#d9c64a"},{"x":9,"y":18,"z":0,"color":"#37642a"},{"x":9,"y":18,"z":1,"color":"#d9c64a"},{"x":9,"y":18,"z":2,"color":"#37642a"},{"x":9,"y":18,"z":3,"color":"#37642a"},{"x":9,"y":18,"z":4,"color":"#37642a"},{"x":9,"y":18,"z":5,"color":"#d9c64a"},{"x":9,"y":18,"z":6,"color":"#37642a"},{"x":9,"y":19,"z":0,"color":"#37642a"},{"x":9,"y":19,"z":1,"color":"#d9c64a"},{"x":9,"y":19,"z":2,"color":"#37642a"},{"x":9,"y":19,"z":3,"color":"#37642a"},{"x":9,"y":19,"z":4,"color":"#37642a"},{"x":9,"y":19,"z":5,"color":"#d9c64a"},{"x":9,"y":19,"z":6,"color":"#37642a"},{"x":9,"y":20,"z":0,"color":"#37642a"},{"x":9,"y":20,"z":1,"color":"#d9c64a"},{"x":9,"y":20,"z":2,"color":"#37642a"},{"x":9,"y":20,"z":3,"color":"#37642a"},{"x":9,"y":20,"z":4,"color":"#37642a"},{"x":9,"y":20,"z":5,"color":"#d9c64a"},{"x":9,"y":20,"z":6,"color":"#37642a"},{"x":9,"y":21,"z":0,"color":"#d9c64a"},{"x":9,"y":21,"z":1,"color":"#d9c64a"},{"x":9,"y":21,"z":2,"color":"#d9c64a"},{"x":9,"y":21,"z":3,"color":"#d9c64a"},{"x":9,"y":21,"z":4,"color":"#d9c64a"},{"x":9,"y":21,"z":5,"color":"#d9c64a"},{"x":9,"y":21,"z":6,"color":"#d9c64a"},{"x":9,"y":22,"z":0,"color":"#37642a"},{"x":9,"y":22,"z":1,"color":"#d9c64a"},{"x":9,"y":22,"z":2,"color":"#37642a"},{"x":9,"y":22,"z":3,"color":"#37642a"},{"x":9,"y":22,"z":4,"color":"#37642a"},{"x":9,"y":22,"z":5,"color":"#d9c64a"},{"x":9,"y":22,"z":6,"color":"#37642a"},{"x":9,"y":23,"z":0,"color":"#37642a"},{"x":9,"y":23,"z":1,"color":"#d9c64a"},{"x":9,"y":23,"z":2,"color":"#37642a"},{"x":9,"y":23,"z":3,"color":"#37642a"},{"x":9,"y":23,"z":4,"color":"#37642a"},{"x":9,"y":23,"z":5,"color":"#d9c64a"},{"x":9,"y":23,"z":6,"color":"#37642a"},{"x":10,"y":13,"z":0,"color":"#37642a"},{"x":10,"y":13,"z":1,"color":"#d9c64a"},{"x":10,"y":13,"z":2,"color":"#37642a"},{"x":10,"y":13,"z":3,"color":"#37642a"},{"x":10,"y":13,"z":4,"color":"#37642a"},{"x":10,"y":13,"z":5,"color":"#d9c64a"},{"x":10,"y":13,"z":6,"color":"#37642a"},{"x":10,"y":14,"z":0,"color":"#4f8a3f"},{"x":10,"y":14,"z":1,"color":"#37642a"},{"x":10,"y":14,"z":2,"color":"#4f8a3f"},{"x":10,"y":14,"z":3,"color":"#4f8a3f"},{"x":10,"y":14,"z":4,"color":"#4f8a3f"},{"x":10,"y":14,"z":5,"color":"#37642a"},{"x":10,"y":14,"z":6,"color":"#4f8a3f"},{"x":10,"y":15,"z":0,"color":"#4f8a3f"},{"x":10,"y":15,"z":1,"color":"#37642a"},{"x":10,"y":15,"z":2,"color":"#4f8a3f"},{"x":10,"y":15,"z":3,"color":"#4f8a3f"},{"x":10,"y":15,"z":4,"color":"#4f8a3f"},{"x":10,"y":15,"z":5,"color":"#37642a"},{"x":10,"y":15,"z":6,"color":"#4f8a3f"},{"x":10,"y":16,"z":0,"color":"#4f8a3f"},{"x":10,"y":16,"z":1,"color":"#37642a"},{"x":10,"y":16,"z":2,"color":"#4f8a3f"},{"x":10,"y":16,"z":3,"color":"#4f8a3f"},{"x":10,"y":16,"z":4,"color":"#4f8a3f"},{"x":10,"y":16,"z":5,"color":"#37642a"},{"x":10,"y":16,"z":6,"color":"#4f8a3f"},{"x":10,"y":17,"z":0,"color":"#37642a"},{"x":10,"y":17,"z":1,"color":"#d9c64a"},{"x":10,"y":17,"z":2,"color":"#37642a"},{"x":10,"y":17,"z":3,"color":"#37642a"},{"x":10,"y":17,"z":4,"color":"#37642a"},{"x":10,"y":17,"z":5,"color":"#d9c64a"},{"x":10,"y":17,"z":6,"color":"#37642a"},{"x":10,"y":18,"z":0,"color":"#4f8a3f"},{"x":10,"y":18,"z":1,"color":"#37642a"},{"x":10,"y":18,"z":2,"color":"#4f8a3f"},{"x":10,"y":18,"z":3,"color":"#4f8a3f"},{"x":10,"y":18,"z":4,"color":"#4f8a3f"},{"x":10,"y":18,"z":5,"color":"#37642a"},{"x":10,"y":18,"z":6,"color":"#4f8a3f"},{"x":10,"y":19,"z":0,"color":"#4f8a3f"},{"x":10,"y":19,"z":1,"color":"#37642a"},{"x":10,"y":19,"z":2,"color":"#4f8a3f"},{"x":10,"y":19,"z":3,"color":"#4f8a3f"},{"x":10,"y":19,"z":4,"color":"#4f8a3f"},{"x":10,"y":19,"z":5,"color":"#37642a"},{"x":10,"y":19,"z":6,"color":"#4f8a3f"},{"x":10,"y":20,"z":0,"color":"#4f8a3f"},{"x":10,"y":20,"z":1,"color":"#37642a"},{"x":10,"y":20,"z":2,"color":"#4f8a3f"},{"x":10,"y":20,"z":3,"color":"#4f8a3f"},{"x":10,"y":20,"z":4,"color":"#4f8a3f"},{"x":10,"y":20,"z":5,"color":"#37642a"},{"x":10,"y":20,"z":6,"color":"#4f8a3f"},{"x":10,"y":21,"z":0,"color":"#37642a"},{"x":10,"y":21,"z":1,"color":"#d9c64a"},{"x":10,"y":21,"z":2,"color":"#37642a"},{"x":10,"y":21,"z":3,"color":"#37642a"},{"x":10,"y":21,"z":4,"color":"#37642a"},{"x":10,"y":21,"z":5,"color":"#d9c64a"},{"x":10,"y":21,"z":6,"color":"#37642a"},{"x":10,"y":22,"z":0,"color":"#4f8a3f"},{"x":10,"y":22,"z":1,"color":"#37642a"},{"x":10,"y":22,"z":2,"color":"#4f8a3f"},{"x":10,"y":22,"z":3,"color":"#4f8a3f"},{"x":10,"y":22,"z":4,"color":"#4f8a3f"},{"x":10,"y":22,"z":5,"color":"#37642a"},{"x":10,"y":22,"z":6,"color":"#4f8a3f"},{"x":10,"y":23,"z":0,"color":"#4f8a3f"},{"x":10,"y":23,"z":1,"color":"#37642a"},{"x":10,"y":23,"z":2,"color":"#4f8a3f"},{"x":10,"y":23,"z":3,"color":"#4f8a3f"},{"x":10,"y":23,"z":4,"color":"#4f8a3f"},{"x":10,"y":23,"z":5,"color":"#37642a"},{"x":10,"y":23,"z":6,"color":"#4f8a3f"},{"x":11,"y":13,"z":0,"color":"#37642a"},{"x":11,"y":13,"z":1,"color":"#d9c64a"},{"x":11,"y":13,"z":2,"color":"#37642a"},{"x":11,"y":13,"z":3,"color":"#37642a"},{"x":11,"y":13,"z":4,"color":"#37642a"},{"x":11,"y":13,"z":5,"color":"#d9c64a"},{"x":11,"y":13,"z":6,"color":"#37642a"},{"x":11,"y":14,"z":0,"color":"#4f8a3f"},{"x":11,"y":14,"z":1,"color":"#37642a"},{"x":11,"y":14,"z":2,"color":"#4f8a3f"},{"x":11,"y":14,"z":3,"color":"#4f8a3f"},{"x":11,"y":14,"z":4,"color":"#4f8a3f"},{"x":11,"y":14,"z":5,"color":"#37642a"},{"x":11,"y":14,"z":6,"color":"#4f8a3f"},{"x":11,"y":15,"z":0,"color":"#4f8a3f"},{"x":11,"y":15,"z":1,"color":"#37642a"},{"x":11,"y":15,"z":2,"color":"#4f8a3f"},{"x":11,"y":15,"z":3,"color":"#4f8a3f"},{"x":11,"y":15,"z":4,"color":"#4f8a3f"},{"x":11,"y":15,"z":5,"color":"#37642a"},{"x":11,"y":15,"z":6,"color":"#4f8a3f"},{"x":11,"y":16,"z":0,"color":"#4f8a3f"},{"x":11,"y":16,"z":1,"color":"#37642a"},{"x":11,"y":16,"z":2,"color":"#4f8a3f"},{"x":11,"y":16,"z":3,"color":"#4f8a3f"},{"x":11,"y":16,"z":4,"color":"#4f8a3f"},{"x":11,"y":16,"z":5,"color":"#37642a"},{"x":11,"y":16,"z":6,"color":"#4f8a3f"},{"x":11,"y":17,"z":0,"color":"#37642a"},{"x":11,"y":17,"z":1,"color":"#d9c64a"},{"x":11,"y":17,"z":2,"color":"#37642a"},{"x":11,"y":17,"z":3,"color":"#37642a"},{"x":11,"y":17,"z":4,"color":"#37642a"},{"x":11,"y":17,"z":5,"color":"#d9c64a"},{"x":11,"y":17,"z":6,"color":"#37642a"},{"x":11,"y":18,"z":0,"color":"#4f8a3f"},{"x":11,"y":18,"z":1,"color":"#37642a"},{"x":11,"y":18,"z":2,"color":"#4f8a3f"},{"x":11,"y":18,"z":3,"color":"#4f8a3f"},{"x":11,"y":18,"z":4,"color":"#4f8a3f"},{"x":11,"y":18,"z":5,"color":"#37642a"},{"x":11,"y":18,"z":6,"color":"#4f8a3f"},{"x":11,"y":19,"z":0,"color":"#4f8a3f"},{"x":11,"y":19,"z":1,"color":"#37642a"},{"x":11,"y":19,"z":2,"color":"#4f8a3f"},{"x":11,"y":19,"z":3,"color":"#4f8a3f"},{"x":11,"y":19,"z":4,"color":"#4f8a3f"},{"x":11,"y":19,"z":5,"color":"#37642a"},{"x":11,"y":19,"z":6,"color":"#4f8a3f"},{"x":11,"y":20,"z":0,"color":"#4f8a3f"},{"x":11,"y":20,"z":1,"color":"#37642a"},{"x":11,"y":20,"z":2,"color":"#4f8a3f"},{"x":11,"y":20,"z":3,"color":"#4f8a3f"},{"x":11,"y":20,"z":4,"color":"#4f8a3f"},{"x":11,"y":20,"z":5,"color":"#37642a"},{"x":11,"y":20,"z":6,"color":"#4f8a3f"},{"x":11,"y":21,"z":0,"color":"#37642a"},{"x":11,"y":21,"z":1,"color":"#d9c64a"},{"x":11,"y":21,"z":2,"color":"#37642a"},{"x":11,"y":21,"z":3,"color":"#37642a"},{"x":11,"y":21,"z":4,"color":"#37642a"},{"x":11,"y":21,"z":5,"color":"#d9c64a"},{"x":11,"y":21,"z":6,"color":"#37642a"},{"x":11,"y":22,"z":0,"color":"#4f8a3f"},{"x":11,"y":22,"z":1,"color":"#37642a"},{"x":11,"y":22,"z":2,"color":"#4f8a3f"},{"x":11,"y":22,"z":3,"color":"#4f8a3f"},{"x":11,"y":22,"z":4,"color":"#4f8a3f"},{"x":11,"y":22,"z":5,"color":"#37642a"},{"x":11,"y":22,"z":6,"color":"#4f8a3f"},{"x":11,"y":23,"z":0,"color":"#4f8a3f"},{"x":11,"y":23,"z":1,"color":"#37642a"},{"x":11,"y":23,"z":2,"color":"#4f8a3f"},{"x":11,"y":23,"z":3,"color":"#4f8a3f"},{"x":11,"y":23,"z":4,"color":"#4f8a3f"},{"x":11,"y":23,"z":5,"color":"#37642a"},{"x":11,"y":23,"z":6,"color":"#4f8a3f"},{"x":0,"y":24,"z":0,"color":"#d8a878"},{"x":0,"y":24,"z":1,"color":"#d8a878"},{"x":0,"y":24,"z":2,"color":"#d8a878"},{"x":0,"y":24,"z":3,"color":"#d8a878"},{"x":0,"y":24,"z":4,"color":"#d8a878"},{"x":0,"y":24,"z":5,"color":"#d8a878"},{"x":0,"y":24,"z":6,"color":"#d8a878"},{"x":0,"y":25,"z":0,"color":"#d8a878"},{"x":0,"y":25,"z":1,"color":"#d8a878"},{"x":0,"y":25,"z":2,"color":"#d8a878"},{"x":0,"y":25,"z":3,"color":"#d8a878"},{"x":0,"y":25,"z":4,"color":"#d8a878"},{"x":0,"y":25,"z":5,"color":"#d8a878"},{"x":0,"y":25,"z":6,"color":"#d8a878"},{"x":0,"y":26,"z":0,"color":"#d8a878"},{"x":0,"y":26,"z":1,"color":"#d8a878"},{"x":0,"y":26,"z":2,"color":"#d8a878"},{"x":0,"y":26,"z":3,"color":"#d8a878"},{"x":0,"y":26,"z":4,"color":"#d8a878"},{"x":0,"y":26,"z":5,"color":"#d8a878"},{"x":0,"y":26,"z":6,"color":"#d8a878"},{"x":0,"y":27,"z":0,"color":"#d8a878"},{"x":0,"y":27,"z":1,"color":"#d8a878"},{"x":0,"y":27,"z":2,"color":"#d8a878"},{"x":0,"y":27,"z":3,"color":"#d8a878"},{"x":0,"y":27,"z":4,"color":"#d8a878"},{"x":0,"y":27,"z":5,"color":"#d8a878"},{"x":0,"y":27,"z":6,"color":"#d8a878"},{"x":0,"y":28,"z":0,"color":"#d8a878"},{"x":0,"y":28,"z":1,"color":"#d8a878"},{"x":0,"y":28,"z":2,"color":"#d8a878"},{"x":0,"y":28,"z":3,"color":"#d8a878"},{"x":0,"y":28,"z":4,"color":"#d8a878"},{"x":0,"y":28,"z":5,"color":"#d8a878"},{"x":0,"y":28,"z":6,"color":"#d8a878"},{"x":0,"y":29,"z":0,"color":"#d8a878"},{"x":0,"y":29,"z":1,"color":"#d8a878"},{"x":0,"y":29,"z":2,"color":"#d8a878"},{"x":0,"y":29,"z":3,"color":"#d8a878"},{"x":0,"y":29,"z":4,"color":"#d8a878"},{"x":0,"y":29,"z":5,"color":"#d8a878"},{"x":0,"y":29,"z":6,"color":"#d8a878"},{"x":0,"y":30,"z":0,"color":"#d8a878"},{"x":0,"y":30,"z":1,"color":"#d8a878"},{"x":0,"y":30,"z":2,"color":"#d8a878"},{"x":0,"y":30,"z":3,"color":"#d8a878"},{"x":0,"y":30,"z":4,"color":"#d8a878"},{"x":0,"y":30,"z":5,"color":"#d8a878"},{"x":0,"y":30,"z":6,"color":"#d8a878"},{"x":0,"y":31,"z":0,"color":"#d8a878"},{"x":0,"y":31,"z":1,"color":"#d8a878"},{"x":0,"y":31,"z":2,"color":"#d8a878"},{"x":0,"y":31,"z":3,"color":"#d8a878"},{"x":0,"y":31,"z":4,"color":"#d8a878"},{"x":0,"y":31,"z":5,"color":"#d8a878"},{"x":0,"y":31,"z":6,"color":"#d8a878"},{"x":1,"y":24,"z":0,"color":"#d8a878"},{"x":1,"y":24,"z":1,"color":"#d8a878"},{"x":1,"y":24,"z":2,"color":"#d8a878"},{"x":1,"y":24,"z":3,"color":"#d8a878"},{"x":1,"y":24,"z":4,"color":"#d8a878"},{"x":1,"y":24,"z":5,"color":"#d8a878"},{"x":1,"y":24,"z":6,"color":"#d8a878"},{"x":1,"y":25,"z":0,"color":"#d8a878"},{"x":1,"y":25,"z":1,"color":"#d8a878"},{"x":1,"y":25,"z":2,"color":"#d8a878"},{"x":1,"y":25,"z":3,"color":"#d8a878"},{"x":1,"y":25,"z":4,"color":"#d8a878"},{"x":1,"y":25,"z":5,"color":"#d8a878"},{"x":1,"y":25,"z":6,"color":"#d8a878"},{"x":1,"y":26,"z":0,"color":"#d8a878"},{"x":1,"y":26,"z":1,"color":"#d8a878"},{"x":1,"y":26,"z":2,"color":"#d8a878"},{"x":1,"y":26,"z":3,"color":"#d8a878"},{"x":1,"y":26,"z":4,"color":"#d8a878"},{"x":1,"y":26,"z":5,"color":"#d8a878"},{"x":1,"y":26,"z":6,"color":"#d8a878"},{"x":1,"y":27,"z":0,"color":"#d8a878"},{"x":1,"y":27,"z":1,"color":"#d8a878"},{"x":1,"y":27,"z":2,"color":"#d8a878"},{"x":1,"y":27,"z":3,"color":"#d8a878"},{"x":1,"y":27,"z":4,"color":"#d8a878"},{"x":1,"y":27,"z":5,"color":"#d8a878"},{"x":1,"y":27,"z":6,"color":"#d8a878"},{"x":1,"y":28,"z":0,"color":"#d8a878"},{"x":1,"y":28,"z":1,"color":"#d8a878"},{"x":1,"y":28,"z":2,"color":"#d8a878"},{"x":1,"y":28,"z":3,"color":"#d8a878"},{"x":1,"y":28,"z":4,"color":"#d8a878"},{"x":1,"y":28,"z":5,"color":"#d8a878"},{"x":1,"y":28,"z":6,"color":"#d8a878"},{"x":1,"y":29,"z":0,"color":"#d8a878"},{"x":1,"y":29,"z":1,"color":"#d8a878"},{"x":1,"y":29,"z":2,"color":"#d8a878"},{"x":1,"y":29,"z":3,"color":"#d8a878"},{"x":1,"y":29,"z":4,"color":"#d8a878"},{"x":1,"y":29,"z":5,"color":"#d8a878"},{"x":1,"y":29,"z":6,"color":"#d8a878"},{"x":1,"y":30,"z":0,"color":"#d8a878"},{"x":1,"y":30,"z":1,"color":"#d8a878"},{"x":1,"y":30,"z":2,"color":"#d8a878"},{"x":1,"y":30,"z":3,"color":"#d8a878"},{"x":1,"y":30,"z":4,"color":"#d8a878"},{"x":1,"y":30,"z":5,"color":"#d8a878"},{"x":1,"y":30,"z":6,"color":"#d8a878"},{"x":1,"y":31,"z":0,"color":"#d8a878"},{"x":1,"y":31,"z":1,"color":"#d8a878"},{"x":1,"y":31,"z":2,"color":"#d8a878"},{"x":1,"y":31,"z":3,"color":"#d8a878"},{"x":1,"y":31,"z":4,"color":"#d8a878"},{"x":1,"y":31,"z":5,"color":"#d8a878"},{"x":1,"y":31,"z":6,"color":"#d8a878"},{"x":2,"y":24,"z":0,"color":"#d8a878"},{"x":2,"y":24,"z":1,"color":"#d8a878"},{"x":2,"y":24,"z":2,"color":"#d8a878"},{"x":2,"y":24,"z":3,"color":"#d8a878"},{"x":2,"y":24,"z":4,"color":"#d8a878"},{"x":2,"y":24,"z":5,"color":"#d8a878"},{"x":2,"y":24,"z":6,"color":"#d8a878"},{"x":2,"y":25,"z":0,"color":"#d8a878"},{"x":2,"y":25,"z":1,"color":"#d8a878"},{"x":2,"y":25,"z":2,"color":"#d8a878"},{"x":2,"y":25,"z":3,"color":"#d8a878"},{"x":2,"y":25,"z":4,"color":"#d8a878"},{"x":2,"y":25,"z":5,"color":"#d8a878"},{"x":2,"y":25,"z":6,"color":"#d8a878"},{"x":2,"y":26,"z":0,"color":"#d8a878"},{"x":2,"y":26,"z":1,"color":"#d8a878"},{"x":2,"y":26,"z":2,"color":"#d8a878"},{"x":2,"y":26,"z":3,"color":"#d8a878"},{"x":2,"y":26,"z":4,"color":"#d8a878"},{"x":2,"y":26,"z":5,"color":"#d8a878"},{"x":2,"y":26,"z":6,"color":"#d8a878"},{"x":2,"y":27,"z":0,"color":"#d8a878"},{"x":2,"y":27,"z":1,"color":"#d8a878"},{"x":2,"y":27,"z":2,"color":"#d8a878"},{"x":2,"y":27,"z":3,"color":"#d8a878"},{"x":2,"y":27,"z":4,"color":"#d8a878"},{"x":2,"y":27,"z":5,"color":"#d8a878"},{"x":2,"y":27,"z":6,"color":"#d8a878"},{"x":2,"y":28,"z":0,"color":"#d8a878"},{"x":2,"y":28,"z":1,"color":"#d8a878"},{"x":2,"y":28,"z":2,"color":"#d8a878"},{"x":2,"y":28,"z":3,"color":"#d8a878"},{"x":2,"y":28,"z":4,"color":"#d8a878"},{"x":2,"y":28,"z":5,"color":"#d8a878"},{"x":2,"y":28,"z":6,"color":"#d8a878"},{"x":2,"y":29,"z":0,"color":"#d8a878"},{"x":2,"y":29,"z":1,"color":"#d8a878"},{"x":2,"y":29,"z":2,"color":"#d8a878"},{"x":2,"y":29,"z":3,"color":"#d8a878"},{"x":2,"y":29,"z":4,"color":"#d8a878"},{"x":2,"y":29,"z":5,"color":"#d8a878"},{"x":2,"y":29,"z":6,"color":"#d8a878"},{"x":2,"y":30,"z":0,"color":"#d8a878"},{"x":2,"y":30,"z":1,"color":"#d8a878"},{"x":2,"y":30,"z":2,"color":"#d8a878"},{"x":2,"y":30,"z":3,"color":"#d8a878"},{"x":2,"y":30,"z":4,"color":"#d8a878"},{"x":2,"y":30,"z":5,"color":"#d8a878"},{"x":2,"y":30,"z":6,"color":"#d8a878"},{"x":2,"y":31,"z":0,"color":"#d8a878"},{"x":2,"y":31,"z":1,"color":"#d8a878"},{"x":2,"y":31,"z":2,"color":"#d8a878"},{"x":2,"y":31,"z":3,"color":"#d8a878"},{"x":2,"y":31,"z":4,"color":"#d8a878"},{"x":2,"y":31,"z":5,"color":"#d8a878"},{"x":2,"y":31,"z":6,"color":"#d8a878"},{"x":3,"y":24,"z":0,"color":"#d8a878"},{"x":3,"y":24,"z":1,"color":"#d8a878"},{"x":3,"y":24,"z":2,"color":"#d8a878"},{"x":3,"y":24,"z":3,"color":"#d8a878"},{"x":3,"y":24,"z":4,"color":"#d8a878"},{"x":3,"y":24,"z":5,"color":"#d8a878"},{"x":3,"y":24,"z":6,"color":"#d8a878"},{"x":3,"y":25,"z":0,"color":"#d8a878"},{"x":3,"y":25,"z":1,"color":"#d8a878"},{"x":3,"y":25,"z":2,"color":"#d8a878"},{"x":3,"y":25,"z":3,"color":"#d8a878"},{"x":3,"y":25,"z":4,"color":"#d8a878"},{"x":3,"y":25,"z":5,"color":"#d8a878"},{"x":3,"y":25,"z":6,"color":"#d8a878"},{"x":3,"y":26,"z":0,"color":"#d8a878"},{"x":3,"y":26,"z":1,"color":"#d8a878"},{"x":3,"y":26,"z":2,"color":"#d8a878"},{"x":3,"y":26,"z":3,"color":"#d8a878"},{"x":3,"y":26,"z":4,"color":"#d8a878"},{"x":3,"y":26,"z":5,"color":"#d8a878"},{"x":3,"y":26,"z":6,"color":"#d8a878"},{"x":3,"y":27,"z":0,"color":"#d8a878"},{"x":3,"y":27,"z":1,"color":"#d8a878"},{"x":3,"y":27,"z":2,"color":"#d8a878"},{"x":3,"y":27,"z":3,"color":"#d8a878"},{"x":3,"y":27,"z":4,"color":"#d8a878"},{"x":3,"y":27,"z":5,"color":"#d8a878"},{"x":3,"y":27,"z":6,"color":"#d8a878"},{"x":3,"y":28,"z":0,"color":"#d8a878"},{"x":3,"y":28,"z":1,"color":"#d8a878"},{"x":3,"y":28,"z":2,"color":"#d8a878"},{"x":3,"y":28,"z":3,"color":"#d8a878"},{"x":3,"y":28,"z":4,"color":"#d8a878"},{"x":3,"y":28,"z":5,"color":"#d8a878"},{"x":3,"y":28,"z":6,"color":"#d8a878"},{"x":3,"y":29,"z":0,"color":"#d8a878"},{"x":3,"y":29,"z":1,"color":"#d8a878"},{"x":3,"y":29,"z":2,"color":"#d8a878"},{"x":3,"y":29,"z":3,"color":"#d8a878"},{"x":3,"y":29,"z":4,"color":"#d8a878"},{"x":3,"y":29,"z":5,"color":"#d8a878"},{"x":3,"y":29,"z":6,"color":"#d8a878"},{"x":3,"y":30,"z":0,"color":"#d8a878"},{"x":3,"y":30,"z":1,"color":"#d8a878"},{"x":3,"y":30,"z":2,"color":"#d8a878"},{"x":3,"y":30,"z":3,"color":"#d8a878"},{"x":3,"y":30,"z":4,"color":"#d8a878"},{"x":3,"y":30,"z":5,"color":"#d8a878"},{"x":3,"y":30,"z":6,"color":"#d8a878"},{"x":3,"y":31,"z":0,"color":"#d8a878"},{"x":3,"y":31,"z":1,"color":"#d8a878"},{"x":3,"y":31,"z":2,"color":"#d8a878"},{"x":3,"y":31,"z":3,"color":"#d8a878"},{"x":3,"y":31,"z":4,"color":"#d8a878"},{"x":3,"y":31,"z":5,"color":"#d8a878"},{"x":3,"y":31,"z":6,"color":"#d8a878"},{"x":4,"y":24,"z":0,"color":"#d8a878"},{"x":4,"y":24,"z":1,"color":"#d8a878"},{"x":4,"y":24,"z":2,"color":"#d8a878"},{"x":4,"y":24,"z":3,"color":"#d8a878"},{"x":4,"y":24,"z":4,"color":"#d8a878"},{"x":4,"y":24,"z":5,"color":"#d8a878"},{"x":4,"y":24,"z":6,"color":"#d8a878"},{"x":4,"y":25,"z":0,"color":"#d8a878"},{"x":4,"y":25,"z":1,"color":"#d8a878"},{"x":4,"y":25,"z":2,"color":"#d8a878"},{"x":4,"y":25,"z":3,"color":"#d8a878"},{"x":4,"y":25,"z":4,"color":"#d8a878"},{"x":4,"y":25,"z":5,"color":"#d8a878"},{"x":4,"y":25,"z":6,"color":"#d8a878"},{"x":4,"y":26,"z":0,"color":"#d8a878"},{"x":4,"y":26,"z":1,"color":"#d8a878"},{"x":4,"y":26,"z":2,"color":"#d8a878"},{"x":4,"y":26,"z":3,"color":"#d8a878"},{"x":4,"y":26,"z":4,"color":"#d8a878"},{"x":4,"y":26,"z":5,"color":"#d8a878"},{"x":4,"y":26,"z":6,"color":"#d8a878"},{"x":4,"y":27,"z":0,"color":"#d8a878"},{"x":4,"y":27,"z":1,"color":"#d8a878"},{"x":4,"y":27,"z":2,"color":"#d8a878"},{"x":4,"y":27,"z":3,"color":"#d8a878"},{"x":4,"y":27,"z":4,"color":"#d8a878"},{"x":4,"y":27,"z":5,"color":"#d8a878"},{"x":4,"y":27,"z":6,"color":"#d8a878"},{"x":4,"y":28,"z":0,"color":"#d8a878"},{"x":4,"y":28,"z":1,"color":"#d8a878"},{"x":4,"y":28,"z":2,"color":"#d8a878"},{"x":4,"y":28,"z":3,"color":"#d8a878"},{"x":4,"y":28,"z":4,"color":"#d8a878"},{"x":4,"y":28,"z":5,"color":"#d8a878"},{"x":4,"y":28,"z":6,"color":"#d8a878"},{"x":4,"y":29,"z":0,"color":"#d8a878"},{"x":4,"y":29,"z":1,"color":"#d8a878"},{"x":4,"y":29,"z":2,"color":"#d8a878"},{"x":4,"y":29,"z":3,"color":"#d8a878"},{"x":4,"y":29,"z":4,"color":"#d8a878"},{"x":4,"y":29,"z":5,"color":"#d8a878"},{"x":4,"y":29,"z":6,"color":"#d8a878"},{"x":4,"y":30,"z":0,"color":"#d8a878"},{"x":4,"y":30,"z":1,"color":"#d8a878"},{"x":4,"y":30,"z":2,"color":"#d8a878"},{"x":4,"y":30,"z":3,"color":"#d8a878"},{"x":4,"y":30,"z":4,"color":"#d8a878"},{"x":4,"y":30,"z":5,"color":"#d8a878"},{"x":4,"y":30,"z":6,"color":"#d8a878"},{"x":4,"y":31,"z":0,"color":"#d8a878"},{"x":4,"y":31,"z":1,"color":"#d8a878"},{"x":4,"y":31,"z":2,"color":"#d8a878"},{"x":4,"y":31,"z":3,"color":"#d8a878"},{"x":4,"y":31,"z":4,"color":"#d8a878"},{"x":4,"y":31,"z":5,"color":"#d8a878"},{"x":4,"y":31,"z":6,"color":"#d8a878"},{"x":5,"y":24,"z":0,"color":"#d8a878"},{"x":5,"y":24,"z":1,"color":"#d8a878"},{"x":5,"y":24,"z":2,"color":"#d8a878"},{"x":5,"y":24,"z":3,"color":"#d8a878"},{"x":5,"y":24,"z":4,"color":"#d8a878"},{"x":5,"y":24,"z":5,"color":"#d8a878"},{"x":5,"y":24,"z":6,"color":"#d8a878"},{"x":5,"y":25,"z":0,"color":"#d8a878"},{"x":5,"y":25,"z":1,"color":"#d8a878"},{"x":5,"y":25,"z":2,"color":"#d8a878"},{"x":5,"y":25,"z":3,"color":"#d8a878"},{"x":5,"y":25,"z":4,"color":"#d8a878"},{"x":5,"y":25,"z":5,"color":"#d8a878"},{"x":5,"y":25,"z":6,"color":"#d8a878"},{"x":5,"y":26,"z":0,"color":"#d8a878"},{"x":5,"y":26,"z":1,"color":"#d8a878"},{"x":5,"y":26,"z":2,"color":"#d8a878"},{"x":5,"y":26,"z":3,"color":"#d8a878"},{"x":5,"y":26,"z":4,"color":"#d8a878"},{"x":5,"y":26,"z":5,"color":"#d8a878"},{"x":5,"y":26,"z":6,"color":"#d8a878"},{"x":5,"y":27,"z":0,"color":"#d8a878"},{"x":5,"y":27,"z":1,"color":"#d8a878"},{"x":5,"y":27,"z":2,"color":"#d8a878"},{"x":5,"y":27,"z":3,"color":"#d8a878"},{"x":5,"y":27,"z":4,"color":"#d8a878"},{"x":5,"y":27,"z":5,"color":"#d8a878"},{"x":5,"y":27,"z":6,"color":"#d8a878"},{"x":5,"y":28,"z":0,"color":"#d8a878"},{"x":5,"y":28,"z":1,"color":"#d8a878"},{"x":5,"y":28,"z":2,"color":"#d8a878"},{"x":5,"y":28,"z":3,"color":"#d8a878"},{"x":5,"y":28,"z":4,"color":"#d8a878"},{"x":5,"y":28,"z":5,"color":"#d8a878"},{"x":5,"y":28,"z":6,"color":"#d8a878"},{"x":5,"y":29,"z":0,"color":"#d8a878"},{"x":5,"y":29,"z":1,"color":"#d8a878"},{"x":5,"y":29,"z":2,"color":"#d8a878"},{"x":5,"y":29,"z":3,"color":"#d8a878"},{"x":5,"y":29,"z":4,"color":"#d8a878"},{"x":5,"y":29,"z":5,"color":"#d8a878"},{"x":5,"y":29,"z":6,"color":"#d8a878"},{"x":5,"y":30,"z":0,"color":"#d8a878"},{"x":5,"y":30,"z":1,"color":"#d8a878"},{"x":5,"y":30,"z":2,"color":"#d8a878"},{"x":5,"y":30,"z":3,"color":"#d8a878"},{"x":5,"y":30,"z":4,"color":"#d8a878"},{"x":5,"y":30,"z":5,"color":"#d8a878"},{"x":5,"y":30,"z":6,"color":"#d8a878"},{"x":5,"y":31,"z":0,"color":"#d8a878"},{"x":5,"y":31,"z":1,"color":"#d8a878"},{"x":5,"y":31,"z":2,"color":"#d8a878"},{"x":5,"y":31,"z":3,"color":"#d8a878"},{"x":5,"y":31,"z":4,"color":"#d8a878"},{"x":5,"y":31,"z":5,"color":"#d8a878"},{"x":5,"y":31,"z":6,"color":"#d8a878"},{"x":6,"y":24,"z":0,"color":"#d8a878"},{"x":6,"y":24,"z":1,"color":"#d8a878"},{"x":6,"y":24,"z":2,"color":"#d8a878"},{"x":6,"y":24,"z":3,"color":"#d8a878"},{"x":6,"y":24,"z":4,"color":"#d8a878"},{"x":6,"y":24,"z":5,"color":"#d8a878"},{"x":6,"y":24,"z":6,"color":"#d8a878"},{"x":6,"y":25,"z":0,"color":"#d8a878"},{"x":6,"y":25,"z":1,"color":"#d8a878"},{"x":6,"y":25,"z":2,"color":"#d8a878"},{"x":6,"y":25,"z":3,"color":"#d8a878"},{"x":6,"y":25,"z":4,"color":"#d8a878"},{"x":6,"y":25,"z":5,"color":"#d8a878"},{"x":6,"y":25,"z":6,"color":"#d8a878"},{"x":6,"y":26,"z":0,"color":"#d8a878"},{"x":6,"y":26,"z":1,"color":"#d8a878"},{"x":6,"y":26,"z":2,"color":"#d8a878"},{"x":6,"y":26,"z":3,"color":"#d8a878"},{"x":6,"y":26,"z":4,"color":"#d8a878"},{"x":6,"y":26,"z":5,"color":"#d8a878"},{"x":6,"y":26,"z":6,"color":"#d8a878"},{"x":6,"y":27,"z":0,"color":"#d8a878"},{"x":6,"y":27,"z":1,"color":"#d8a878"},{"x":6,"y":27,"z":2,"color":"#d8a878"},{"x":6,"y":27,"z":3,"color":"#d8a878"},{"x":6,"y":27,"z":4,"color":"#d8a878"},{"x":6,"y":27,"z":5,"color":"#d8a878"},{"x":6,"y":27,"z":6,"color":"#d8a878"},{"x":6,"y":28,"z":0,"color":"#d8a878"},{"x":6,"y":28,"z":1,"color":"#d8a878"},{"x":6,"y":28,"z":2,"color":"#d8a878"},{"x":6,"y":28,"z":3,"color":"#d8a878"},{"x":6,"y":28,"z":4,"color":"#d8a878"},{"x":6,"y":28,"z":5,"color":"#d8a878"},{"x":6,"y":28,"z":6,"color":"#d8a878"},{"x":6,"y":29,"z":0,"color":"#d8a878"},{"x":6,"y":29,"z":1,"color":"#d8a878"},{"x":6,"y":29,"z":2,"color":"#d8a878"},{"x":6,"y":29,"z":3,"color":"#d8a878"},{"x":6,"y":29,"z":4,"color":"#d8a878"},{"x":6,"y":29,"z":5,"color":"#d8a878"},{"x":6,"y":29,"z":6,"color":"#d8a878"},{"x":6,"y":30,"z":0,"color":"#d8a878"},{"x":6,"y":30,"z":1,"color":"#d8a878"},{"x":6,"y":30,"z":2,"color":"#d8a878"},{"x":6,"y":30,"z":3,"color":"#d8a878"},{"x":6,"y":30,"z":4,"color":"#d8a878"},{"x":6,"y":30,"z":5,"color":"#d8a878"},{"x":6,"y":30,"z":6,"color":"#d8a878"},{"x":6,"y":31,"z":0,"color":"#d8a878"},{"x":6,"y":31,"z":1,"color":"#d8a878"},{"x":6,"y":31,"z":2,"color":"#d8a878"},{"x":6,"y":31,"z":3,"color":"#d8a878"},{"x":6,"y":31,"z":4,"color":"#d8a878"},{"x":6,"y":31,"z":5,"color":"#d8a878"},{"x":6,"y":31,"z":6,"color":"#d8a878"},{"x":7,"y":24,"z":0,"color":"#d8a878"},{"x":7,"y":24,"z":1,"color":"#d8a878"},{"x":7,"y":24,"z":2,"color":"#d8a878"},{"x":7,"y":24,"z":3,"color":"#d8a878"},{"x":7,"y":24,"z":4,"color":"#d8a878"},{"x":7,"y":24,"z":5,"color":"#d8a878"},{"x":7,"y":24,"z":6,"color":"#d8a878"},{"x":7,"y":25,"z":0,"color":"#d8a878"},{"x":7,"y":25,"z":1,"color":"#d8a878"},{"x":7,"y":25,"z":2,"color":"#d8a878"},{"x":7,"y":25,"z":3,"color":"#d8a878"},{"x":7,"y":25,"z":4,"color":"#d8a878"},{"x":7,"y":25,"z":5,"color":"#d8a878"},{"x":7,"y":25,"z":6,"color":"#d8a878"},{"x":7,"y":26,"z":0,"color":"#d8a878"},{"x":7,"y":26,"z":1,"color":"#d8a878"},{"x":7,"y":26,"z":2,"color":"#d8a878"},{"x":7,"y":26,"z":3,"color":"#d8a878"},{"x":7,"y":26,"z":4,"color":"#d8a878"},{"x":7,"y":26,"z":5,"color":"#d8a878"},{"x":7,"y":26,"z":6,"color":"#d8a878"},{"x":7,"y":27,"z":0,"color":"#d8a878"},{"x":7,"y":27,"z":1,"color":"#d8a878"},{"x":7,"y":27,"z":2,"color":"#d8a878"},{"x":7,"y":27,"z":3,"color":"#d8a878"},{"x":7,"y":27,"z":4,"color":"#d8a878"},{"x":7,"y":27,"z":5,"color":"#d8a878"},{"x":7,"y":27,"z":6,"color":"#d8a878"},{"x":7,"y":28,"z":0,"color":"#d8a878"},{"x":7,"y":28,"z":1,"color":"#d8a878"},{"x":7,"y":28,"z":2,"color":"#d8a878"},{"x":7,"y":28,"z":3,"color":"#d8a878"},{"x":7,"y":28,"z":4,"color":"#d8a878"},{"x":7,"y":28,"z":5,"color":"#d8a878"},{"x":7,"y":28,"z":6,"color":"#d8a878"},{"x":7,"y":29,"z":0,"color":"#d8a878"},{"x":7,"y":29,"z":1,"color":"#d8a878"},{"x":7,"y":29,"z":2,"color":"#d8a878"},{"x":7,"y":29,"z":3,"color":"#d8a878"},{"x":7,"y":29,"z":4,"color":"#d8a878"},{"x":7,"y":29,"z":5,"color":"#d8a878"},{"x":7,"y":29,"z":6,"color":"#d8a878"},{"x":7,"y":30,"z":0,"color":"#d8a878"},{"x":7,"y":30,"z":1,"color":"#d8a878"},{"x":7,"y":30,"z":2,"color":"#d8a878"},{"x":7,"y":30,"z":3,"color":"#d8a878"},{"x":7,"y":30,"z":4,"color":"#d8a878"},{"x":7,"y":30,"z":5,"color":"#d8a878"},{"x":7,"y":30,"z":6,"color":"#d8a878"},{"x":7,"y":31,"z":0,"color":"#d8a878"},{"x":7,"y":31,"z":1,"color":"#d8a878"},{"x":7,"y":31,"z":2,"color":"#d8a878"},{"x":7,"y":31,"z":3,"color":"#d8a878"},{"x":7,"y":31,"z":4,"color":"#d8a878"},{"x":7,"y":31,"z":5,"color":"#d8a878"},{"x":7,"y":31,"z":6,"color":"#d8a878"},{"x":8,"y":24,"z":0,"color":"#d8a878"},{"x":8,"y":24,"z":1,"color":"#d8a878"},{"x":8,"y":24,"z":2,"color":"#d8a878"},{"x":8,"y":24,"z":3,"color":"#d8a878"},{"x":8,"y":24,"z":4,"color":"#d8a878"},{"x":8,"y":24,"z":5,"color":"#d8a878"},{"x":8,"y":24,"z":6,"color":"#d8a878"},{"x":8,"y":25,"z":0,"color":"#d8a878"},{"x":8,"y":25,"z":1,"color":"#d8a878"},{"x":8,"y":25,"z":2,"color":"#d8a878"},{"x":8,"y":25,"z":3,"color":"#d8a878"},{"x":8,"y":25,"z":4,"color":"#d8a878"},{"x":8,"y":25,"z":5,"color":"#d8a878"},{"x":8,"y":25,"z":6,"color":"#d8a878"},{"x":8,"y":26,"z":0,"color":"#d8a878"},{"x":8,"y":26,"z":1,"color":"#d8a878"},{"x":8,"y":26,"z":2,"color":"#d8a878"},{"x":8,"y":26,"z":3,"color":"#d8a878"},{"x":8,"y":26,"z":4,"color":"#d8a878"},{"x":8,"y":26,"z":5,"color":"#d8a878"},{"x":8,"y":26,"z":6,"color":"#d8a878"},{"x":8,"y":27,"z":0,"color":"#d8a878"},{"x":8,"y":27,"z":1,"color":"#d8a878"},{"x":8,"y":27,"z":2,"color":"#d8a878"},{"x":8,"y":27,"z":3,"color":"#d8a878"},{"x":8,"y":27,"z":4,"color":"#d8a878"},{"x":8,"y":27,"z":5,"color":"#d8a878"},{"x":8,"y":27,"z":6,"color":"#d8a878"},{"x":8,"y":28,"z":0,"color":"#d8a878"},{"x":8,"y":28,"z":1,"color":"#d8a878"},{"x":8,"y":28,"z":2,"color":"#d8a878"},{"x":8,"y":28,"z":3,"color":"#d8a878"},{"x":8,"y":28,"z":4,"color":"#d8a878"},{"x":8,"y":28,"z":5,"color":"#d8a878"},{"x":8,"y":28,"z":6,"color":"#d8a878"},{"x":8,"y":29,"z":0,"color":"#d8a878"},{"x":8,"y":29,"z":1,"color":"#d8a878"},{"x":8,"y":29,"z":2,"color":"#d8a878"},{"x":8,"y":29,"z":3,"color":"#d8a878"},{"x":8,"y":29,"z":4,"color":"#d8a878"},{"x":8,"y":29,"z":5,"color":"#d8a878"},{"x":8,"y":29,"z":6,"color":"#d8a878"},{"x":8,"y":30,"z":0,"color":"#d8a878"},{"x":8,"y":30,"z":1,"color":"#d8a878"},{"x":8,"y":30,"z":2,"color":"#d8a878"},{"x":8,"y":30,"z":3,"color":"#d8a878"},{"x":8,"y":30,"z":4,"color":"#d8a878"},{"x":8,"y":30,"z":5,"color":"#d8a878"},{"x":8,"y":30,"z":6,"color":"#d8a878"},{"x":8,"y":31,"z":0,"color":"#d8a878"},{"x":8,"y":31,"z":1,"color":"#d8a878"},{"x":8,"y":31,"z":2,"color":"#d8a878"},{"x":8,"y":31,"z":3,"color":"#d8a878"},{"x":8,"y":31,"z":4,"color":"#d8a878"},{"x":8,"y":31,"z":5,"color":"#d8a878"},{"x":8,"y":31,"z":6,"color":"#d8a878"},{"x":9,"y":24,"z":0,"color":"#d8a878"},{"x":9,"y":24,"z":1,"color":"#d8a878"},{"x":9,"y":24,"z":2,"color":"#d8a878"},{"x":9,"y":24,"z":3,"color":"#d8a878"},{"x":9,"y":24,"z":4,"color":"#d8a878"},{"x":9,"y":24,"z":5,"color":"#d8a878"},{"x":9,"y":24,"z":6,"color":"#d8a878"},{"x":9,"y":25,"z":0,"color":"#d8a878"},{"x":9,"y":25,"z":1,"color":"#d8a878"},{"x":9,"y":25,"z":2,"color":"#d8a878"},{"x":9,"y":25,"z":3,"color":"#d8a878"},{"x":9,"y":25,"z":4,"color":"#d8a878"},{"x":9,"y":25,"z":5,"color":"#d8a878"},{"x":9,"y":25,"z":6,"color":"#d8a878"},{"x":9,"y":26,"z":0,"color":"#d8a878"},{"x":9,"y":26,"z":1,"color":"#d8a878"},{"x":9,"y":26,"z":2,"color":"#d8a878"},{"x":9,"y":26,"z":3,"color":"#d8a878"},{"x":9,"y":26,"z":4,"color":"#d8a878"},{"x":9,"y":26,"z":5,"color":"#d8a878"},{"x":9,"y":26,"z":6,"color":"#d8a878"},{"x":9,"y":27,"z":0,"color":"#d8a878"},{"x":9,"y":27,"z":1,"color":"#d8a878"},{"x":9,"y":27,"z":2,"color":"#d8a878"},{"x":9,"y":27,"z":3,"color":"#d8a878"},{"x":9,"y":27,"z":4,"color":"#d8a878"},{"x":9,"y":27,"z":5,"color":"#d8a878"},{"x":9,"y":27,"z":6,"color":"#d8a878"},{"x":9,"y":28,"z":0,"color":"#d8a878"},{"x":9,"y":28,"z":1,"color":"#d8a878"},{"x":9,"y":28,"z":2,"color":"#d8a878"},{"x":9,"y":28,"z":3,"color":"#d8a878"},{"x":9,"y":28,"z":4,"color":"#d8a878"},{"x":9,"y":28,"z":5,"color":"#d8a878"},{"x":9,"y":28,"z":6,"color":"#d8a878"},{"x":9,"y":29,"z":0,"color":"#d8a878"},{"x":9,"y":29,"z":1,"color":"#d8a878"},{"x":9,"y":29,"z":2,"color":"#d8a878"},{"x":9,"y":29,"z":3,"color":"#d8a878"},{"x":9,"y":29,"z":4,"color":"#d8a878"},{"x":9,"y":29,"z":5,"color":"#d8a878"},{"x":9,"y":29,"z":6,"color":"#d8a878"},{"x":9,"y":30,"z":0,"color":"#d8a878"},{"x":9,"y":30,"z":1,"color":"#d8a878"},{"x":9,"y":30,"z":2,"color":"#d8a878"},{"x":9,"y":30,"z":3,"color":"#d8a878"},{"x":9,"y":30,"z":4,"color":"#d8a878"},{"x":9,"y":30,"z":5,"color":"#d8a878"},{"x":9,"y":30,"z":6,"color":"#d8a878"},{"x":9,"y":31,"z":0,"color":"#d8a878"},{"x":9,"y":31,"z":1,"color":"#d8a878"},{"x":9,"y":31,"z":2,"color":"#d8a878"},{"x":9,"y":31,"z":3,"color":"#d8a878"},{"x":9,"y":31,"z":4,"color":"#d8a878"},{"x":9,"y":31,"z":5,"color":"#d8a878"},{"x":9,"y":31,"z":6,"color":"#d8a878"},{"x":10,"y":24,"z":0,"color":"#d8a878"},{"x":10,"y":24,"z":1,"color":"#d8a878"},{"x":10,"y":24,"z":2,"color":"#d8a878"},{"x":10,"y":24,"z":3,"color":"#d8a878"},{"x":10,"y":24,"z":4,"color":"#d8a878"},{"x":10,"y":24,"z":5,"color":"#d8a878"},{"x":10,"y":24,"z":6,"color":"#d8a878"},{"x":10,"y":25,"z":0,"color":"#d8a878"},{"x":10,"y":25,"z":1,"color":"#d8a878"},{"x":10,"y":25,"z":2,"color":"#d8a878"},{"x":10,"y":25,"z":3,"color":"#d8a878"},{"x":10,"y":25,"z":4,"color":"#d8a878"},{"x":10,"y":25,"z":5,"color":"#d8a878"},{"x":10,"y":25,"z":6,"color":"#d8a878"},{"x":10,"y":26,"z":0,"color":"#d8a878"},{"x":10,"y":26,"z":1,"color":"#d8a878"},{"x":10,"y":26,"z":2,"color":"#d8a878"},{"x":10,"y":26,"z":3,"color":"#d8a878"},{"x":10,"y":26,"z":4,"color":"#d8a878"},{"x":10,"y":26,"z":5,"color":"#d8a878"},{"x":10,"y":26,"z":6,"color":"#d8a878"},{"x":10,"y":27,"z":0,"color":"#d8a878"},{"x":10,"y":27,"z":1,"color":"#d8a878"},{"x":10,"y":27,"z":2,"color":"#d8a878"},{"x":10,"y":27,"z":3,"color":"#d8a878"},{"x":10,"y":27,"z":4,"color":"#d8a878"},{"x":10,"y":27,"z":5,"color":"#d8a878"},{"x":10,"y":27,"z":6,"color":"#d8a878"},{"x":10,"y":28,"z":0,"color":"#d8a878"},{"x":10,"y":28,"z":1,"color":"#d8a878"},{"x":10,"y":28,"z":2,"color":"#d8a878"},{"x":10,"y":28,"z":3,"color":"#d8a878"},{"x":10,"y":28,"z":4,"color":"#d8a878"},{"x":10,"y":28,"z":5,"color":"#d8a878"},{"x":10,"y":28,"z":6,"color":"#d8a878"},{"x":10,"y":29,"z":0,"color":"#d8a878"},{"x":10,"y":29,"z":1,"color":"#d8a878"},{"x":10,"y":29,"z":2,"color":"#d8a878"},{"x":10,"y":29,"z":3,"color":"#d8a878"},{"x":10,"y":29,"z":4,"color":"#d8a878"},{"x":10,"y":29,"z":5,"color":"#d8a878"},{"x":10,"y":29,"z":6,"color":"#d8a878"},{"x":10,"y":30,"z":0,"color":"#d8a878"},{"x":10,"y":30,"z":1,"color":"#d8a878"},{"x":10,"y":30,"z":2,"color":"#d8a878"},{"x":10,"y":30,"z":3,"color":"#d8a878"},{"x":10,"y":30,"z":4,"color":"#d8a878"},{"x":10,"y":30,"z":5,"color":"#d8a878"},{"x":10,"y":30,"z":6,"color":"#d8a878"},{"x":10,"y":31,"z":0,"color":"#d8a878"},{"x":10,"y":31,"z":1,"color":"#d8a878"},{"x":10,"y":31,"z":2,"color":"#d8a878"},{"x":10,"y":31,"z":3,"color":"#d8a878"},{"x":10,"y":31,"z":4,"color":"#d8a878"},{"x":10,"y":31,"z":5,"color":"#d8a878"},{"x":10,"y":31,"z":6,"color":"#d8a878"},{"x":11,"y":24,"z":0,"color":"#d8a878"},{"x":11,"y":24,"z":1,"color":"#d8a878"},{"x":11,"y":24,"z":2,"color":"#d8a878"},{"x":11,"y":24,"z":3,"color":"#d8a878"},{"x":11,"y":24,"z":4,"color":"#d8a878"},{"x":11,"y":24,"z":5,"color":"#d8a878"},{"x":11,"y":24,"z":6,"color":"#d8a878"},{"x":11,"y":25,"z":0,"color":"#d8a878"},{"x":11,"y":25,"z":1,"color":"#d8a878"},{"x":11,"y":25,"z":2,"color":"#d8a878"},{"x":11,"y":25,"z":3,"color":"#d8a878"},{"x":11,"y":25,"z":4,"color":"#d8a878"},{"x":11,"y":25,"z":5,"color":"#d8a878"},{"x":11,"y":25,"z":6,"color":"#d8a878"},{"x":11,"y":26,"z":0,"color":"#d8a878"},{"x":11,"y":26,"z":1,"color":"#d8a878"},{"x":11,"y":26,"z":2,"color":"#d8a878"},{"x":11,"y":26,"z":3,"color":"#d8a878"},{"x":11,"y":26,"z":4,"color":"#d8a878"},{"x":11,"y":26,"z":5,"color":"#d8a878"},{"x":11,"y":26,"z":6,"color":"#d8a878"},{"x":11,"y":27,"z":0,"color":"#d8a878"},{"x":11,"y":27,"z":1,"color":"#d8a878"},{"x":11,"y":27,"z":2,"color":"#d8a878"},{"x":11,"y":27,"z":3,"color":"#d8a878"},{"x":11,"y":27,"z":4,"color":"#d8a878"},{"x":11,"y":27,"z":5,"color":"#d8a878"},{"x":11,"y":27,"z":6,"color":"#d8a878"},{"x":11,"y":28,"z":0,"color":"#d8a878"},{"x":11,"y":28,"z":1,"color":"#d8a878"},{"x":11,"y":28,"z":2,"color":"#d8a878"},{"x":11,"y":28,"z":3,"color":"#d8a878"},{"x":11,"y":28,"z":4,"color":"#d8a878"},{"x":11,"y":28,"z":5,"color":"#d8a878"},{"x":11,"y":28,"z":6,"color":"#d8a878"},{"x":11,"y":29,"z":0,"color":"#d8a878"},{"x":11,"y":29,"z":1,"color":"#d8a878"},{"x":11,"y":29,"z":2,"color":"#d8a878"},{"x":11,"y":29,"z":3,"color":"#d8a878"},{"x":11,"y":29,"z":4,"color":"#d8a878"},{"x":11,"y":29,"z":5,"color":"#d8a878"},{"x":11,"y":29,"z":6,"color":"#d8a878"},{"x":11,"y":30,"z":0,"color":"#d8a878"},{"x":11,"y":30,"z":1,"color":"#d8a878"},{"x":11,"y":30,"z":2,"color":"#d8a878"},{"x":11,"y":30,"z":3,"color":"#d8a878"},{"x":11,"y":30,"z":4,"color":"#d8a878"},{"x":11,"y":30,"z":5,"color":"#d8a878"},{"x":11,"y":30,"z":6,"color":"#d8a878"},{"x":11,"y":31,"z":0,"color":"#d8a878"},{"x":11,"y":31,"z":1,"color":"#d8a878"},{"x":11,"y":31,"z":2,"color":"#d8a878"},{"x":11,"y":31,"z":3,"color":"#d8a878"},{"x":11,"y":31,"z":4,"color":"#d8a878"},{"x":11,"y":31,"z":5,"color":"#d8a878"},{"x":11,"y":31,"z":6,"color":"#d8a878"},{"x":0,"y":28,"z":7,"color":"#141418"},{"x":0,"y":29,"z":7,"color":"#141418"},{"x":1,"y":28,"z":7,"color":"#141418"},{"x":1,"y":29,"z":7,"color":"#141418"},{"x":2,"y":28,"z":7,"color":"#141418"},{"x":2,"y":29,"z":7,"color":"#141418"},{"x":3,"y":28,"z":7,"color":"#141418"},{"x":3,"y":29,"z":7,"color":"#141418"},{"x":4,"y":28,"z":7,"color":"#141418"},{"x":4,"y":29,"z":7,"color":"#141418"},{"x":7,"y":28,"z":7,"color":"#141418"},{"x":7,"y":29,"z":7,"color":"#141418"},{"x":8,"y":28,"z":7,"color":"#141418"},{"x":8,"y":29,"z":7,"color":"#141418"},{"x":9,"y":28,"z":7,"color":"#141418"},{"x":9,"y":29,"z":7,"color":"#141418"},{"x":10,"y":28,"z":7,"color":"#141418"},{"x":10,"y":29,"z":7,"color":"#141418"},{"x":11,"y":28,"z":7,"color":"#141418"},{"x":11,"y":29,"z":7,"color":"#141418"},{"x":0,"y":32,"z":0,"color":"#6b4a2b"},{"x":0,"y":32,"z":1,"color":"#6b4a2b"},{"x":0,"y":32,"z":2,"color":"#6b4a2b"},{"x":0,"y":32,"z":3,"color":"#6b4a2b"},{"x":0,"y":32,"z":4,"color":"#6b4a2b"},{"x":0,"y":32,"z":5,"color":"#6b4a2b"},{"x":0,"y":32,"z":6,"color":"#6b4a2b"},{"x":0,"y":33,"z":0,"color":"#6b4a2b"},{"x":0,"y":34,"z":0,"color":"#6b4a2b"},{"x":0,"y":35,"z":0,"color":"#6b4a2b"},{"x":1,"y":32,"z":0,"color":"#6b4a2b"},{"x":1,"y":32,"z":1,"color":"#6b4a2b"},{"x":1,"y":32,"z":2,"color":"#6b4a2b"},{"x":1,"y":32,"z":3,"color":"#6b4a2b"},{"x":1,"y":32,"z":4,"color":"#6b4a2b"},{"x":1,"y":32,"z":5,"color":"#6b4a2b"},{"x":1,"y":32,"z":6,"color":"#6b4a2b"},{"x":1,"y":33,"z":1,"color":"#6b4a2b"},{"x":1,"y":33,"z":2,"color":"#6b4a2b"},{"x":1,"y":33,"z":3,"color":"#6b4a2b"},{"x":1,"y":33,"z":4,"color":"#6b4a2b"},{"x":1,"y":33,"z":5,"color":"#6b4a2b"},{"x":1,"y":34,"z":1,"color":"#6b4a2b"},{"x":1,"y":34,"z":2,"color":"#6b4a2b"},{"x":1,"y":34,"z":3,"color":"#6b4a2b"},{"x":1,"y":34,"z":4,"color":"#6b4a2b"},{"x":1,"y":34,"z":5,"color":"#6b4a2b"},{"x":1,"y":35,"z":1,"color":"#6b4a2b"},{"x":1,"y":35,"z":2,"color":"#6b4a2b"},{"x":1,"y":35,"z":3,"color":"#6b4a2b"},{"x":1,"y":35,"z":4,"color":"#6b4a2b"},