{"voxels":[{"x":-1,"y":7,"z":-16,"color":"#2b3f50"},{"x":-1,"y":7,"z":-15,"color":"#2b3f50"},{"x":-1,"y":7,"z":-14,"color":"#2b3f50"},{"x":-1,"y":7,"z":-13,"color":"#2b3f50"},{"x":-1,"y":7,"z":-12,"color":"#2b3f50"},{"x":-1,"y":8,"z":-17,"color":"#2b3f50"},{"x":-1,"y":8,"z":-16,"color":"#5f93ad"},{"x":-1,"y":8,"z":-15,"color":"#5f93ad"},{"x":-1,"y":8,"z":-14,"color":"#5f93ad"},{"x":-1,"y":8,"z":-13,"color":"#5f93ad"},{"x":-1,"y":8,"z":-12,"color":"#2b3f50"},{"x":-1,"y":9,"z":-17,"color":"#2b3f50"},{"x":-1,"y":9,"z":-16,"color":"#a9d6e6"},{"x":-1,"y":9,"z":-15,"color":"#a9d6e6"},{"x":-1,"y":9,"z":-14,"color":"#a9d6e6"},{"x":-1,"y":9,"z":-13,"color":"#a9d6e6"},{"x":-1,"y":9,"z":-12,"color":"#a9d6e6"},{"x":-1,"y":10,"z":-17,"color":"#2b3f50"},{"x":-1,"y":10,"z":-16,"color":"#a9d6e6"},{"x":-1,"y":11,"z":-17,"color":"#2b3f50"},{"x":-1,"y":11,"z":-16,"color":"#a9d6e6"},{"x":-1,"y":11,"z":-15,"color":"#a9d6e6"},{"x":-1,"y":11,"z":-14,"color":"#a9d6e6"},{"x":-1,"y":11,"z":-13,"color":"#a9d6e6"},{"x":-1,"y":11,"z":-12,"color":"#a9d6e6"},{"x":-1,"y":12,"z":-16,"color":"#a9d6e6"},{"x":-1,"y":12,"z":-15,"color":"#a9d6e6"},{"x":-1,"y":12,"z":-14,"color":"#a9d6e6"},{"x":-1,"y":13,"z":-15,"color":"#a9d6e6"},{"x":-1,"y":13,"z":-14,"color":"#a9d6e6"},{"x":-1,"y":13,"z":-13,"color":"#a9d6e6"},{"x":-1,"y":13,"z":-12,"color":"#d6eef5"},{"x":0,"y":7,"z":-16,"color":"#2b3f50"},{"x":0,"y":7,"z":-15,"color":"#2b3f50"},{"x":0,"y":7,"z":-14,"color":"#2b3f50"},{"x":0,"y":7,"z":-13,"color":"#2b3f50"},{"x":0,"y":7,"z":-12,"color":"#2b3f50"},{"x":0,"y":8,"z":-17,"color":"#2b3f50"},{"x":0,"y":8,"z":-16,"color":"#5f93ad"},{"x":0,"y":8,"z":-15,"color":"#5f93ad"},{"x":0,"y":8,"z":-14,"color":"#5f93ad"},{"x":0,"y":8,"z":-13,"color":"#5f93ad"},{"x":0,"y":8,"z":-12,"color":"#2b3f50"},{"x":0,"y":9,"z":-17,"color":"#2b3f50"},{"x":0,"y":9,"z":-16,"color":"#a9d6e6"},{"x":0,"y":9,"z":-15,"color":"#a9d6e6"},{"x":0,"y":9,"z":-14,"color":"#a9d6e6"},{"x":0,"y":9,"z":-13,"color":"#a9d6e6"},{"x":0,"y":9,"z":-12,"color":"#a9d6e6"},{"x":0,"y":10,"z":-17,"color":"#2b3f50"},{"x":0,"y":10,"z":-16,"color":"#a9d6e6"},{"x":0,"y":10,"z":-15,"color":"#a9d6e6"},{"x":0,"y":10,"z":-14,"color":"#a9d6e6"},{"x":0,"y":10,"z":-13,"color":"#a9d6e6"},{"x":0,"y":10,"z":-12,"color":"#a9d6e6"},{"x":0,"y":11,"z":-17,"color":"#2b3f50"},{"x":0,"y":11,"z":-16,"color":"#a9d6e6"},{"x":0,"y":11,"z":-15,"color":"#a9d6e6"},{"x":0,"y":11,"z":-14,"color":"#a9d6e6"},{"x":0,"y":11,"z":-13,"color":"#a9d6e6"},{"x":0,"y":11,"z":-12,"color":"#a9d6e6"},{"x":0,"y":12,"z":-16,"color":"#a9d6e6"},{"x":0,"y":12,"z":-15,"color":"#a9d6e6"},{"x":0,"y":12,"z":-14,"color":"#a9d6e6"},{"x":0,"y":12,"z":-13,"color":"#a9d6e6"},{"x":0,"y":12,"z":-12,"color":"#a9d6e6"},{"x":0,"y":13,"z":-15,"color":"#a9d6e6"},{"x":0,"y":13,"z":-14,"color":"#a9d6e6"},{"x":0,"y":13,"z":-13,"color":"#a9d6e6"},{"x":0,"y":13,"z":-12,"color":"#a9d6e6"},{"x":1,"y":7,"z":-16,"color":"#2b3f50"},{"x":1,"y":7,"z":-15,"color":"#2b3f50"},{"x":1,"y":7,"z":-14,"color":"#2b3f50"},{"x":1,"y":7,"z":-13,"color":"#2b3f50"},{"x":1,"y":7,"z":-12,"color":"#2b3f50"},{"x":1,"y":8,"z":-17,"color":"#2b3f50"},{"x":1,"y":8,"z":-16,"color":"#5f93ad"},{"x":1,"y":8,"z":-15,"color":"#5f93ad"},{"x":1,"y":8,"z":-14,"color":"#5f93ad"},{"x":1,"y":8,"z":-13,"color":"#5f93ad"},{"x":1,"y":8,"z":-12,"color":"#2b3f50"},{"x":1,"y":9,"z":-17,"color":"#2b3f50"},{"x":1,"y":9,"z":-16,"color":"#a9d6e6"},{"x":1,"y":9,"z":-15,"color":"#a9d6e6"},{"x":1,"y":9,"z":-14,"color":"#a9d6e6"},{"x":1,"y":9,"z":-13,"color":"#a9d6e6"},{"x":1,"y":9,"z":-12,"color":"#a9d6e6"},{"x":1,"y":10,"z":-17,"color":"#2b3f50"},{"x":1,"y":10,"z":-16,"color":"#a9d6e6"},{"x":1,"y":11,"z":-17,"color":"#2b3f50"},{"x":1,"y":11,"z":-16,"color":"#a9d6e6"},{"x":1,"y":11,"z":-15,"color":"#a9d6e6"},{"x":1,"y":11,"z":-14,"color":"#a9d6e6"},{"x":1,"y":11,"z":-13,"color":"#a9d6e6"},{"x":1,"y":11,"z":-12,"color":"#a9d6e6"},{"x":1,"y":12,"z":-16,"color":"#a9d6e6"},{"x":1,"y":12,"z":-15,"color":"#a9d6e6"},{"x":1,"y":12,"z":-14,"color":"#a9d6e6"},{"x":1,"y":13,"z":-15,"color":"#a9d6e6"},{"x":1,"y":13,"z":-14,"color":"#a9d6e6"},{"x":1,"y":13,"z":-13,"color":"#a9d6e6"},{"x":1,"y":13,"z":-12,"color":"#a9d6e6"},{"x":-1,"y":8,"z":-11,"color":"#2b3f50"},{"x":-1,"y":8,"z":-10,"color":"#2b3f50"},{"x":-1,"y":8,"z":-9,"color":"#2b3f50"},{"x":-1,"y":8,"z":-8,"color":"#2b3f50"},{"x":-1,"y":8,"z":-7,"color":"#2b3f50"},{"x":-1,"y":8,"z":-6,"color":"#2b3f50"},{"x":-1,"y":8,"z":-5,"color":"#2b3f50"},{"x":-1,"y":8,"z":-4,"color":"#2b3f50"},{"x":-1,"y":8,"z":-3,"color":"#2b3f50"},{"x":-1,"y":8,"z":-2,"color":"#2b3f50"},{"x":-1,"y":9,"z":-11,"color":"#a9d6e6"},{"x":-1,"y":9,"z":-10,"color":"#a9d6e6"},{"x":-1,"y":9,"z":-9,"color":"#a9d6e6"},{"x":-1,"y":9,"z":-8,"color":"#a9d6e6"},{"x":-1,"y":9,"z":-7,"color":"#a9d6e6"},{"x":-1,"y":9,"z":-6,"color":"#a9d6e6"},{"x":-1,"y":9,"z":-5,"color":"#a9d6e6"},{"x":-1,"y":9,"z":-4,"color":"#a9d6e6"},{"x":-1,"y":9,"z":-3,"color":"#a9d6e6"},{"x":-1,"y":9,"z":-2,"color":"#2b3f50"},{"x":-1,"y":10,"z":-9,"color":"#5f93ad"},{"x":-1,"y":10,"z":-8,"color":"#5f93ad"},{"x":-1,"y":10,"z":-7,"color":"#5f93ad"},{"x":-1,"y":10,"z":-6,"color":"#5f93ad"},{"x":-1,"y":10,"z":-5,"color":"#5f93ad"},{"x":-1,"y":10,"z":-4,"color":"#5f93ad"},{"x":-1,"y":10,"z":-3,"color":"#5f93ad"},{"x":-1,"y":10,"z":-2,"color":"#a9d6e6"},{"x":-1,"y":11,"z":-3,"color":"#a9d6e6"},{"x":-1,"y":11,"z":-2,"color":"#a9d6e6"},{"x":-1,"y":12,"z":-9,"color":"#5f93ad"},{"x":-1,"y":12,"z":-8,"color":"#5f93ad"},{"x":-1,"y":12,"z":-7,"color":"#5f93ad"},{"x":-1,"y":12,"z":-2,"color":"#a9d6e6"},{"x":-1,"y":13,"z":-11,"color":"#d6eef5"},{"x":-1,"y":13,"z":-10,"color":"#d6eef5"},{"x":-1,"y":13,"z":-9,"color":"#d6eef5"},{"x":-1,"y":13,"z":-8,"color":"#d6eef5"},{"x":-1,"y":13,"z":-7,"color":"#d6eef5"},{"x":-1,"y":13,"z":-6,"color":"#d6eef5"},{"x":-1,"y":13,"z":-5,"color":"#d6eef5"},{"x":-1,"y":13,"z":-4,"color":"#d6eef5"},{"x":-1,"y":13,"z":-3,"color":"#d6eef5"},{"x":-1,"y":13,"z":-2,"color":"#d6eef5"},{"x":0,"y":8,"z":-11,"color":"#2b3f50"},{"x":0,"y":8,"z":-10,"color":"#2b3f50"},{"x":0,"y":8,"z":-9,"color":"#2b3f50"},{"x":0,"y":8,"z":-8,"color":"#2b3f50"},{"x":0,"y":8,"z":-7,"color":"#2b3f50"},{"x":0,"y":8,"z":-6,"color":"#2b3f50"},{"x":0,"y":8,"z":-5,"color":"#2b3f50"},{"x":0,"y":8,"z":-4,"color":"#2b3f50"},{"x":0,"y":8,"z":-3,"color":"#2b3f50"},{"x":0,"y":8,"z":-2,"color":"#2b3f50"},{"x":0,"y":9,"z":-11,"color":"#a9d6e6"},{"x":0,"y":9,"z":-10,"color":"#a9d6e6"},{"x":0,"y":9,"z":-9,"color":"#a9d6e6"},{"x":0,"y":9,"z":-8,"color":"#a9d6e6"},{"x":0,"y":9,"z":-7,"color":"#a9d6e6"},{"x":0,"y":9,"z":-6,"color":"#a9d6e6"},{"x":0,"y":9,"z":-5,"color":"#a9d6e6"},{"x":0,"y":9,"z":-4,"color":"#a9d6e6"},{"x":0,"y":9,"z":-3,"color":"#a9d6e6"},{"x":0,"y":9,"z":-2,"color":"#2b3f50"},{"x":0,"y":10,"z":-11,"color":"#5f93ad"},{"x":0,"y":10,"z":-10,"color":"#5f93ad"},{"x":0,"y":10,"z":-9,"color":"#5f93ad"},{"x":0,"y":10,"z":-8,"color":"#5f93ad"},{"x":0,"y":10,"z":-7,"color":"#5f93ad"},{"x":0,"y":10,"z":-6,"color":"#5f93ad"},{"x":0,"y":10,"z":-5,"color":"#5f93ad"},{"x":0,"y":10,"z":-4,"color":"#5f93ad"},{"x":0,"y":10,"z":-3,"color":"#5f93ad"},{"x":0,"y":10,"z":-2,"color":"#a9d6e6"},{"x":0,"y":11,"z":-11,"color":"#a9d6e6"},{"x":0,"y":11,"z":-10,"color":"#a9d6e6"},{"x":0,"y":11,"z":-9,"color":"#a9d6e6"},{"x":0,"y":11,"z":-8,"color":"#a9d6e6"},{"x":0,"y":11,"z":-7,"color":"#a9d6e6"},{"x":0,"y":11,"z":-6,"color":"#2b3f50"},{"x":0,"y":11,"z":-5,"color":"#2b3f50"},{"x":0,"y":11,"z":-4,"color":"#2b3f50"},{"x":0,"y":11,"z":-3,"color":"#a9d6e6"},{"x":0,"y":11,"z":-2,"color":"#a9d6e6"},{"x":0,"y":12,"z":-11,"color":"#5f93ad"},{"x":0,"y":12,"z":-10,"color":"#5f93ad"},{"x":0,"y":12,"z":-9,"color":"#5f93ad"},{"x":0,"y":12,"z":-8,"color":"#5f93ad"},{"x":0,"y":12,"z":-7,"color":"#5f93ad"},{"x":0,"y":12,"z":-6,"color":"#2b3f50"},{"x":0,"y":12,"z":-5,"color":"#2b3f50"},{"x":0,"y":12,"z":-4,"color":"#2b3f50"},{"x":0,"y":12,"z":-3,"color":"#5f93ad"},{"x":0,"y":12,"z":-2,"color":"#a9d6e6"},{"x":0,"y":13,"z":-11,"color":"#a9d6e6"},{"x":0,"y":13,"z":-10,"color":"#a9d6e6"},{"x":0,"y":13,"z":-9,"color":"#a9d6e6"},{"x":0,"y":13,"z":-8,"color":"#a9d6e6"},{"x":0,"y":13,"z":-7,"color":"#16161b"},{"x":0,"y":13,"z":-6,"color":"#a9d6e6"},{"x":0,"y":13,"z":-5,"color":"#a9d6e6"},{"x":0,"y":13,"z":-4,"color":"#a9d6e6"},{"x":0,"y":13,"z":-3,"color":"#a9d6e6"},{"x":0,"y":13,"z":-2,"color":"#16161b"},{"x":1,"y":8,"z":-11,"color":"#2b3f50"},{"x":1,"y":8,"z":-10,"color":"#2b3f50"},{"x":1,"y":8,"z":-9,"color":"#2b3f50"},{"x":1,"y":8,"z":-8,"color":"#2b3f50"},{"x":1,"y":8,"z":-7,"color":"#2b3f50"},{"x":1,"y":8,"z":-6,"color":"#2b3f50"},{"x":1,"y":8,"z":-5,"color":"#2b3f50"},{"x":1,"y":8,"z":-4,"color":"#2b3f50"},{"x":1,"y":8,"z":-3,"color":"#2b3f50"},{"x":1,"y":8,"z":-2,"color":"#2b3f50"},{"x":1,"y":9,"z":-11,"color":"#a9d6e6"},{"x":1,"y":9,"z":-10,"color":"#a9d6e6"},{"x":1,"y":9,"z":-9,"color":"#a9d6e6"},{"x":1,"y":9,"z":-8,"color":"#a9d6e6"},{"x":1,"y":9,"z":-7,"color":"#a9d6e6"},{"x":1,"y":9,"z":-6,"color":"#a9d6e6"},{"x":1,"y":9,"z":-5,"color":"#a9d6e6"},{"x":1,"y":9,"z":-4,"color":"#a9d6e6"},{"x":1,"y":9,"z":-3,"color":"#a9d6e6"},{"x":1,"y":9,"z":-2,"color":"#2b3f50"},{"x":1,"y":10,"z":-9,"color":"#5f93ad"},{"x":1,"y":10,"z":-8,"color":"#5f93ad"},{"x":1,"y":10,"z":-7,"color":"#5f93ad"},{"x":1,"y":10,"z":-6,"color":"#5f93ad"},{"x":1,"y":10,"z":-5,"color":"#5f93ad"},{"x":1,"y":10,"z":-4,"color":"#5f93ad"},{"x":1,"y":10,"z":-3,"color":"#5f93ad"},{"x":1,"y":10,"z":-2,"color":"#a9d6e6"},{"x":1,"y":11,"z":-3,"color":"#a9d6e6"},{"x":1,"y":11,"z":-2,"color":"#a9d6e6"},{"x":1,"y":12,"z":-10,"color":"#5f93ad"},{"x":1,"y":12,"z":-9,"color":"#5f93ad"},{"x":1,"y":12,"z":-8,"color":"#5f93ad"},{"x":1,"y":12,"z":-7,"color":"#5f93ad"},{"x":1,"y":12,"z":-2,"color":"#a9d6e6"},{"x":1,"y":13,"z":-11,"color":"#a9d6e6"},{"x":1,"y":13,"z":-10,"color":"#a9d6e6"},{"x":1,"y":13,"z":-9,"color":"#a9d6e6"},{"x":1,"y":13,"z":-8,"color":"#a9d6e6"},{"x":1,"y":13,"z":-7,"color":"#16161b"},{"x":1,"y":13,"z":-6,"color":"#a9d6e6"},{"x":1,"y":13,"z":-5,"color":"#a9d6e6"},{"x":1,"y":13,"z":-4,"color":"#a9d6e6"},{"x":1,"y":13,"z":-3,"color":"#a9d6e6"},{"x":1,"y":13,"z":-2,"color":"#16161b"},{"x":-1,"y":6,"z":-11,"color":"#2b3f50"},{"x":-1,"y":6,"z":-10,"color":"#2b3f50"},{"x":-1,"y":7,"z":-11,"color":"#2b3f50"},{"x":-1,"y":7,"z":-10,"color":"#2b3f50"},{"x":0,"y":6,"z":-11,"color":"#2b3f50"},{"x":0,"y":6,"z":-10,"color":"#2b3f50"},{"x":0,"y":7,"z":-11,"color":"#2b3f50"},{"x":0,"y":7,"z":-10,"color":"#2b3f50"},{"x":1,"y":6,"z":-11,"color":"#2b3f50"},{"x":1,"y":6,"z":-10,"color":"#2b3f50"},{"x":1,"y":7,"z":-11,"color":"#2b3f50"},{"x":1,"y":7,"z":-10,"color":"#2b3f50"},{"x":-1,"y":4,"z":-12,"color":"#2b3f50"},{"x":-1,"y":4,"z":-11,"color":"#2b3f50"},{"x":-1,"y":4,"z":-10,"color":"#2b3f50"},{"x":-1,"y":5,"z":-12,"color":"#2b3f50"},{"x":-1,"y":5,"z":-11,"color":"#2b3f50"},{"x":-1,"y":5,"z":-10,"color":"#2b3f50"},{"x":-1,"y":6,"z":-12,"color":"#2b3f50"},{"x":0,"y":4,"z":-12,"color":"#2b3f50"},{"x":0,"y":4,"z":-11,"color":"#2b3f50"},{"x":0,"y":4,"z":-10,"color":"#2b3f50"},{"x":0,"y":5,"z":-12,"color":"#2b3f50"},{"x":0,"y":5,"z":-11,"color":"#2b3f50"},{"x":0,"y":5,"z":-10,"color":"#2b3f50"},{"x":0,"y":6,"z":-12,"color":"#2b3f50"},{"x":1,"y":4,"z":-12,"color":"#2b3f50"},{"x":1,"y":4,"z":-11,"color":"#2b3f50"},{"x":1,"y":4,"z":-10,"color":"#2b3f50"},{"x":1,"y":5,"z":-12,"color":"#2b3f50"},{"x":1,"y":5,"z":-11,"color":"#2b3f50"},{"x":1,"y":5,"z":-10,"color":"#2b3f50"},{"x":1,"y":6,"z":-12,"color":"#2b3f50"},{"x":-1,"y":2,"z":-13,"color":"#16161b"},{"x":-1,"y":2,"z":-12,"color":"#16161b"},{"x":-1,"y":2,"z":-11,"color":"#2b3f50"},{"x":-1,"y":3,"z":-13,"color":"#2b3f50"},{"x":-1,"y":3,"z":-12,"color":"#2b3f50"},{"x":-1,"y":3,"z":-11,"color":"#2b3f50"},{"x":-1,"y":4,"z":-13,"color":"#2b3f50"},{"x":0,"y":2,"z":-13,"color":"#16161b"},{"x":0,"y":2,"z":-12,"color":"#16161b"},{"x":0,"y":2,"z":-11,"color":"#2b3f50"},{"x":0,"y":3,"z":-13,"color":"#2b3f50"},{"x":0,"y":3,"z":-12,"color":"#2b3f50"},{"x":0,"y":3,"z":-11,"color":"#2b3f50"},{"x":0,"y":4,"z":-13,"color":"#2b3f50"},{"x":1,"y":2,"z":-13,"color":"#16161b"},{"x":1,"y":2,"z":-12,"color":"#16161b"},{"x":1,"y":2,"z":-11,"color":"#2b3f50"},{"x":1,"y":3,"z":-13,"color":"#2b3f50"},{"x":1,"y":3,"z":-12,"color":"#2b3f50"},{"x":1,"y":3,"z":-11,"color":"#2b3f50"},{"x":1,"y":4,"z":-13,"color":"#2b3f50"},{"x":-1,"y":1,"z":-13,"color":"#16161b"},{"x":-1,"y":1,"z":-12,"color":"#16161b"},{"x":0,"y":1,"z":-13,"color":"#16161b"},{"x":0,"y":1,"z":-12,"color":"#16161b"},{"x":1,"y":1,"z":-13,"color":"#16161b"},{"x":1,"y":1,"z":-12,"color":"#16161b"},{"x":0,"y":5,"z":-9,"color":"#16161b"},{"x":1,"y":5,"z":-9,"color":"#16161b"},{"x":-1,"y":5,"z":-8,"color":"#16161b"},{"x":0,"y":5,"z":-8,"color":"#16161b"},{"x":1,"y":5,"z":-8,"color":"#16161b"},{"x":-1,"y":6,"z":-8,"color":"#16161b"},{"x":-1,"y":7,"z":-8,"color":"#16161b"},{"x":0,"y":6,"z":-8,"color":"#16161b"},{"x":0,"y":7,"z":-8,"color":"#16161b"},{"x":1,"y":6,"z":-8,"color":"#16161b"},{"x":1,"y":7,"z":-8,"color":"#16161b"},{"x":-1,"y":9,"z":-1,"color":"#2b3f50"},{"x":-1,"y":9,"z":0,"color":"#2b3f50"},{"x":-1,"y":9,"z":1,"color":"#2b3f50"},{"x":-1,"y":9,"z":2,"color":"#2b3f50"},{"x":-1,"y":9,"z":3,"color":"#2b3f50"},{"x":-1,"y":9,"z":4,"color":"#2b3f50"},{"x":-1,"y":9,"z":5,"color":"#2b3f50"},{"x":-1,"y":9,"z":6,"color":"#2b3f50"},{"x":-1,"y":10,"z":-1,"color":"#2b3f50"},{"x":-1,"y":10,"z":0,"color":"#a9d6e6"},{"x":-1,"y":10,"z":1,"color":"#2b3f50"},{"x":-1,"y":10,"z":2,"color":"#a9d6e6"},{"x":-1,"y":10,"z":3,"color":"#2b3f50"},{"x":-1,"y":10,"z":4,"color":"#a9d6e6"},{"x":-1,"y":10,"z":5,"color":"#2b3f50"},{"x":-1,"y":10,"z":6,"color":"#2b3f50"},{"x":-1,"y":11,"z":-1,"color":"#2b3f50"},{"x":-1,"y":11,"z":0,"color":"#a9d6e6"},{"x":-1,"y":11,"z":1,"color":"#2b3f50"},{"x":-1,"y":11,"z":2,"color":"#a9d6e6"},{"x":-1,"y":11,"z":3,"color":"#2b3f50"},{"x":-1,"y":11,"z":4,"color":"#a9d6e6"},{"x":-1,"y":11,"z":5,"color":"#2b3f50"},{"x":-1,"y":11,"z":6,"color":"#a9d6e6"},{"x":-1,"y":12,"z":-1,"color":"#2b3f50"},{"x":-1,"y":12,"z":0,"color":"#a9d6e6"},{"x":-1,"y":12,"z":1,"color":"#2b3f50"},{"x":-1,"y":12,"z":2,"color":"#a9d6e6"},{"x":-1,"y":12,"z":3,"color":"#2b3f50"},{"x":-1,"y":12,"z":4,"color":"#a9d6e6"},{"x":-1,"y":12,"z":5,"color":"#2b3f50"},{"x":-1,"y":13,"z":-1,"color":"#d6eef5"},{"x":-1,"y":13,"z":0,"color":"#d6eef5"},{"x":-1,"y":13,"z":1,"color":"#d6eef5"},{"x":-1,"y":13,"z":3,"color":"#d6eef5"},{"x":-1,"y":13,"z":5,"color":"#d6eef5"},{"x":0,"y":9,"z":-1,"color":"#2b3f50"},{"x":0,"y":9,"z":0,"color":"#2b3f50"},{"x":0,"y":9,"z":1,"color":"#2b3f50"},{"x":0,"y":9,"z":2,"color":"#2b3f50"},{"x":0,"y":9,"z":3,"color":"#2b3f50"},{"x":0,"y":9,"z":4,"color":"#2b3f50"},{"x":0,"y":9,"z":5,"color":"#2b3f50"},{"x":0,"y":9,"z":6,"color":"#2b3f50"},{"x":0,"y":10,"z":-1,"color":"#a9d6e6"},{"x":0,"y":10,"z":0,"color":"#a9d6e6"},{"x":0,"y":10,"z":1,"color":"#a9d6e6"},{"x":0,"y":10,"z":2,"color":"#a9d6e6"},{"x":0,"y":10,"z":3,"color":"#a9d6e6"},{"x":0,"y":10,"z":4,"color":"#a9d6e6"},{"x":0,"y":10,"z":5,"color":"#a9d6e6"},{"x":0,"y":10,"z":6,"color":"#2b3f50"},{"x":0,"y":11,"z":-1,"color":"#a9d6e6"},{"x":0,"y":11,"z":0,"color":"#a9d6e6"},{"x":0,"y":11,"z":1,"color":"#a9d6e6"},{"x":0,"y":11,"z":2,"color":"#a9d6e6"},{"x":0,"y":11,"z":3,"color":"#a9d6e6"},{"x":0,"y":11,"z":4,"color":"#a9d6e6"},{"x":0,"y":11,"z":5,"color":"#a9d6e6"},{"x":0,"y":11,"z":6,"color":"#a9d6e6"},{"x":0,"y":12,"z":-1,"color":"#a9d6e6"},{"x":0,"y":12,"z":0,"color":"#a9d6e6"},{"x":0,"y":12,"z":1,"color":"#a9d6e6"},{"x":0,"y":12,"z":2,"color":"#a9d6e6"},{"x":0,"y":12,"z":3,"color":"#a9d6e6"},{"x":0,"y":12,"z":4,"color":"#a9d6e6"},{"x":0,"y":12,"z":5,"color":"#a9d6e6"},{"x":0,"y":12,"z":6,"color":"#d6eef5"},{"x":0,"y":13,"z":-1,"color":"#5f93ad"},{"x":0,"y":13,"z":0,"color":"#5f93ad"},{"x":0,"y":13,"z":3,"color":"#5f93ad"},{"x":0,"y":13,"z":5,"color":"#5f93ad"},{"x":0,"y":13,"z":6,"color":"#5f93ad"},{"x":1,"y":9,"z":-1,"color":"#2b3f50"},{"x":1,"y":9,"z":0,"color":"#2b3f50"},{"x":1,"y":9,"z":1,"color":"#2b3f50"},{"x":1,"y":9,"z":2,"color":"#2b3f50"},{"x":1,"y":9,"z":3,"color":"#2b3f50"},{"x":1,"y":9,"z":4,"color":"#2b3f50"},{"x":1,"y":9,"z":5,"color":"#2b3f50"},{"x":1,"y":9,"z":6,"color":"#2b3f50"},{"x":1,"y":10,"z":-1,"color":"#2b3f50"},{"x":1,"y":10,"z":0,"color":"#a9d6e6"},{"x":1,"y":10,"z":1,"color":"#2b3f50"},{"x":1,"y":10,"z":3,"color":"#2b3f50"},{"x":1,"y":10,"z":5,"color":"#2b3f50"},{"x":1,"y":10,"z":6,"color":"#2b3f50"},{"x":1,"y":11,"z":-1,"color":"#2b3f50"},{"x":1,"y":11,"z":0,"color":"#a9d6e6"},{"x":1,"y":11,"z":1,"color":"#2b3f50"},{"x":1,"y":11,"z":3,"color":"#2b3f50"},{"x":1,"y":11,"z":5,"color":"#2b3f50"},{"x":1,"y":11,"z":6,"color":"#a9d6e6"},{"x":1,"y":12,"z":-1,"color":"#2b3f50"},{"x":1,"y":12,"z":0,"color":"#a9d6e6"},{"x":1,"y":12,"z":1,"color":"#2b3f50"},{"x":1,"y":12,"z":3,"color":"#2b3f50"},{"x":1,"y":12,"z":5,"color":"#2b3f50"},{"x":1,"y":13,"z":-1,"color":"#5f93ad"},{"x":1,"y":13,"z":0,"color":"#5f93ad"},{"x":1,"y":13,"z":1,"color":"#5f93ad"},{"x":1,"y":13,"z":3,"color":"#5f93ad"},{"x":1,"y":13,"z":5,"color":"#5f93ad"},{"x":-1,"y":2,"z":1,"color":"#16161b"},{"x":-1,"y":2,"z":2,"color":"#16161b"},{"x":-1,"y":2,"z":3,"color":"#5f93ad"},{"x":-1,"y":3,"z":1,"color":"#2b3f50"},{"x":-1,"y":3,"z":2,"color":"#2b3f50"},{"x":-1,"y":3,"z":3,"color":"#5f93ad"},{"x":-1,"y":4,"z":1,"color":"#2b3f50"},{"x":-1,"y":4,"z":2,"color":"#2b3f50"},{"x":-1,"y":4,"z":3,"color":"#5f93ad"},{"x":-1,"y":5,"z":1,"color":"#2b3f50"},{"x":-1,"y":5,"z":2,"color":"#2b3f50"},{"x":-1,"y":5,"z":3,"color":"#5f93ad"},{"x":-1,"y":6,"z":1,"color":"#2b3f50"},{"x":-1,"y":6,"z":2,"color":"#2b3f50"},{"x":-1,"y":6,"z":3,"color":"#5f93ad"},{"x":-1,"y":7,"z":1,"color":"#2b3f50"},{"x":-1,"y":7,"z":2,"color":"#2b3f50"},{"x":-1,"y":7,"z":3,"color":"#5f93ad"},{"x":-1,"y":8,"z":1,"color":"#2b3f50"},{"x":-1,"y":8,"z":2,"color":"#2b3f50"},{"x":-1,"y":8,"z":3,"color":"#5f93ad"},{"x":0,"y":2,"z":1,"color":"#16161b"},{"x":0,"y":2,"z":2,"color":"#16161b"},{"x":0,"y":2,"z":3,"color":"#5f93ad"},{"x":0,"y":3,"z":1,"color":"#2b3f50"},{"x":0,"y":3,"z":2,"color":"#2b3f50"},{"x":0,"y":3,"z":3,"color":"#5f93ad"},{"x":0,"y":4,"z":1,"color":"#2b3f50"},{"x":0,"y":4,"z":2,"color":"#2b3f50"},{"x":0,"y":4,"z":3,"color":"#5f93ad"},{"x":0,"y":5,"z":1,"color":"#2b3f50"},{"x":0,"y":5,"z":2,"color":"#2b3f50"},{"x":0,"y":5,"z":3,"color":"#5f93ad"},{"x":0,"y":6,"z":1,"color":"#2b3f50"},{"x":0,"y":6,"z":2,"color":"#2b3f50"},{"x":0,"y":6,"z":3,"color":"#5f93ad"},{"x":0,"y":7,"z":1,"color":"#2b3f50"},{"x":0,"y":7,"z":2,"color":"#2b3f50"},{"x":0,"y":7,"z":3,"color":"#5f93ad"},{"x":0,"y":8,"z":1,"color":"#2b3f50"},{"x":0,"y":8,"z":2,"color":"#2b3f50"},{"x":0,"y":8,"z":3,"color":"#5f93ad"},{"x":1,"y":2,"z":1,"color":"#16161b"},{"x":1,"y":2,"z":2,"color":"#16161b"},{"x":1,"y":2,"z":3,"color":"#5f93ad"},{"x":1,"y":3,"z":1,"color":"#2b3f50"},{"x":1,"y":3,"z":2,"color":"#2b3f50"},{"x":1,"y":3,"z":3,"color":"#5f93ad"},{"x":1,"y":4,"z":1,"color":"#2b3f50"},{"x":1,"y":4,"z":2,"color":"#2b3f50"},{"x":1,"y":4,"z":3,"color":"#5f93ad"},{"x":1,"y":5,"z":1,"color":"#2b3f50"},{"x":1,"y":5,"z":2,"color":"#2b3f50"},{"x":1,"y":5,"z":3,"color":"#5f93ad"},{"x":1,"y":6,"z":1,"color":"#2b3f50"},{"x":1,"y":6,"z":2,"color":"#2b3f50"},{"x":1,"y":6,"z":3,"color":"#5f93ad"},{"x":1,"y":7,"z":1,"color":"#2b3f50"},{"x":1,"y":7,"z":2,"color":"#2b3f50"},{"x":1,"y":7,"z":3,"color":"#5f93ad"},{"x":1,"y":8,"z":1,"color":"#2b3f50"},{"x":1,"y":8,"z":2,"color":"#2b3f50"},{"x":1,"y":8,"z":3,"color":"#5f93ad"},{"x":-1,"y":1,"z":1,"color":"#16161b"},{"x":-1,"y":1,"z":2,"color":"#16161b"},{"x":0,"y":1,"z":1,"color":"#16161b"},{"x":0,"y":1,"z":2,"color":"#16161b"},{"x":1,"y":1,"z":1,"color":"#16161b"},{"x":1,"y":1,"z":2,"color":"#16161b"},{"x":-1,"y":10,"z":7,"color":"#2b3f50"},{"x":-1,"y":10,"z":8,"color":"#2b3f50"},{"x":-1,"y":10,"z":9,"color":"#2b3f50"},{"x":-1,"y":10,"z":10,"color":"#2b3f50"},{"x":-1,"y":10,"z":11,"color":"#2b3f50"},{"x":-1,"y":10,"z":12,"color":"#2b3f50"},{"x":-1,"y":10,"z":13,"color":"#2b3f50"},{"x":-1,"y":11,"z":7,"color":"#a9d6e6"},{"x":-1,"y":11,"z":8,"color":"#a9d6e6"},{"x":-1,"y":11,"z":9,"color":"#a9d6e6"},{"x":-1,"y":11,"z":10,"color":"#a9d6e6"},{"x":-1,"y":11,"z":11,"color":"#a9d6e6"},{"x":-1,"y":11,"z":12,"color":"#a9d6e6"},{"x":-1,"y":11,"z":13,"color":"#2b3f50"},{"x":-1,"y":12,"z":13,"color":"#2b3f50"},{"x":0,"y":10,"z":7,"color":"#2b3f50"},{"x":0,"y":10,"z":8,"color":"#2b3f50"},{"x":0,"y":10,"z":9,"color":"#2b3f50"},{"x":0,"y":10,"z":10,"color":"#2b3f50"},{"x":0,"y":10,"z":11,"color":"#2b3f50"},{"x":0,"y":10,"z":12,"color":"#2b3f50"},{"x":0,"y":10,"z":13,"color":"#2b3f50"},{"x":0,"y":11,"z":7,"color":"#a9d6e6"},{"x":0,"y":11,"z":8,"color":"#a9d6e6"},{"x":0,"y":11,"z":9,"color":"#a9d6e6"},{"x":0,"y":11,"z":10,"color":"#a9d6e6"},{"x":0,"y":11,"z":11,"color":"#a9d6e6"},{"x":0,"y":11,"z":12,"color":"#a9d6e6"},{"x":0,"y":11,"z":13,"color":"#2b3f50"},{"x":0,"y":12,"z":7,"color":"#d6eef5"},{"x":0,"y":12,"z":8,"color":"#d6eef5"},{"x":0,"y":12,"z":9,"color":"#d6eef5"},{"x":0,"y":12,"z":10,"color":"#d6eef5"},{"x":0,"y":12,"z":11,"color":"#d6eef5"},{"x":0,"y":12,"z":12,"color":"#d6eef5"},{"x":0,"y":12,"z":13,"color":"#2b3f50"},{"x":1,"y":10,"z":7,"color":"#2b3f50"},{"x":1,"y":10,"z":8,"color":"#2b3f50"},{"x":1,"y":10,"z":9,"color":"#2b3f50"},{"x":1,"y":10,"z":10,"color":"#2b3f50"},{"x":1,"y":10,"z":11,"color":"#2b3f50"},{"x":1,"y":10,"z":12,"color":"#2b3f50"},{"x":1,"y":10,"z":13,"color":"#2b3f50"},{"x":1,"y":11,"z":7,"color":"#a9d6e6"},{"x":1,"y":11,"z":8,"color":"#a9d6e6"},{"x":1,"y":11,"z":9,"color":"#a9d6e6"},{"x":1,"y":11,"z":10,"color":"#a9d6e6"},{"x":1,"y":11,"z":11,"color":"#a9d6e6"},{"x":1,"y":11,"z":12,"color":"#a9d6e6"},{"x":1,"y":11,"z":13,"color":"#2b3f50"},{"x":1,"y":12,"z":13,"color":"#2b3f50"},{"x":-1,"y":10,"z":14,"color":"#9af0ff"},{"x":-1,"y":11,"z":14,"color":"#9af0ff"},{"x":-1,"y":12,"z":14,"color":"#9af0ff"},{"x":0,"y":10,"z":14,"color":"#9af0ff"},{"x":0,"y":11,"z":14,"color":"#9af0ff"},{"x":0,"y":12,"z":14,"color":"#9af0ff"},{"x":1,"y":10,"z":14,"color":"#9af0ff"},{"x":1,"y":11,"z":14,"color":"#9af0ff"},{"x":1,"y":12,"z":14,"color":"#9af0ff"},{"x":-1,"y":11,"z":15,"color":"#9af0ff"},{"x":0,"y":10,"z":15,"color":"#9af0ff"},{"x":0,"y":12,"z":15,"color":"#9af0ff"},{"x":1,"y":11,"z":15,"color":"#9af0ff"},{"x":-1,"y":14,"z":-8,"color":"#2b3f50"},{"x":-1,"y":14,"z":-7,"color":"#2b3f50"},{"x":-1,"y":14,"z":-6,"color":"#2b3f50"},{"x":-1,"y":14,"z":-5,"color":"#2b3f50"},{"x":-1,"y":14,"z":-4,"color":"#2b3f50"},{"x":-1,"y":14,"z":-3,"color":"#2b3f50"},{"x":-1,"y":14,"z":-2,"color":"#2b3f50"},{"x":-1,"y":14,"z":-1,"color":"#2b3f50"},{"x":-1,"y":15,"z":-8,"color":"#9af0ff"},{"x":-1,"y":15,"z":-1,"color":"#9af0ff"},{"x":0,"y":14,"z":-8,"color":"#2b3f50"},{"x":0,"y":14,"z":-7,"color":"#2b3f50"},{"x":0,"y":14,"z":-6,"color":"#2b3f50"},{"x":0,"y":14,"z":-5,"color":"#2b3f50"},{"x":0,"y":14,"z":-4,"color":"#2b3f50"},{"x":0,"y":14,"z":-3,"color":"#2b3f50"},{"x":0,"y":14,"z":-2,"color":"#2b3f50"},{"x":0,"y":14,"z":-1,"color":"#2b3f50"},{"x":1,"y":14,"z":-8,"color":"#2b3f50"},{"x":1,"y":14,"z":-7,"color":"#2b3f50"},{"x":1,"y":14,"z":-6,"color":"#2b3f50"},{"x":1,"y":14,"z":-5,"color":"#2b3f50"},{"x":1,"y":14,"z":-4,"color":"#2b3f50"},{"x":1,"y":14,"z":-3,"color":"#2b3f50"},{"x":1,"y":14,"z":-2,"color":"#2b3f50"},{"x":1,"y":14,"z":-1,"color":"#2b3f50"},{"x":1,"y":15,"z":-8,"color":"#9af0ff"},{"x":1,"y":15,"z":-1,"color":"#9af0ff"},{"x":-1,"y":7,"z":-9,"color":"#d8a878"},{"x":-1,"y":6,"z":-9,"color":"#d8a878"},{"x":-1,"y":5,"z":-9,"color":"#d8a878"},{"x":-1,"y":7,"z":-7,"color":"#d8a878"},{"x":-1,"y":6,"z":-7,"color":"#d8a878"},{"x":-1,"y":5,"z":-7,"color":"#d8a878"},{"x":-2,"y":5,"z":-9,"color":"#d8a878"},{"x":-2,"y":5,"z":-8,"color":"#d8a878"},{"x":-2,"y":5,"z":-7,"color":"#d8a878"},{"x":-2,"y":6,"z":-9,"color":"#d8a878"},{"x":-2,"y":6,"z":-8,"color":"#d8a878"},{"x":-2,"y":6,"z":-7,"color":"#d8a878"},{"x":-2,"y":7,"z":-9,"color":"#d8a878"},{"x":-2,"y":7,"z":-8,"color":"#d8a878"},{"x":-2,"y":7,"z":-7,"color":"#d8a878"},{"x":2,"y":10,"z":9,"color":"#d8a878"},{"x":2,"y":10,"z":8,"color":"#d8a878"},{"x":2,"y":10,"z":7,"color":"#d8a878"},{"x":0,"y":9,"z":9,"color":"#d8a878"},{"x":1,"y":9,"z":9,"color":"#d8a878"},{"x":2,"y":9,"z":9,"color":"#d8a878"},{"x":0,"y":9,"z":8,"color":"#d8a878"},{"x":1,"y":9,"z":8,"color":"#d8a878"},{"x":2,"y":9,"z":8,"color":"#d8a878"},{"x":0,"y":9,"z":7,"color":"#d8a878"},{"x":1,"y":9,"z":7,"color":"#d8a878"},{"x":2,"y":9,"z":7,"color":"#d8a878"},{"x":0,"y":8,"z":7,"color":"#d8a878"},{"x":1,"y":8,"z":7,"color":"#d8a878"},{"x":2,"y":8,"z":7,"color":"#d8a878"},{"x":0,"y":8,"z":8,"color":"#d8a878"},{"x":1,"y":8,"z":8,"color":"#d8a878"},{"x":2,"y":8,"z":8,"color":"#d8a878"},{"x":0,"y":8,"z":9,"color":"#d8a878"},{"x":1,"y":8,"z":9,"color":"#d8a878"},{"x":2,"y":8,"z":9,"color":"#d8a878"},{"x":-3,"y":7,"z":-9,"color":"#d8a878"},{"x":-3,"y":6,"z":-9,"color":"#d8a878"},{"x":-3,"y":5,"z":-9,"color":"#d8a878"},{"x":-3,"y":7,"z":-8,"color":"#d8a878"},{"x":-3,"y":6,"z":-8,"color":"#d8a878"},{"x":-3,"y":5,"z":-8,"color":"#d8a878"},{"x":-3,"y":7,"z":-7,"color":"#d8a878"},{"x":-3,"y":6,"z":-7,"color":"#d8a878"},{"x":-3,"y":5,"z":-7,"color":"#d8a878"},{"x":0,"y":7,"z":-9,"color":"#d8a878"},{"x":0,"y":6,"z":-9,"color":"#d8a878"},{"x":1,"y":6,"z":-9,"color":"#d8a878"},{"x":1,"y":7,"z":-9,"color":"#d8a878"}]}